Workbook

Sheet Instructions
A1: CLIENT INVESTMENT TRACKER - TOTAL REVIEW
A2: Built to match the scheme-wise Profit & Loss export from the portfolio software.
B4: HOW TO USE
B5: 1. Clients | C5: Enter every client once - code, name, PAN, address, mobile, email, DOB, 'Rep By' / family head. This list drives the dropdowns, the client-wise review and the Client Report header.
B6: 2. Import Report | C6: The easy way to load data. Paste a whole Profit & Loss export on the left of that sheet; clean register rows appear on the right, ready to copy into Investments. Category headings, transaction sub-tables and total lines are dropped for you, and the scheme name and folio are split apart.
B7: 3. Investments | C7: One row per scheme per client. Columns A to O are one unbroken block, in the same order as the Import Report output, so a whole report goes in with a single Paste Special > Values on cell A6. Columns P to V are formulas - never paste over them.
B8: 4. Total Review | C8: Read-only dashboard: firm-level snapshot, client-wise review, asset-class review and category-wise review, with charts.
B9: 5. Client Report | C9: Pick one client from the dropdown to get that client's header block, summary and scheme list - the single-client view your software prints.
B11: HOW THE MATHS WORKS
B12: Total Invested | C12: Purchase + Switch In + Div Reinv
B13: Withdrawn | C13: Redemption + Switch Out + Div Pay
B14: Gain / Loss | C14: (Cur. Value + Withdrawn) - Total Invested
B15: Abs. Rtn. | C15: Gain / Loss ÷ Total Invested
B16: Net Invested | C16: Total Invested - Withdrawn (money still at work; shown for reference)
B17: Status | C17: Live when Cur. Value is above zero, otherwise Exited.
B18: XIRR | C18: Typed in from the software - it needs every cash-flow date, which this sheet does not hold. Client, category and firm level XIRR is a current-value-weighted average of the scheme XIRRs, so treat it as indicative, not as a recomputed XIRR.
B20: WHAT YOU EDIT
B21: Blue text on yellow fill | C21: Input cells - type or paste here.
B22: Black text on grey fill | C22: Formula cells - do not overwrite, they will stop calculating.
B23: EXAMPLE rows | C23: Clients row 4 and Investments row 6 are filled in as a format guide. Delete both before real use.
B24: Paste Special > Values | C24: Use this rather than a plain Ctrl+V when pasting into Investments: a plain paste drags the source formatting across and can wreck the column widths, fills and dropdowns.
B26: GOOD TO KNOW
B27: Capacity | C27: 200 clients, 1000 scheme rows, 100 schemes per client in the Client Report. To add rows, insert them INSIDE the existing table so the formulas extend with them.
B28: Asset Class | C28: Derived from the text before the ' - ' in Category, which is why categories are named 'Equity - Flexi Cap Fund' exactly as in the software.
B29: New categories | C29: Add them on the Lists sheet; the dropdown and the category-wise review pick them up. Keep the 'Asset - Category' naming.
B30: Currency | C30: Indian Rupee with lakh / crore grouping. To switch, select the amount columns > Format Cells > Custom and edit the symbol.
B31: Blank amounts | C31: Leave a column blank where the software prints 0.00 - blanks and zeros both total correctly.

Sheet Clients
A1: CLIENT MASTER
A2: One row per client. The name entered here is the key used by every other sheet.
A3: Client Code | B3: Client Name | C3: PAN | D3: Rep By / Family Head | E3: Segment | F3: Mobile No. | G3: Email | H3: DOB | I3: Address | J3: Advisor / RM | K3: Onboarding Date | L3: Remarks
A4: CL-0001 | B4: Sample Client (EXAMPLE) | C4: ABCDE1234F | D4: Rep By Family Head Name | E4: HNI | F4: 98xxxxxx61 | G4: client@example.com | H4: 2008-06-05 | I4: Flat 301, Sample Residency, Kothrud, Pune 411038 | J4: S. Kadam | K4: 2020-08-31 | L4: Delete this EXAMPLE row before use

Sheet Import Report
A1: IMPORT A PROFIT & LOSS REPORT
A2: Paste the report on the left - ready-to-paste register rows appear on the right.
A4: STEP 1 | B4: Open the client's Profit & Loss report, press Ctrl+A then Ctrl+C to copy the whole sheet.
A5: STEP 2 | B5: Click cell A9 below and press Ctrl+V. Category headings, transaction rows and total lines are ignored automatically. | Q5: Client Name | W5: =IFERROR(INDEX($A$9:$A$2008,MATCH(1,$V$9:$V$2008,0)),"")
A6: STEP 3 | B6: Check the Client Name box on the right. It is read from the report header - type over it, or pick from the list, so it matches the Clients sheet exactly. | Q6: read from report: | R6: =IF($W$5="","",TRIM(IF(ISNUMBER(SEARCH(" REP BY ",$W$5)),LEFT($W$5,SEARCH(" REP BY ",$W$5)-1),SUBSTITUTE($W$5,"()",""))))
A7: STEP 4 | B7: Select X9:AL... down to the last filled row, press Ctrl+C, then on the Investments sheet right-click cell A6 and choose Paste Special > Values. | X7: READY TO PASTE → copy these rows, then Investments!A6 → Paste Special → Values
A8: Scheme Name (+ Folio) | D8: Inv. Since | E8: Purchase | F8: Switch In | G8: Div Reinv | H8: Redemption | I8: Switch Out | J8: Div Pay | K8: Cur. Value | L8: Cur. Units | M8: Cur. NAV | N8: Gain/Loss | O8: Abs. Rtn. | P8: XIRR | X8: Client Name | Y8: Category | Z8: Scheme Name | AA8: Folio No. | AB8: Inv. Since | AC8: Purchase | AD8: Switch In | AE8: Div Reinv | AF8: Redemption | AG8: Switch Out | AH8: Div Pay | AI8: Cur. Value | AJ8: Cur. Units | AK8: Cur. NAV | AL8: XIRR
S9: =IF(AND(ISTEXT($A9),ISNUMBER(SEARCH(" - ",$A9)),ISERROR(SEARCH("Folio",$A9)),$D9=""),TRIM($A9),"") | T9: =IF(AND(ISNUMBER(SEARCH("Folio",$A9)),$D9<>""),1,"") | U9: =IF($T9=1,COUNTIF($T$9:$T9,1),"") | V9: =IF(AND(ISTEXT($A9),LEFT($A10,3)="Pan"),1,"") | W9: =IFERROR(MATCH(1,$U$9:$U$2008,0),"") | X9: =IF($W9="","",IF($R$5<>"",$R$5,$R$6)) | Y9: =IF($W9="","",INDEX($S$9:$S$2008,$W9)) | Z9: =IF($W9="","",IFERROR(TRIM(LEFT(SUBSTITUTE(INDEX($A$9:$A$2008,$W9),CHAR(10)," "),SEARCH("Folio",SUBSTITUTE(INDEX($A$9:$A$2008,$W9),CHAR(10)," "))-1)),TRIM(SUBSTITUTE(INDEX($A$9:$A$2008,$W9),CHAR(10)," ")))) | AA9: =IF($W9="","",IFERROR(TRIM(SUBSTITUTE(MID(SUBSTITUTE(INDEX($A$9:$A$2008,$W9),CHAR(10)," "),SEARCH("Folio",SUBSTITUTE(INDEX($A$9:$A$2008,$W9),CHAR(10)," "))+5,200),":","")),"")) | AB9: =IF($W9="","",IF(ISNUMBER(INDEX($D$9:$D$2008,$W9)),INDEX($D$9:$D$2008,$W9),IFERROR(DATE(2000+VALUE(RIGHT(INDEX($D$9:$D$2008,$W9),2)),VALUE(MID(INDEX($D$9:$D$2008,$W9),4,2)),VALUE(LEFT(INDEX($D$9:$D$2008,$W9),2))),""))) | AC9: =IF($W9="","",IFERROR(IF(ISNUMBER(INDEX($E$9:$E$2008,$W9)),INDEX($E$9:$E$2008,$W9),VALUE(SUBSTITUTE(INDEX($E$9:$E$2008,$W9),",",""))),"")) | AD9: =IF($W9="","",IFERROR(IF(ISNUMBER(INDEX($F$9:$F$2008,$W9)),INDEX($F$9:$F$2008,$W9),VALUE(SUBSTITUTE(INDEX($F$9:$F$2008,$W9),",",""))),"")) | AE9: =IF($W9="","",IFERROR(IF(ISNUMBER(INDEX($G$9:$G$2008,$W9)),INDEX($G$9:$G$2008,$W9),VALUE(SUBSTITUTE(INDEX($G$9:$G$2008,$W9),",",""))),"")) | AF9: =IF($W9="","",IFERROR(IF(ISNUMBER(INDEX($H$9:$H$2008,$W9)),INDEX($H$9:$H$2008,$W9),VALUE(SUBSTITUTE(INDEX($H$9:$H$2008,$W9),",",""))),"")) | AG9: =IF($W9="","",IFERROR(IF(ISNUMBER(INDEX($I$9:$I$2008,$W9)),INDEX($I$9:$I$2008,$W9),VALUE(SUBSTITUTE(INDEX($I$9:$I$2008,$W9),",",""))),"")) | AH9: =IF($W9="","",IFERROR(IF(ISNUMBER(INDEX($J$9:$J$2008,$W9)),INDEX($J$9:$J$2008,$W9),VALUE(SUBSTITUTE(INDEX($J$9:$J$2008,$W9),",",""))),"")) | AI9: =IF($W9="","",IFERROR(IF(ISNUMBER(INDEX($K$9:$K$2008,$W9)),INDEX($K$9:$K$2008,$W9),VALUE(SUBSTITUTE(INDEX($K$9:$K$2008,$W9),",",""))),"")) | AJ9: =IF($W9="","",IFERROR(IF(ISNUMBER(INDEX($L$9:$L$2008,$W9)),INDEX($L$9:$L$2008,$W9),VALUE(SUBSTITUTE(INDEX($L$9:$L$2008,$W9),",",""))),"")) | AK9: =IF($W9="","",IFERROR(IF(ISNUMBER(INDEX($M$9:$M$2008,$W9)),INDEX($M$9:$M$2008,$W9),VALUE(SUBSTITUTE(INDEX($M$9:$M$2008,$W9),",",""))),"")) | AL9: =IF($W9="","",IFERROR(IF(ISNUMBER(INDEX($P$9:$P$2008,$W9)),INDEX($P$9:$P$2008,$W9),VALUE(SUBSTITUTE(INDEX($P$9:$P$2008,$W9),"%",""))/100),""))
S10: =IF(AND(ISTEXT($A10),ISNUMBER(SEARCH(" - ",$A10)),ISERROR(SEARCH("Folio",$A10)),$D10=""),TRIM($A10),$S9) | T10: =IF(AND(ISNUMBER(SEARCH("Folio",$A10)),$D10<>""),1,"") | U10: =IF($T10=1,COUNTIF($T$9:$T10,1),"") | V10: =IF(AND(ISTEXT($A10),LEFT($A11,3)="Pan"),1,"") | W10: =IFERROR(MATCH(2,$U$9:$U$2008,0),"") | X10: =IF($W10="","",IF($R$5<>"",$R$5,$R$6)) | Y10: =IF($W10="","",INDEX($S$9:$S$2008,$W10)) | Z10: =IF($W10="","",IFERROR(TRIM(LEFT(SUBSTITUTE(INDEX($A$9:$A$2008,$W10),CHAR(10)," "),SEARCH("Folio",SUBSTITUTE(INDEX($A$9:$A$2008,$W10),CHAR(10)," "))-1)),TRIM(SUBSTITUTE(INDEX($A$9:$A$2008,$W10),CHAR(10)," ")))) | AA10: =IF($W10="","",IFERROR(TRIM(SUBSTITUTE(MID(SUBSTITUTE(INDEX($A$9:$A$2008,$W10),CHAR(10)," "),SEARCH("Folio",SUBSTITUTE(INDEX($A$9:$A$2008,$W10),CHAR(10)," "))+5,200),":","")),"")) | AB10: =IF($W10="","",IF(ISNUMBER(INDEX($D$9:$D$2008,$W10)),INDEX($D$9:$D$2008,$W10),IFERROR(DATE(2000+VALUE(RIGHT(INDEX($D$9:$D$2008,$W10),2)),VALUE(MID(INDEX($D$9:$D$2008,$W10),4,2)),VALUE(LEFT(INDEX($D$9:$D$2008,$W10),2))),""))) | AC10: =IF($W10="","",IFERROR(IF(ISNUMBER(INDEX($E$9:$E$2008,$W10)),INDEX($E$9:$E$2008,$W10),VALUE(SUBSTITUTE(INDEX($E$9:$E$2008,$W10),",",""))),"")) | AD10: =IF($W10="","",IFERROR(IF(ISNUMBER(INDEX($F$9:$F$2008,$W10)),INDEX($F$9:$F$2008,$W10),VALUE(SUBSTITUTE(INDEX($F$9:$F$2008,$W10),",",""))),"")) | AE10: =IF($W10="","",IFERROR(IF(ISNUMBER(INDEX($G$9:$G$2008,$W10)),INDEX($G$9:$G$2008,$W10),VALUE(SUBSTITUTE(INDEX($G$9:$G$2008,$W10),",",""))),"")) | AF10: =IF($W10="","",IFERROR(IF(ISNUMBER(INDEX($H$9:$H$2008,$W10)),INDEX($H$9:$H$2008,$W10),VALUE(SUBSTITUTE(INDEX($H$9:$H$2008,$W10),",",""))),"")) | AG10: =IF($W10="","",IFERROR(IF(ISNUMBER(INDEX($I$9:$I$2008,$W10)),INDEX($I$9:$I$2008,$W10),VALUE(SUBSTITUTE(INDEX($I$9:$I$2008,$W10),",",""))),"")) | AH10: =IF($W10="","",IFERROR(IF(ISNUMBER(INDEX($J$9:$J$2008,$W10)),INDEX($J$9:$J$2008,$W10),VALUE(SUBSTITUTE(INDEX($J$9:$J$2008,$W10),",",""))),"")) | AI10: =IF($W10="","",IFERROR(IF(ISNUMBER(INDEX($K$9:$K$2008,$W10)),INDEX($K$9:$K$2008,$W10),VALUE(SUBSTITUTE(INDEX($K$9:$K$2008,$W10),",",""))),"")) | AJ10: =IF($W10="","",IFERROR(IF(ISNUMBER(INDEX($L$9:$L$2008,$W10)),INDEX($L$9:$L$2008,$W10),VALUE(SUBSTITUTE(INDEX($L$9:$L$2008,$W10),",",""))),"")) | AK10: =IF($W10="","",IFERROR(IF(ISNUMBER(INDEX($M$9:$M$2008,$W10)),INDEX($M$9:$M$2008,$W10),VALUE(SUBSTITUTE(INDEX($M$9:$M$2008,$W10),",",""))),"")) | AL10: =IF($W10="","",IFERROR(IF(ISNUMBER(INDEX($P$9:$P$2008,$W10)),INDEX($P$9:$P$2008,$W10),VALUE(SUBSTITUTE(INDEX($P$9:$P$2008,$W10),"%",""))/100),""))
S11: =IF(AND(ISTEXT($A11),ISNUMBER(SEARCH(" - ",$A11)),ISERROR(SEARCH("Folio",$A11)),$D11=""),TRIM($A11),$S10) | T11: =IF(AND(ISNUMBER(SEARCH("Folio",$A11)),$D11<>""),1,"") | U11: =IF($T11=1,COUNTIF($T$9:$T11,1),"") | V11: =IF(AND(ISTEXT($A11),LEFT($A12,3)="Pan"),1,"") | W11: =IFERROR(MATCH(3,$U$9:$U$2008,0),"") | X11: =IF($W11="","",IF($R$5<>"",$R$5,$R$6)) | Y11: =IF($W11="","",INDEX($S$9:$S$2008,$W11)) | Z11: =IF($W11="","",IFERROR(TRIM(LEFT(SUBSTITUTE(INDEX($A$9:$A$2008,$W11),CHAR(10)," "),SEARCH("Folio",SUBSTITUTE(INDEX($A$9:$A$2008,$W11),CHAR(10)," "))-1)),TRIM(SUBSTITUTE(INDEX($A$9:$A$2008,$W11),CHAR(10)," ")))) | AA11: =IF($W11="","",IFERROR(TRIM(SUBSTITUTE(MID(SUBSTITUTE(INDEX($A$9:$A$2008,$W11),CHAR(10)," "),SEARCH("Folio",SUBSTITUTE(INDEX($A$9:$A$2008,$W11),CHAR(10)," "))+5,200),":","")),"")) | AB11: =IF($W11="","",IF(ISNUMBER(INDEX($D$9:$D$2008,$W11)),INDEX($D$9:$D$2008,$W11),IFERROR(DATE(2000+VALUE(RIGHT(INDEX($D$9:$D$2008,$W11),2)),VALUE(MID(INDEX($D$9:$D$2008,$W11),4,2)),VALUE(LEFT(INDEX($D$9:$D$2008,$W11),2))),""))) | AC11: =IF($W11="","",IFERROR(IF(ISNUMBER(INDEX($E$9:$E$2008,$W11)),INDEX($E$9:$E$2008,$W11),VALUE(SUBSTITUTE(INDEX($E$9:$E$2008,$W11),",",""))),"")) | AD11: =IF($W11="","",IFERROR(IF(ISNUMBER(INDEX($F$9:$F$2008,$W11)),INDEX($F$9:$F$2008,$W11),VALUE(SUBSTITUTE(INDEX($F$9:$F$2008,$W11),",",""))),"")) | AE11: =IF($W11="","",IFERROR(IF(ISNUMBER(INDEX($G$9:$G$2008,$W11)),INDEX($G$9:$G$2008,$W11),VALUE(SUBSTITUTE(INDEX($G$9:$G$2008,$W11),",",""))),"")) | AF11: =IF($W11="","",IFERROR(IF(ISNUMBER(INDEX($H$9:$H$2008,$W11)),INDEX($H$9:$H$2008,$W11),VALUE(SUBSTITUTE(INDEX($H$9:$H$2008,$W11),",",""))),"")) | AG11: =IF($W11="","",IFERROR(IF(ISNUMBER(INDEX($I$9:$I$2008,$W11)),INDEX($I$9:$I$2008,$W11),VALUE(SUBSTITUTE(INDEX($I$9:$I$2008,$W11),",",""))),"")) | AH11: =IF($W11="","",IFERROR(IF(ISNUMBER(INDEX($J$9:$J$2008,$W11)),INDEX($J$9:$J$2008,$W11),VALUE(SUBSTITUTE(INDEX($J$9:$J$2008,$W11),",",""))),"")) | AI11: =IF($W11="","",IFERROR(IF(ISNUMBER(INDEX($K$9:$K$2008,$W11)),INDEX($K$9:$K$2008,$W11),VALUE(SUBSTITUTE(INDEX($K$9:$K$2008,$W11),",",""))),"")) | AJ11: =IF($W11="","",IFERROR(IF(ISNUMBER(INDEX($L$9:$L$2008,$W11)),INDEX($L$9:$L$2008,$W11),VALUE(SUBSTITUTE(INDEX($L$9:$L$2008,$W11),",",""))),"")) | AK11: =IF($W11="","",IFERROR(IF(ISNUMBER(INDEX($M$9:$M$2008,$W11)),INDEX($M$9:$M$2008,$W11),VALUE(SUBSTITUTE(INDEX($M$9:$M$2008,$W11),",",""))),"")) | AL11: =IF($W11="","",IFERROR(IF(ISNUMBER(INDEX($P$9:$P$2008,$W11)),INDEX($P$9:$P$2008,$W11),VALUE(SUBSTITUTE(INDEX($P$9:$P$2008,$W11),"%",""))/100),""))
S12: =IF(AND(ISTEXT($A12),ISNUMBER(SEARCH(" - ",$A12)),ISERROR(SEARCH("Folio",$A12)),$D12=""),TRIM($A12),$S11) | T12: =IF(AND(ISNUMBER(SEARCH("Folio",$A12)),$D12<>""),1,"") | U12: =IF($T12=1,COUNTIF($T$9:$T12,1),"") | V12: =IF(AND(ISTEXT($A12),LEFT($A13,3)="Pan"),1,"") | W12: =IFERROR(MATCH(4,$U$9:$U$2008,0),"") | X12: =IF($W12="","",IF($R$5<>"",$R$5,$R$6)) | Y12: =IF($W12="","",INDEX($S$9:$S$2008,$W12)) | Z12: =IF($W12="","",IFERROR(TRIM(LEFT(SUBSTITUTE(INDEX($A$9:$A$2008,$W12),CHAR(10)," "),SEARCH("Folio",SUBSTITUTE(INDEX($A$9:$A$2008,$W12),CHAR(10)," "))-1)),TRIM(SUBSTITUTE(INDEX($A$9:$A$2008,$W12),CHAR(10)," ")))) | AA12: =IF($W12="","",IFERROR(TRIM(SUBSTITUTE(MID(SUBSTITUTE(INDEX($A$9:$A$2008,$W12),CHAR(10)," "),SEARCH("Folio",SUBSTITUTE(INDEX($A$9:$A$2008,$W12),CHAR(10)," "))+5,200),":","")),"")) | AB12: =IF($W12="","",IF(ISNUMBER(INDEX($D$9:$D$2008,$W12)),INDEX($D$9:$D$2008,$W12),IFERROR(DATE(2000+VALUE(RIGHT(INDEX($D$9:$D$2008,$W12),2)),VALUE(MID(INDEX($D$9:$D$2008,$W12),4,2)),VALUE(LEFT(INDEX($D$9:$D$2008,$W12),2))),""))) | AC12: =IF($W12="","",IFERROR(IF(ISNUMBER(INDEX($E$9:$E$2008,$W12)),INDEX($E$9:$E$2008,$W12),VALUE(SUBSTITUTE(INDEX($E$9:$E$2008,$W12),",",""))),"")) | AD12: =IF($W12="","",IFERROR(IF(ISNUMBER(INDEX($F$9:$F$2008,$W12)),INDEX($F$9:$F$2008,$W12),VALUE(SUBSTITUTE(INDEX($F$9:$F$2008,$W12),",",""))),"")) | AE12: =IF($W12="","",IFERROR(IF(ISNUMBER(INDEX($G$9:$G$2008,$W12)),INDEX($G$9:$G$2008,$W12),VALUE(SUBSTITUTE(INDEX($G$9:$G$2008,$W12),",",""))),"")) | AF12: =IF($W12="","",IFERROR(IF(ISNUMBER(INDEX($H$9:$H$2008,$W12)),INDEX($H$9:$H$2008,$W12),VALUE(SUBSTITUTE(INDEX($H$9:$H$2008,$W12),",",""))),"")) | AG12: =IF($W12="","",IFERROR(IF(ISNUMBER(INDEX($I$9:$I$2008,$W12)),INDEX($I$9:$I$2008,$W12),VALUE(SUBSTITUTE(INDEX($I$9:$I$2008,$W12),",",""))),"")) | AH12: =IF($W12="","",IFERROR(IF(ISNUMBER(INDEX($J$9:$J$2008,$W12)),INDEX($J$9:$J$2008,$W12),VALUE(SUBSTITUTE(INDEX($J$9:$J$2008,$W12),",",""))),"")) | AI12: =IF($W12="","",IFERROR(IF(ISNUMBER(INDEX($K$9:$K$2008,$W12)),INDEX($K$9:$K$2008,$W12),VALUE(SUBSTITUTE(INDEX($K$9:$K$2008,$W12),",",""))),"")) | AJ12: =IF($W12="","",IFERROR(IF(ISNUMBER(INDEX($L$9:$L$2008,$W12)),INDEX($L$9:$L$2008,$W12),VALUE(SUBSTITUTE(INDEX($L$9:$L$2008,$W12),",",""))),"")) | AK12: =IF($W12="","",IFERROR(IF(ISNUMBER(INDEX($M$9:$M$2008,$W12)),INDEX($M$9:$M$2008,$W12),VALUE(SUBSTITUTE(INDEX($M$9:$M$2008,$W12),",",""))),"")) | AL12: =IF($W12="","",IFERROR(IF(ISNUMBER(INDEX($P$9:$P$2008,$W12)),INDEX($P$9:$P$2008,$W12),VALUE(SUBSTITUTE(INDEX($P$9:$P$2008,$W12),"%",""))/100),""))
S13: =IF(AND(ISTEXT($A13),ISNUMBER(SEARCH(" - ",$A13)),ISERROR(SEARCH("Folio",$A13)),$D13=""),TRIM($A13),$S12) | T13: =IF(AND(ISNUMBER(SEARCH("Folio",$A13)),$D13<>""),1,"") | U13: =IF($T13=1,COUNTIF($T$9:$T13,1),"") | V13: =IF(AND(ISTEXT($A13),LEFT($A14,3)="Pan"),1,"") | W13: =IFERROR(MATCH(5,$U$9:$U$2008,0),"") | X13: =IF($W13="","",IF($R$5<>"",$R$5,$R$6)) | Y13: =IF($W13="","",INDEX($S$9:$S$2008,$W13)) | Z13: =IF($W13="","",IFERROR(TRIM(LEFT(SUBSTITUTE(INDEX($A$9:$A$2008,$W13),CHAR(10)," "),SEARCH("Folio",SUBSTITUTE(INDEX($A$9:$A$2008,$W13),CHAR(10)," "))-1)),TRIM(SUBSTITUTE(INDEX($A$9:$A$2008,$W13),CHAR(10)," ")))) | AA13: =IF($W13="","",IFERROR(TRIM(SUBSTITUTE(MID(SUBSTITUTE(INDEX($A$9:$A$2008,$W13),CHAR(10)," "),SEARCH("Folio",SUBSTITUTE(INDEX($A$9:$A$2008,$W13),CHAR(10)," "))+5,200),":","")),"")) | AB13: =IF($W13="","",IF(ISNUMBER(INDEX($D$9:$D$2008,$W13)),INDEX($D$9:$D$2008,$W13),IFERROR(DATE(2000+VALUE(RIGHT(INDEX($D$9:$D$2008,$W13),2)),VALUE(MID(INDEX($D$9:$D$2008,$W13),4,2)),VALUE(LEFT(INDEX($D$9:$D$2008,$W13),2))),""))) | AC13: =IF($W13="","",IFERROR(IF(ISNUMBER(INDEX($E$9:$E$2008,$W13)),INDEX($E$9:$E$2008,$W13),VALUE(SUBSTITUTE(INDEX($E$9:$E$2008,$W13),",",""))),"")) | AD13: =IF($W13="","",IFERROR(IF(ISNUMBER(INDEX($F$9:$F$2008,$W13)),INDEX($F$9:$F$2008,$W13),VALUE(SUBSTITUTE(INDEX($F$9:$F$2008,$W13),",",""))),"")) | AE13: =IF($W13="","",IFERROR(IF(ISNUMBER(INDEX($G$9:$G$2008,$W13)),INDEX($G$9:$G$2008,$W13),VALUE(SUBSTITUTE(INDEX($G$9:$G$2008,$W13),",",""))),"")) | AF13: =IF($W13="","",IFERROR(IF(ISNUMBER(INDEX($H$9:$H$2008,$W13)),INDEX($H$9:$H$2008,$W13),VALUE(SUBSTITUTE(INDEX($H$9:$H$2008,$W13),",",""))),"")) | AG13: =IF($W13="","",IFERROR(IF(ISNUMBER(INDEX($I$9:$I$2008,$W13)),INDEX($I$9:$I$2008,$W13),VALUE(SUBSTITUTE(INDEX($I$9:$I$2008,$W13),",",""))),"")) | AH13: =IF($W13="","",IFERROR(IF(ISNUMBER(INDEX($J$9:$J$2008,$W13)),INDEX($J$9:$J$2008,$W13),VALUE(SUBSTITUTE(INDEX($J$9:$J$2008,$W13),",",""))),"")) | AI13: =IF($W13="","",IFERROR(IF(ISNUMBER(INDEX($K$9:$K$2008,$W13)),INDEX($K$9:$K$2008,$W13),VALUE(SUBSTITUTE(INDEX($K$9:$K$2008,$W13),",",""))),"")) | AJ13: =IF($W13="","",IFERROR(IF(ISNUMBER(INDEX($L$9:$L$2008,$W13)),INDEX($L$9:$L$2008,$W13),VALUE(SUBSTITUTE(INDEX($L$9:$L$2008,$W13),",",""))),"")) | AK13: =IF($W13="","",IFERROR(IF(ISNUMBER(INDEX($M$9:$M$2008,$W13)),INDEX($M$9:$M$2008,$W13),VALUE(SUBSTITUTE(INDEX($M$9:$M$2008,$W13),",",""))),"")) | AL13: =IF($W13="","",IFERROR(IF(ISNUMBER(INDEX($P$9:$P$2008,$W13)),INDEX($P$9:$P$2008,$W13),VALUE(SUBSTITUTE(INDEX($P$9:$P$2008,$W13),"%",""))/100),""))
S14: =IF(AND(ISTEXT($A14),ISNUMBER(SEARCH(" - ",$A14)),ISERROR(SEARCH("Folio",$A14)),$D14=""),TRIM($A14),$S13) | T14: =IF(AND(ISNUMBER(SEARCH("Folio",$A14)),$D14<>""),1,"") | U14: =IF($T14=1,COUNTIF($T$9:$T14,1),"") | V14: =IF(AND(ISTEXT($A14),LEFT($A15,3)="Pan"),1,"") | W14: =IFERROR(MATCH(6,$U$9:$U$2008,0),"") | X14: =IF($W14="","",IF($R$5<>"",$R$5,$R$6)) | Y14: =IF($W14="","",INDEX($S$9:$S$2008,$W14)) | Z14: =IF($W14="","",IFERROR(TRIM(LEFT(SUBSTITUTE(INDEX($A$9:$A$2008,$W14),CHAR(10)," "),SEARCH("Folio",SUBSTITUTE(INDEX($A$9:$A$2008,$W14),CHAR(10)," "))-1)),TRIM(SUBSTITUTE(INDEX($A$9:$A$2008,$W14),CHAR(10)," ")))) | AA14: =IF($W14="","",IFERROR(TRIM(SUBSTITUTE(MID(SUBSTITUTE(INDEX($A$9:$A$2008,$W14),CHAR(10)," "),SEARCH("Folio",SUBSTITUTE(INDEX($A$9:$A$2008,$W14),CHAR(10)," "))+5,200),":","")),"")) | AB14: =IF($W14="","",IF(ISNUMBER(INDEX($D$9:$D$2008,$W14)),INDEX($D$9:$D$2008,$W14),IFERROR(DATE(2000+VALUE(RIGHT(INDEX($D$9:$D$2008,$W14),2)),VALUE(MID(INDEX($D$9:$D$2008,$W14),4,2)),VALUE(LEFT(INDEX($D$9:$D$2008,$W14),2))),""))) | AC14: =IF($W14="","",IFERROR(IF(ISNUMBER(INDEX($E$9:$E$2008,$W14)),INDEX($E$9:$E$2008,$W14),VALUE(SUBSTITUTE(INDEX($E$9:$E$2008,$W14),",",""))),"")) | AD14: =IF($W14="","",IFERROR(IF(ISNUMBER(INDEX($F$9:$F$2008,$W14)),INDEX($F$9:$F$2008,$W14),VALUE(SUBSTITUTE(INDEX($F$9:$F$2008,$W14),",",""))),"")) | AE14: =IF($W14="","",IFERROR(IF(ISNUMBER(INDEX($G$9:$G$2008,$W14)),INDEX($G$9:$G$2008,$W14),VALUE(SUBSTITUTE(INDEX($G$9:$G$2008,$W14),",",""))),"")) | AF14: =IF($W14="","",IFERROR(IF(ISNUMBER(INDEX($H$9:$H$2008,$W14)),INDEX($H$9:$H$2008,$W14),VALUE(SUBSTITUTE(INDEX($H$9:$H$2008,$W14),",",""))),"")) | AG14: =IF($W14="","",IFERROR(IF(ISNUMBER(INDEX($I$9:$I$2008,$W14)),INDEX($I$9:$I$2008,$W14),VALUE(SUBSTITUTE(INDEX($I$9:$I$2008,$W14),",",""))),"")) | AH14: =IF($W14="","",IFERROR(IF(ISNUMBER(INDEX($J$9:$J$2008,$W14)),INDEX($J$9:$J$2008,$W14),VALUE(SUBSTITUTE(INDEX($J$9:$J$2008,$W14),",",""))),"")) | AI14: =IF($W14="","",IFERROR(IF(ISNUMBER(INDEX($K$9:$K$2008,$W14)),INDEX($K$9:$K$2008,$W14),VALUE(SUBSTITUTE(INDEX($K$9:$K$2008,$W14),",",""))),"")) | AJ14: =IF($W14="","",IFERROR(IF(ISNUMBER(INDEX($L$9:$L$2008,$W14)),INDEX($L$9:$L$2008,$W14),VALUE(SUBSTITUTE(INDEX($L$9:$L$2008,$W14),",",""))),"")) | AK14: =IF($W14="","",IFERROR(IF(ISNUMBER(INDEX($M$9:$M$2008,$W14)),INDEX($M$9:$M$2008,$W14),VALUE(SUBSTITUTE(INDEX($M$9:$M$2008,$W14),",",""))),"")) | AL14: =IF($W14="","",IFERROR(IF(ISNUMBER(INDEX($P$9:$P$2008,$W14)),INDEX($P$9:$P$2008,$W14),VALUE(SUBSTITUTE(INDEX($P$9:$P$2008,$W14),"%",""))/100),""))
S15: =IF(AND(ISTEXT($A15),ISNUMBER(SEARCH(" - ",$A15)),ISERROR(SEARCH("Folio",$A15)),$D15=""),TRIM($A15),$S14) | T15: =IF(AND(ISNUMBER(SEARCH("Folio",$A15)),$D15<>""),1,"") | U15: =IF($T15=1,COUNTIF($T$9:$T15,1),"") | V15: =IF(AND(ISTEXT($A15),LEFT($A16,3)="Pan"),1,"") | W15: =IFERROR(MATCH(7,$U$9:$U$2008,0),"") | X15: =IF($W15="","",IF($R$5<>"",$R$5,$R$6)) | Y15: =IF($W15="","",INDEX($S$9:$S$2008,$W15)) | Z15: =IF($W15="","",IFERROR(TRIM(LEFT(SUBSTITUTE(INDEX($A$9:$A$2008,$W15),CHAR(10)," "),SEARCH("Folio",SUBSTITUTE(INDEX($A$9:$A$2008,$W15),CHAR(10)," "))-1)),TRIM(SUBSTITUTE(INDEX($A$9:$A$2008,$W15),CHAR(10)," ")))) | AA15: =IF($W15="","",IFERROR(TRIM(SUBSTITUTE(MID(SUBSTITUTE(INDEX($A$9:$A$2008,$W15),CHAR(10)," "),SEARCH("Folio",SUBSTITUTE(INDEX($A$9:$A$2008,$W15),CHAR(10)," "))+5,200),":","")),"")) | AB15: =IF($W15="","",IF(ISNUMBER(INDEX($D$9:$D$2008,$W15)),INDEX($D$9:$D$2008,$W15),IFERROR(DATE(2000+VALUE(RIGHT(INDEX($D$9:$D$2008,$W15),2)),VALUE(MID(INDEX($D$9:$D$2008,$W15),4,2)),VALUE(LEFT(INDEX($D$9:$D$2008,$W15),2))),""))) | AC15: =IF($W15="","",IFERROR(IF(ISNUMBER(INDEX($E$9:$E$2008,$W15)),INDEX($E$9:$E$2008,$W15),VALUE(SUBSTITUTE(INDEX($E$9:$E$2008,$W15),",",""))),"")) | AD15: =IF($W15="","",IFERROR(IF(ISNUMBER(INDEX($F$9:$F$2008,$W15)),INDEX($F$9:$F$2008,$W15),VALUE(SUBSTITUTE(INDEX($F$9:$F$2008,$W15),",",""))),"")) | AE15: =IF($W15="","",IFERROR(IF(ISNUMBER(INDEX($G$9:$G$2008,$W15)),INDEX($G$9:$G$2008,$W15),VALUE(SUBSTITUTE(INDEX($G$9:$G$2008,$W15),",",""))),"")) | AF15: =IF($W15="","",IFERROR(IF(ISNUMBER(INDEX($H$9:$H$2008,$W15)),INDEX($H$9:$H$2008,$W15),VALUE(SUBSTITUTE(INDEX($H$9:$H$2008,$W15),",",""))),"")) | AG15: =IF($W15="","",IFERROR(IF(ISNUMBER(INDEX($I$9:$I$2008,$W15)),INDEX($I$9:$I$2008,$W15),VALUE(SUBSTITUTE(INDEX($I$9:$I$2008,$W15),",",""))),"")) | AH15: =IF($W15="","",IFERROR(IF(ISNUMBER(INDEX($J$9:$J$2008,$W15)),INDEX($J$9:$J$2008,$W15),VALUE(SUBSTITUTE(INDEX($J$9:$J$2008,$W15),",",""))),"")) | AI15: =IF($W15="","",IFERROR(IF(ISNUMBER(INDEX($K$9:$K$2008,$W15)),INDEX($K$9:$K$2008,$W15),VALUE(SUBSTITUTE(INDEX($K$9:$K$2008,$W15),",",""))),"")) | AJ15: =IF($W15="","",IFERROR(IF(ISNUMBER(INDEX($L$9:$L$2008,$W15)),INDEX($L$9:$L$2008,$W15),VALUE(SUBSTITUTE(INDEX($L$9:$L$2008,$W15),",",""))),"")) | AK15: =IF($W15="","",IFERROR(IF(ISNUMBER(INDEX($M$9:$M$2008,$W15)),INDEX($M$9:$M$2008,$W15),VALUE(SUBSTITUTE(INDEX($M$9:$M$2008,$W15),",",""))),"")) | AL15: =IF($W15="","",IFERROR(IF(ISNUMBER(INDEX($P$9:$P$2008,$W15)),INDEX($P$9:$P$2008,$W15),VALUE(SUBSTITUTE(INDEX($P$9:$P$2008,$W15),"%",""))/100),""))
S16: =IF(AND(ISTEXT($A16),ISNUMBER(SEARCH(" - ",$A16)),ISERROR(SEARCH("Folio",$A16)),$D16=""),TRIM($A16),$S15) | T16: =IF(AND(ISNUMBER(SEARCH("Folio",$A16)),$D16<>""),1,"") | U16: =IF($T16=1,COUNTIF($T$9:$T16,1),"") | V16: =IF(AND(ISTEXT($A16),LEFT($A17,3)="Pan"),1,"") | W16: =IFERROR(MATCH(8,$U$9:$U$2008,0),"") | X16: =IF($W16="","",IF($R$5<>"",$R$5,$R$6)) | Y16: =IF($W16="","",INDEX($S$9:$S$2008,$W16)) | Z16: =IF($W16="","",IFERROR(TRIM(LEFT(SUBSTITUTE(INDEX($A$9:$A$2008,$W16),CHAR(10)," "),SEARCH("Folio",SUBSTITUTE(INDEX($A$9:$A$2008,$W16),CHAR(10)," "))-1)),TRIM(SUBSTITUTE(INDEX($A$9:$A$2008,$W16),CHAR(10)," ")))) | AA16: =IF($W16="","",IFERROR(TRIM(SUBSTITUTE(MID(SUBSTITUTE(INDEX($A$9:$A$2008,$W16),CHAR(10)," "),SEARCH("Folio",SUBSTITUTE(INDEX($A$9:$A$2008,$W16),CHAR(10)," "))+5,200),":","")),"")) | AB16: =IF($W16="","",IF(ISNUMBER(INDEX($D$9:$D$2008,$W16)),INDEX($D$9:$D$2008,$W16),IFERROR(DATE(2000+VALUE(RIGHT(INDEX($D$9:$D$2008,$W16),2)),VALUE(MID(INDEX($D$9:$D$2008,$W16),4,2)),VALUE(LEFT(INDEX($D$9:$D$2008,$W16),2))),""))) | AC16: =IF($W16="","",IFERROR(IF(ISNUMBER(INDEX($E$9:$E$2008,$W16)),INDEX($E$9:$E$2008,$W16),VALUE(SUBSTITUTE(INDEX($E$9:$E$2008,$W16),",",""))),"")) | AD16: =IF($W16="","",IFERROR(IF(ISNUMBER(INDEX($F$9:$F$2008,$W16)),INDEX($F$9:$F$2008,$W16),VALUE(SUBSTITUTE(INDEX($F$9:$F$2008,$W16),",",""))),"")) | AE16: =IF($W16="","",IFERROR(IF(ISNUMBER(INDEX($G$9:$G$2008,$W16)),INDEX($G$9:$G$2008,$W16),VALUE(SUBSTITUTE(INDEX($G$9:$G$2008,$W16),",",""))),"")) | AF16: =IF($W16="","",IFERROR(IF(ISNUMBER(INDEX($H$9:$H$2008,$W16)),INDEX($H$9:$H$2008,$W16),VALUE(SUBSTITUTE(INDEX($H$9:$H$2008,$W16),",",""))),"")) | AG16: =IF($W16="","",IFERROR(IF(ISNUMBER(INDEX($I$9:$I$2008,$W16)),INDEX($I$9:$I$2008,$W16),VALUE(SUBSTITUTE(INDEX($I$9:$I$2008,$W16),",",""))),"")) | AH16: =IF($W16="","",IFERROR(IF(ISNUMBER(INDEX($J$9:$J$2008,$W16)),INDEX($J$9:$J$2008,$W16),VALUE(SUBSTITUTE(INDEX($J$9:$J$2008,$W16),",",""))),"")) | AI16: =IF($W16="","",IFERROR(IF(ISNUMBER(INDEX($K$9:$K$2008,$W16)),INDEX($K$9:$K$2008,$W16),VALUE(SUBSTITUTE(INDEX($K$9:$K$2008,$W16),",",""))),"")) | AJ16: =IF($W16="","",IFERROR(IF(ISNUMBER(INDEX($L$9:$L$2008,$W16)),INDEX($L$9:$L$2008,$W16),VALUE(SUBSTITUTE(INDEX($L$9:$L$2008,$W16),",",""))),"")) | AK16: =IF($W16="","",IFERROR(IF(ISNUMBER(INDEX($M$9:$M$2008,$W16)),INDEX($M$9:$M$2008,$W16),VALUE(SUBSTITUTE(INDEX($M$9:$M$2008,$W16),",",""))),"")) | AL16: =IF($W16="","",IFERROR(IF(ISNUMBER(INDEX($P$9:$P$2008,$W16)),INDEX($P$9:$P$2008,$W16),VALUE(SUBSTITUTE(INDEX($P$9:$P$2008,$W16),"%",""))/100),""))
S17: =IF(AND(ISTEXT($A17),ISNUMBER(SEARCH(" - ",$A17)),ISERROR(SEARCH("Folio",$A17)),$D17=""),TRIM($A17),$S16) | T17: =IF(AND(ISNUMBER(SEARCH("Folio",$A17)),$D17<>""),1,"") | U17: =IF($T17=1,COUNTIF($T$9:$T17,1),"") | V17: =IF(AND(ISTEXT($A17),LEFT($A18,3)="Pan"),1,"") | W17: =IFERROR(MATCH(9,$U$9:$U$2008,0),"") | X17: =IF($W17="","",IF($R$5<>"",$R$5,$R$6)) | Y17: =IF($W17="","",INDEX($S$9:$S$2008,$W17)) | Z17: =IF($W17="","",IFERROR(TRIM(LEFT(SUBSTITUTE(INDEX($A$9:$A$2008,$W17),CHAR(10)," "),SEARCH("Folio",SUBSTITUTE(INDEX($A$9:$A$2008,$W17),CHAR(10)," "))-1)),TRIM(SUBSTITUTE(INDEX($A$9:$A$2008,$W17),CHAR(10)," ")))) | AA17: =IF($W17="","",IFERROR(TRIM(SUBSTITUTE(MID(SUBSTITUTE(INDEX($A$9:$A$2008,$W17),CHAR(10)," "),SEARCH("Folio",SUBSTITUTE(INDEX($A$9:$A$2008,$W17),CHAR(10)," "))+5,200),":","")),"")) | AB17: =IF($W17="","",IF(ISNUMBER(INDEX($D$9:$D$2008,$W17)),INDEX($D$9:$D$2008,$W17),IFERROR(DATE(2000+VALUE(RIGHT(INDEX($D$9:$D$2008,$W17),2)),VALUE(MID(INDEX($D$9:$D$2008,$W17),4,2)),VALUE(LEFT(INDEX($D$9:$D$2008,$W17),2))),""))) | AC17: =IF($W17="","",IFERROR(IF(ISNUMBER(INDEX($E$9:$E$2008,$W17)),INDEX($E$9:$E$2008,$W17),VALUE(SUBSTITUTE(INDEX($E$9:$E$2008,$W17),",",""))),"")) | AD17: =IF($W17="","",IFERROR(IF(ISNUMBER(INDEX($F$9:$F$2008,$W17)),INDEX($F$9:$F$2008,$W17),VALUE(SUBSTITUTE(INDEX($F$9:$F$2008,$W17),",",""))),"")) | AE17: =IF($W17="","",IFERROR(IF(ISNUMBER(INDEX($G$9:$G$2008,$W17)),INDEX($G$9:$G$2008,$W17),VALUE(SUBSTITUTE(INDEX($G$9:$G$2008,$W17),",",""))),"")) | AF17: =IF($W17="","",IFERROR(IF(ISNUMBER(INDEX($H$9:$H$2008,$W17)),INDEX($H$9:$H$2008,$W17),VALUE(SUBSTITUTE(INDEX($H$9:$H$2008,$W17),",",""))),"")) | AG17: =IF($W17="","",IFERROR(IF(ISNUMBER(INDEX($I$9:$I$2008,$W17)),INDEX($I$9:$I$2008,$W17),VALUE(SUBSTITUTE(INDEX($I$9:$I$2008,$W17),",",""))),"")) | AH17: =IF($W17="","",IFERROR(IF(ISNUMBER(INDEX($J$9:$J$2008,$W17)),INDEX($J$9:$J$2008,$W17),VALUE(SUBSTITUTE(INDEX($J$9:$J$2008,$W17),",",""))),"")) | AI17: =IF($W17="","",IFERROR(IF(ISNUMBER(INDEX($K$9:$K$2008,$W17)),INDEX($K$9:$K$2008,$W17),VALUE(SUBSTITUTE(INDEX($K$9:$K$2008,$W17),",",""))),"")) | AJ17: =IF($W17="","",IFERROR(IF(ISNUMBER(INDEX($L$9:$L$2008,$W17)),INDEX($L$9:$L$2008,$W17),VALUE(SUBSTITUTE(INDEX($L$9:$L$2008,$W17),",",""))),"")) | AK17: =IF($W17="","",IFERROR(IF(ISNUMBER(INDEX($M$9:$M$2008,$W17)),INDEX($M$9:$M$2008,$W17),VALUE(SUBSTITUTE(INDEX($M$9:$M$2008,$W17),",",""))),"")) | AL17: =IF($W17="","",IFERROR(IF(ISNUMBER(INDEX($P$9:$P$2008,$W17)),INDEX($P$9:$P$2008,$W17),VALUE(SUBSTITUTE(INDEX($P$9:$P$2008,$W17),"%",""))/100),""))
S18: =IF(AND(ISTEXT($A18),ISNUMBER(SEARCH(" - ",$A18)),ISERROR(SEARCH("Folio",$A18)),$D18=""),TRIM($A18),$S17) | T18: =IF(AND(ISNUMBER(SEARCH("Folio",$A18)),$D18<>""),1,"") | U18: =IF($T18=1,COUNTIF($T$9:$T18,1),"") | V18: =IF(AND(ISTEXT($A18),LEFT($A19,3)="Pan"),1,"") | W18: =IFERROR(MATCH(10,$U$9:$U$2008,0),"") | X18: =IF($W18="","",IF($R$5<>"",$R$5,$R$6)) | Y18: =IF($W18="","",INDEX($S$9:$S$2008,$W18)) | Z18: =IF($W18="","",IFERROR(TRIM(LEFT(SUBSTITUTE(INDEX($A$9:$A$2008,$W18),CHAR(10)," "),SEARCH("Folio",SUBSTITUTE(INDEX($A$9:$A$2008,$W18),CHAR(10)," "))-1)),TRIM(SUBSTITUTE(INDEX($A$9:$A$2008,$W18),CHAR(10)," ")))) | AA18: =IF($W18="","",IFERROR(TRIM(SUBSTITUTE(MID(SUBSTITUTE(INDEX($A$9:$A$2008,$W18),CHAR(10)," "),SEARCH("Folio",SUBSTITUTE(INDEX($A$9:$A$2008,$W18),CHAR(10)," "))+5,200),":","")),"")) | AB18: =IF($W18="","",IF(ISNUMBER(INDEX($D$9:$D$2008,$W18)),INDEX($D$9:$D$2008,$W18),IFERROR(DATE(2000+VALUE(RIGHT(INDEX($D$9:$D$2008,$W18),2)),VALUE(MID(INDEX($D$9:$D$2008,$W18),4,2)),VALUE(LEFT(INDEX($D$9:$D$2008,$W18),2))),""))) | AC18: =IF($W18="","",IFERROR(IF(ISNUMBER(INDEX($E$9:$E$2008,$W18)),INDEX($E$9:$E$2008,$W18),VALUE(SUBSTITUTE(INDEX($E$9:$E$2008,$W18),",",""))),"")) | AD18: =IF($W18="","",IFERROR(IF(ISNUMBER(INDEX($F$9:$F$2008,$W18)),INDEX($F$9:$F$2008,$W18),VALUE(SUBSTITUTE(INDEX($F$9:$F$2008,$W18),",",""))),"")) | AE18: =IF($W18="","",IFERROR(IF(ISNUMBER(INDEX($G$9:$G$2008,$W18)),INDEX($G$9:$G$2008,$W18),VALUE(SUBSTITUTE(INDEX($G$9:$G$2008,$W18),",",""))),"")) | AF18: =IF($W18="","",IFERROR(IF(ISNUMBER(INDEX($H$9:$H$2008,$W18)),INDEX($H$9:$H$2008,$W18),VALUE(SUBSTITUTE(INDEX($H$9:$H$2008,$W18),",",""))),"")) | AG18: =IF($W18="","",IFERROR(IF(ISNUMBER(INDEX($I$9:$I$2008,$W18)),INDEX($I$9:$I$2008,$W18),VALUE(SUBSTITUTE(INDEX($I$9:$I$2008,$W18),",",""))),"")) | AH18: =IF($W18="","",IFERROR(IF(ISNUMBER(INDEX($J$9:$J$2008,$W18)),INDEX($J$9:$J$2008,$W18),VALUE(SUBSTITUTE(INDEX($J$9:$J$2008,$W18),",",""))),"")) | AI18: =IF($W18="","",IFERROR(IF(ISNUMBER(INDEX($K$9:$K$2008,$W18)),INDEX($K$9:$K$2008,$W18),VALUE(SUBSTITUTE(INDEX($K$9:$K$2008,$W18),",",""))),"")) | AJ18: =IF($W18="","",IFERROR(IF(ISNUMBER(INDEX($L$9:$L$2008,$W18)),INDEX($L$9:$L$2008,$W18),VALUE(SUBSTITUTE(INDEX($L$9:$L$2008,$W18),",",""))),"")) | AK18: =IF($W18="","",IFERROR(IF(ISNUMBER(INDEX($M$9:$M$2008,$W18)),INDEX($M$9:$M$2008,$W18),VALUE(SUBSTITUTE(INDEX($M$9:$M$2008,$W18),",",""))),"")) | AL18: =IF($W18="","",IFERROR(IF(ISNUMBER(INDEX($P$9:$P$2008,$W18)),INDEX($P$9:$P$2008,$W18),VALUE(SUBSTITUTE(INDEX($P$9:$P$2008,$W18),"%",""))/100),""))
S19: =IF(AND(ISTEXT($A19),ISNUMBER(SEARCH(" - ",$A19)),ISERROR(SEARCH("Folio",$A19)),$D19=""),TRIM($A19),$S18) | T19: =IF(AND(ISNUMBER(SEARCH("Folio",$A19)),$D19<>""),1,"") | U19: =IF($T19=1,COUNTIF($T$9:$T19,1),"") | V19: =IF(AND(ISTEXT($A19),LEFT($A20,3)="Pan"),1,"") | W19: =IFERROR(MATCH(11,$U$9:$U$2008,0),"") | X19: =IF($W19="","",IF($R$5<>"",$R$5,$R$6)) | Y19: =IF($W19="","",INDEX($S$9:$S$2008,$W19)) | Z19: =IF($W19="","",IFERROR(TRIM(LEFT(SUBSTITUTE(INDEX($A$9:$A$2008,$W19),CHAR(10)," "),SEARCH("Folio",SUBSTITUTE(INDEX($A$9:$A$2008,$W19),CHAR(10)," "))-1)),TRIM(SUBSTITUTE(INDEX($A$9:$A$2008,$W19),CHAR(10)," ")))) | AA19: =IF($W19="","",IFERROR(TRIM(SUBSTITUTE(MID(SUBSTITUTE(INDEX($A$9:$A$2008,$W19),CHAR(10)," "),SEARCH("Folio",SUBSTITUTE(INDEX($A$9:$A$2008,$W19),CHAR(10)," "))+5,200),":","")),"")) | AB19: =IF($W19="","",IF(ISNUMBER(INDEX($D$9:$D$2008,$W19)),INDEX($D$9:$D$2008,$W19),IFERROR(DATE(2000+VALUE(RIGHT(INDEX($D$9:$D$2008,$W19),2)),VALUE(MID(INDEX($D$9:$D$2008,$W19),4,2)),VALUE(LEFT(INDEX($D$9:$D$2008,$W19),2))),""))) | AC19: =IF($W19="","",IFERROR(IF(ISNUMBER(INDEX($E$9:$E$2008,$W19)),INDEX($E$9:$E$2008,$W19),VALUE(SUBSTITUTE(INDEX($E$9:$E$2008,$W19),",",""))),"")) | AD19: =IF($W19="","",IFERROR(IF(ISNUMBER(INDEX($F$9:$F$2008,$W19)),INDEX($F$9:$F$2008,$W19),VALUE(SUBSTITUTE(INDEX($F$9:$F$2008,$W19),",",""))),"")) | AE19: =IF($W19="","",IFERROR(IF(ISNUMBER(INDEX($G$9:$G$2008,$W19)),INDEX($G$9:$G$2008,$W19),VALUE(SUBSTITUTE(INDEX($G$9:$G$2008,$W19),",",""))),"")) | AF19: =IF($W19="","",IFERROR(IF(ISNUMBER(INDEX($H$9:$H$2008,$W19)),INDEX($H$9:$H$2008,$W19),VALUE(SUBSTITUTE(INDEX($H$9:$H$2008,$W19),",",""))),"")) | AG19: =IF($W19="","",IFERROR(IF(ISNUMBER(INDEX($I$9:$I$2008,$W19)),INDEX($I$9:$I$2008,$W19),VALUE(SUBSTITUTE(INDEX($I$9:$I$2008,$W19),",",""))),"")) | AH19: =IF($W19="","",IFERROR(IF(ISNUMBER(INDEX($J$9:$J$2008,$W19)),INDEX($J$9:$J$2008,$W19),VALUE(SUBSTITUTE(INDEX($J$9:$J$2008,$W19),",",""))),"")) | AI19: =IF($W19="","",IFERROR(IF(ISNUMBER(INDEX($K$9:$K$2008,$W19)),INDEX($K$9:$K$2008,$W19),VALUE(SUBSTITUTE(INDEX($K$9:$K$2008,$W19),",",""))),"")) | AJ19: =IF($W19="","",IFERROR(IF(ISNUMBER(INDEX($L$9:$L$2008,$W19)),INDEX($L$9:$L$2008,$W19),VALUE(SUBSTITUTE(INDEX($L$9:$L$2008,$W19),",",""))),"")) | AK19: =IF($W19="","",IFERROR(IF(ISNUMBER(INDEX($M$9:$M$2008,$W19)),INDEX($M$9:$M$2008,$W19),VALUE(SUBSTITUTE(INDEX($M$9:$M$2008,$W19),",",""))),"")) | AL19: =IF($W19="","",IFERROR(IF(ISNUMBER(INDEX($P$9:$P$2008,$W19)),INDEX($P$9:$P$2008,$W19),VALUE(SUBSTITUTE(INDEX($P$9:$P$2008,$W19),"%",""))/100),""))
S20: =IF(AND(ISTEXT($A20),ISNUMBER(SEARCH(" - ",$A20)),ISERROR(SEARCH("Folio",$A20)),$D20=""),TRIM($A20),$S19) | T20: =IF(AND(ISNUMBER(SEARCH("Folio",$A20)),$D20<>""),1,"") | U20: =IF($T20=1,COUNTIF($T$9:$T20,1),"") | V20: =IF(AND(ISTEXT($A20),LEFT($A21,3)="Pan"),1,"") | W20: =IFERROR(MATCH(12,$U$9:$U$2008,0),"") | X20: =IF($W20="","",IF($R$5<>"",$R$5,$R$6)) | Y20: =IF($W20="","",INDEX($S$9:$S$2008,$W20)) | Z20: =IF($W20="","",IFERROR(TRIM(LEFT(SUBSTITUTE(INDEX($A$9:$A$2008,$W20),CHAR(10)," "),SEARCH("Folio",SUBSTITUTE(INDEX($A$9:$A$2008,$W20),CHAR(10)," "))-1)),TRIM(SUBSTITUTE(INDEX($A$9:$A$2008,$W20),CHAR(10)," ")))) | AA20: =IF($W20="","",IFERROR(TRIM(SUBSTITUTE(MID(SUBSTITUTE(INDEX($A$9:$A$2008,$W20),CHAR(10)," "),SEARCH("Folio",SUBSTITUTE(INDEX($A$9:$A$2008,$W20),CHAR(10)," "))+5,200),":","")),"")) | AB20: =IF($W20="","",IF(ISNUMBER(INDEX($D$9:$D$2008,$W20)),INDEX($D$9:$D$2008,$W20),IFERROR(DATE(2000+VALUE(RIGHT(INDEX($D$9:$D$2008,$W20),2)),VALUE(MID(INDEX($D$9:$D$2008,$W20),4,2)),VALUE(LEFT(INDEX($D$9:$D$2008,$W20),2))),""))) | AC20: =IF($W20="","",IFERROR(IF(ISNUMBER(INDEX($E$9:$E$2008,$W20)),INDEX($E$9:$E$2008,$W20),VALUE(SUBSTITUTE(INDEX($E$9:$E$2008,$W20),",",""))),"")) | AD20: =IF($W20="","",IFERROR(IF(ISNUMBER(INDEX($F$9:$F$2008,$W20)),INDEX($F$9:$F$2008,$W20),VALUE(SUBSTITUTE(INDEX($F$9:$F$2008,$W20),",",""))),"")) | AE20: =IF($W20="","",IFERROR(IF(ISNUMBER(INDEX($G$9:$G$2008,$W20)),INDEX($G$9:$G$2008,$W20),VALUE(SUBSTITUTE(INDEX($G$9:$G$2008,$W20),",",""))),"")) | AF20: =IF($W20="","",IFERROR(IF(ISNUMBER(INDEX($H$9:$H$2008,$W20)),INDEX($H$9:$H$2008,$W20),VALUE(SUBSTITUTE(INDEX($H$9:$H$2008,$W20),",",""))),"")) | AG20: =IF($W20="","",IFERROR(IF(ISNUMBER(INDEX($I$9:$I$2008,$W20)),INDEX($I$9:$I$2008,$W20),VALUE(SUBSTITUTE(INDEX($I$9:$I$2008,$W20),",",""))),"")) | AH20: =IF($W20="","",IFERROR(IF(ISNUMBER(INDEX($J$9:$J$2008,$W20)),INDEX($J$9:$J$2008,$W20),VALUE(SUBSTITUTE(INDEX($J$9:$J$2008,$W20),",",""))),"")) | AI20: =IF($W20="","",IFERROR(IF(ISNUMBER(INDEX($K$9:$K$2008,$W20)),INDEX($K$9:$K$2008,$W20),VALUE(SUBSTITUTE(INDEX($K$9:$K$2008,$W20),",",""))),"")) | AJ20: =IF($W20="","",IFERROR(IF(ISNUMBER(INDEX($L$9:$L$2008,$W20)),INDEX($L$9:$L$2008,$W20),VALUE(SUBSTITUTE(INDEX($L$9:$L$2008,$W20),",",""))),"")) | AK20: =IF($W20="","",IFERROR(IF(ISNUMBER(INDEX($M$9:$M$2008,$W20)),INDEX($M$9:$M$2008,$W20),VALUE(SUBSTITUTE(INDEX($M$9:$M$2008,$W20),",",""))),"")) | AL20: =IF($W20="","",IFERROR(IF(ISNUMBER(INDEX($P$9:$P$2008,$W20)),INDEX($P$9:$P$2008,$W20),VALUE(SUBSTITUTE(INDEX($P$9:$P$2008,$W20),"%",""))/100),""))
S21: =IF(AND(ISTEXT($A21),ISNUMBER(SEARCH(" - ",$A21)),ISERROR(SEARCH("Folio",$A21)),$D21=""),TRIM($A21),$S20) | T21: =IF(AND(ISNUMBER(SEARCH("Folio",$A21)),$D21<>""),1,"") | U21: =IF($T21=1,COUNTIF($T$9:$T21,1),"") | V21: =IF(AND(ISTEXT($A21),LEFT($A22,3)="Pan"),1,"") | W21: =IFERROR(MATCH(13,$U$9:$U$2008,0),"") | X21: =IF($W21="","",IF($R$5<>"",$R$5,$R$6)) | Y21: =IF($W21="","",INDEX($S$9:$S$2008,$W21)) | Z21: =IF($W21="","",IFERROR(TRIM(LEFT(SUBSTITUTE(INDEX($A$9:$A$2008,$W21),CHAR(10)," "),SEARCH("Folio",SUBSTITUTE(INDEX($A$9:$A$2008,$W21),CHAR(10)," "))-1)),TRIM(SUBSTITUTE(INDEX($A$9:$A$2008,$W21),CHAR(10)," ")))) | AA21: =IF($W21="","",IFERROR(TRIM(SUBSTITUTE(MID(SUBSTITUTE(INDEX($A$9:$A$2008,$W21),CHAR(10)," "),SEARCH("Folio",SUBSTITUTE(INDEX($A$9:$A$2008,$W21),CHAR(10)," "))+5,200),":","")),"")) | AB21: =IF($W21="","",IF(ISNUMBER(INDEX($D$9:$D$2008,$W21)),INDEX($D$9:$D$2008,$W21),IFERROR(DATE(2000+VALUE(RIGHT(INDEX($D$9:$D$2008,$W21),2)),VALUE(MID(INDEX($D$9:$D$2008,$W21),4,2)),VALUE(LEFT(INDEX($D$9:$D$2008,$W21),2))),""))) | AC21: =IF($W21="","",IFERROR(IF(ISNUMBER(INDEX($E$9:$E$2008,$W21)),INDEX($E$9:$E$2008,$W21),VALUE(SUBSTITUTE(INDEX($E$9:$E$2008,$W21),",",""))),"")) | AD21: =IF($W21="","",IFERROR(IF(ISNUMBER(INDEX($F$9:$F$2008,$W21)),INDEX($F$9:$F$2008,$W21),VALUE(SUBSTITUTE(INDEX($F$9:$F$2008,$W21),",",""))),"")) | AE21: =IF($W21="","",IFERROR(IF(ISNUMBER(INDEX($G$9:$G$2008,$W21)),INDEX($G$9:$G$2008,$W21),VALUE(SUBSTITUTE(INDEX($G$9:$G$2008,$W21),",",""))),"")) | AF21: =IF($W21="","",IFERROR(IF(ISNUMBER(INDEX($H$9:$H$2008,$W21)),INDEX($H$9:$H$2008,$W21),VALUE(SUBSTITUTE(INDEX($H$9:$H$2008,$W21),",",""))),"")) | AG21: =IF($W21="","",IFERROR(IF(ISNUMBER(INDEX($I$9:$I$2008,$W21)),INDEX($I$9:$I$2008,$W21),VALUE(SUBSTITUTE(INDEX($I$9:$I$2008,$W21),",",""))),"")) | AH21: =IF($W21="","",IFERROR(IF(ISNUMBER(INDEX($J$9:$J$2008,$W21)),INDEX($J$9:$J$2008,$W21),VALUE(SUBSTITUTE(INDEX($J$9:$J$2008,$W21),",",""))),"")) | AI21: =IF($W21="","",IFERROR(IF(ISNUMBER(INDEX($K$9:$K$2008,$W21)),INDEX($K$9:$K$2008,$W21),VALUE(SUBSTITUTE(INDEX($K$9:$K$2008,$W21),",",""))),"")) | AJ21: =IF($W21="","",IFERROR(IF(ISNUMBER(INDEX($L$9:$L$2008,$W21)),INDEX($L$9:$L$2008,$W21),VALUE(SUBSTITUTE(INDEX($L$9:$L$2008,$W21),",",""))),"")) | AK21: =IF($W21="","",IFERROR(IF(ISNUMBER(INDEX($M$9:$M$2008,$W21)),INDEX($M$9:$M$2008,$W21),VALUE(SUBSTITUTE(INDEX($M$9:$M$2008,$W21),",",""))),"")) | AL21: =IF($W21="","",IFERROR(IF(ISNUMBER(INDEX($P$9:$P$2008,$W21)),INDEX($P$9:$P$2008,$W21),VALUE(SUBSTITUTE(INDEX($P$9:$P$2008,$W21),"%",""))/100),""))
S22: =IF(AND(ISTEXT($A22),ISNUMBER(SEARCH(" - ",$A22)),ISERROR(SEARCH("Folio",$A22)),$D22=""),TRIM($A22),$S21) | T22: =IF(AND(ISNUMBER(SEARCH("Folio",$A22)),$D22<>""),1,"") | U22: =IF($T22=1,COUNTIF($T$9:$T22,1),"") | V22: =IF(AND(ISTEXT($A22),LEFT($A23,3)="Pan"),1,"") | W22: =IFERROR(MATCH(14,$U$9:$U$2008,0),"") | X22: =IF($W22="","",IF($R$5<>"",$R$5,$R$6)) | Y22: =IF($W22="","",INDEX($S$9:$S$2008,$W22)) | Z22: =IF($W22="","",IFERROR(TRIM(LEFT(SUBSTITUTE(INDEX($A$9:$A$2008,$W22),CHAR(10)," "),SEARCH("Folio",SUBSTITUTE(INDEX($A$9:$A$2008,$W22),CHAR(10)," "))-1)),TRIM(SUBSTITUTE(INDEX($A$9:$A$2008,$W22),CHAR(10)," ")))) | AA22: =IF($W22="","",IFERROR(TRIM(SUBSTITUTE(MID(SUBSTITUTE(INDEX($A$9:$A$2008,$W22),CHAR(10)," "),SEARCH("Folio",SUBSTITUTE(INDEX($A$9:$A$2008,$W22),CHAR(10)," "))+5,200),":","")),"")) | AB22: =IF($W22="","",IF(ISNUMBER(INDEX($D$9:$D$2008,$W22)),INDEX($D$9:$D$2008,$W22),IFERROR(DATE(2000+VALUE(RIGHT(INDEX($D$9:$D$2008,$W22),2)),VALUE(MID(INDEX($D$9:$D$2008,$W22),4,2)),VALUE(LEFT(INDEX($D$9:$D$2008,$W22),2))),""))) | AC22: =IF($W22="","",IFERROR(IF(ISNUMBER(INDEX($E$9:$E$2008,$W22)),INDEX($E$9:$E$2008,$W22),VALUE(SUBSTITUTE(INDEX($E$9:$E$2008,$W22),",",""))),"")) | AD22: =IF($W22="","",IFERROR(IF(ISNUMBER(INDEX($F$9:$F$2008,$W22)),INDEX($F$9:$F$2008,$W22),VALUE(SUBSTITUTE(INDEX($F$9:$F$2008,$W22),",",""))),"")) | AE22: =IF($W22="","",IFERROR(IF(ISNUMBER(INDEX($G$9:$G$2008,$W22)),INDEX($G$9:$G$2008,$W22),VALUE(SUBSTITUTE(INDEX($G$9:$G$2008,$W22),",",""))),"")) | AF22: =IF($W22="","",IFERROR(IF(ISNUMBER(INDEX($H$9:$H$2008,$W22)),INDEX($H$9:$H$2008,$W22),VALUE(SUBSTITUTE(INDEX($H$9:$H$2008,$W22),",",""))),"")) | AG22: =IF($W22="","",IFERROR(IF(ISNUMBER(INDEX($I$9:$I$2008,$W22)),INDEX($I$9:$I$2008,$W22),VALUE(SUBSTITUTE(INDEX($I$9:$I$2008,$W22),",",""))),"")) | AH22: =IF($W22="","",IFERROR(IF(ISNUMBER(INDEX($J$9:$J$2008,$W22)),INDEX($J$9:$J$2008,$W22),VALUE(SUBSTITUTE(INDEX($J$9:$J$2008,$W22),",",""))),"")) | AI22: =IF($W22="","",IFERROR(IF(ISNUMBER(INDEX($K$9:$K$2008,$W22)),INDEX($K$9:$K$2008,$W22),VALUE(SUBSTITUTE(INDEX($K$9:$K$2008,$W22),",",""))),"")) | AJ22: =IF($W22="","",IFERROR(IF(ISNUMBER(INDEX($L$9:$L$2008,$W22)),INDEX($L$9:$L$2008,$W22),VALUE(SUBSTITUTE(INDEX($L$9:$L$2008,$W22),",",""))),"")) | AK22: =IF($W22="","",IFERROR(IF(ISNUMBER(INDEX($M$9:$M$2008,$W22)),INDEX($M$9:$M$2008,$W22),VALUE(SUBSTITUTE(INDEX($M$9:$M$2008,$W22),",",""))),"")) | AL22: =IF($W22="","",IFERROR(IF(ISNUMBER(INDEX($P$9:$P$2008,$W22)),INDEX($P$9:$P$2008,$W22),VALUE(SUBSTITUTE(INDEX($P$9:$P$2008,$W22),"%",""))/100),""))
S23: =IF(AND(ISTEXT($A23),ISNUMBER(SEARCH(" - ",$A23)),ISERROR(SEARCH("Folio",$A23)),$D23=""),TRIM($A23),$S22) | T23: =IF(AND(ISNUMBER(SEARCH("Folio",$A23)),$D23<>""),1,"") | U23: =IF($T23=1,COUNTIF($T$9:$T23,1),"") | V23: =IF(AND(ISTEXT($A23),LEFT($A24,3)="Pan"),1,"") | W23: =IFERROR(MATCH(15,$U$9:$U$2008,0),"") | X23: =IF($W23="","",IF($R$5<>"",$R$5,$R$6)) | Y23: =IF($W23="","",INDEX($S$9:$S$2008,$W23)) | Z23: =IF($W23="","",IFERROR(TRIM(LEFT(SUBSTITUTE(INDEX($A$9:$A$2008,$W23),CHAR(10)," "),SEARCH("Folio",SUBSTITUTE(INDEX($A$9:$A$2008,$W23),CHAR(10)," "))-1)),TRIM(SUBSTITUTE(INDEX($A$9:$A$2008,$W23),CHAR(10)," ")))) | AA23: =IF($W23="","",IFERROR(TRIM(SUBSTITUTE(MID(SUBSTITUTE(INDEX($A$9:$A$2008,$W23),CHAR(10)," "),SEARCH("Folio",SUBSTITUTE(INDEX($A$9:$A$2008,$W23),CHAR(10)," "))+5,200),":","")),"")) | AB23: =IF($W23="","",IF(ISNUMBER(INDEX($D$9:$D$2008,$W23)),INDEX($D$9:$D$2008,$W23),IFERROR(DATE(2000+VALUE(RIGHT(INDEX($D$9:$D$2008,$W23),2)),VALUE(MID(INDEX($D$9:$D$2008,$W23),4,2)),VALUE(LEFT(INDEX($D$9:$D$2008,$W23),2))),""))) | AC23: =IF($W23="","",IFERROR(IF(ISNUMBER(INDEX($E$9:$E$2008,$W23)),INDEX($E$9:$E$2008,$W23),VALUE(SUBSTITUTE(INDEX($E$9:$E$2008,$W23),",",""))),"")) | AD23: =IF($W23="","",IFERROR(IF(ISNUMBER(INDEX($F$9:$F$2008,$W23)),INDEX($F$9:$F$2008,$W23),VALUE(SUBSTITUTE(INDEX($F$9:$F$2008,$W23),",",""))),"")) | AE23: =IF($W23="","",IFERROR(IF(ISNUMBER(INDEX($G$9:$G$2008,$W23)),INDEX($G$9:$G$2008,$W23),VALUE(SUBSTITUTE(INDEX($G$9:$G$2008,$W23),",",""))),"")) | AF23: =IF($W23="","",IFERROR(IF(ISNUMBER(INDEX($H$9:$H$2008,$W23)),INDEX($H$9:$H$2008,$W23),VALUE(SUBSTITUTE(INDEX($H$9:$H$2008,$W23),",",""))),"")) | AG23: =IF($W23="","",IFERROR(IF(ISNUMBER(INDEX($I$9:$I$2008,$W23)),INDEX($I$9:$I$2008,$W23),VALUE(SUBSTITUTE(INDEX($I$9:$I$2008,$W23),",",""))),"")) | AH23: =IF($W23="","",IFERROR(IF(ISNUMBER(INDEX($J$9:$J$2008,$W23)),INDEX($J$9:$J$2008,$W23),VALUE(SUBSTITUTE(INDEX($J$9:$J$2008,$W23),",",""))),"")) | AI23: =IF($W23="","",IFERROR(IF(ISNUMBER(INDEX($K$9:$K$2008,$W23)),INDEX($K$9:$K$2008,$W23),VALUE(SUBSTITUTE(INDEX($K$9:$K$2008,$W23),",",""))),"")) | AJ23: =IF($W23="","",IFERROR(IF(ISNUMBER(INDEX($L$9:$L$2008,$W23)),INDEX($L$9:$L$2008,$W23),VALUE(SUBSTITUTE(INDEX($L$9:$L$2008,$W23),",",""))),"")) | AK23: =IF($W23="","",IFERROR(IF(ISNUMBER(INDEX($M$9:$M$2008,$W23)),INDEX($M$9:$M$2008,$W23),VALUE(SUBSTITUTE(INDEX($M$9:$M$2008,$W23),",",""))),"")) | AL23: =IF($W23="","",IFERROR(IF(ISNUMBER(INDEX($P$9:$P$2008,$W23)),INDEX($P$9:$P$2008,$W23),VALUE(SUBSTITUTE(INDEX($P$9:$P$2008,$W23),"%",""))/100),""))
S24: =IF(AND(ISTEXT($A24),ISNUMBER(SEARCH(" - ",$A24)),ISERROR(SEARCH("Folio",$A24)),$D24=""),TRIM($A24),$S23) | T24: =IF(AND(ISNUMBER(SEARCH("Folio",$A24)),$D24<>""),1,"") | U24: =IF($T24=1,COUNTIF($T$9:$T24,1),"") | V24: =IF(AND(ISTEXT($A24),LEFT($A25,3)="Pan"),1,"") | W24: =IFERROR(MATCH(16,$U$9:$U$2008,0),"") | X24: =IF($W24="","",IF($R$5<>"",$R$5,$R$6)) | Y24: =IF($W24="","",INDEX($S$9:$S$2008,$W24)) | Z24: =IF($W24="","",IFERROR(TRIM(LEFT(SUBSTITUTE(INDEX($A$9:$A$2008,$W24),CHAR(10)," "),SEARCH("Folio",SUBSTITUTE(INDEX($A$9:$A$2008,$W24),CHAR(10)," "))-1)),TRIM(SUBSTITUTE(INDEX($A$9:$A$2008,$W24),CHAR(10)," ")))) | AA24: =IF($W24="","",IFERROR(TRIM(SUBSTITUTE(MID(SUBSTITUTE(INDEX($A$9:$A$2008,$W24),CHAR(10)," "),SEARCH("Folio",SUBSTITUTE(INDEX($A$9:$A$2008,$W24),CHAR(10)," "))+5,200),":","")),"")) | AB24: =IF($W24="","",IF(ISNUMBER(INDEX($D$9:$D$2008,$W24)),INDEX($D$9:$D$2008,$W24),IFERROR(DATE(2000+VALUE(RIGHT(INDEX($D$9:$D$2008,$W24),2)),VALUE(MID(INDEX($D$9:$D$2008,$W24),4,2)),VALUE(LEFT(INDEX($D$9:$D$2008,$W24),2))),""))) | AC24: =IF($W24="","",IFERROR(IF(ISNUMBER(INDEX($E$9:$E$2008,$W24)),INDEX($E$9:$E$2008,$W24),VALUE(SUBSTITUTE(INDEX($E$9:$E$2008,$W24),",",""))),"")) | AD24: =IF($W24="","",IFERROR(IF(ISNUMBER(INDEX($F$9:$F$2008,$W24)),INDEX($F$9:$F$2008,$W24),VALUE(SUBSTITUTE(INDEX($F$9:$F$2008,$W24),",",""))),"")) | AE24: =IF($W24="","",IFERROR(IF(ISNUMBER(INDEX($G$9:$G$2008,$W24)),INDEX($G$9:$G$2008,$W24),VALUE(SUBSTITUTE(INDEX($G$9:$G$2008,$W24),",",""))),"")) | AF24: =IF($W24="","",IFERROR(IF(ISNUMBER(INDEX($H$9:$H$2008,$W24)),INDEX($H$9:$H$2008,$W24),VALUE(SUBSTITUTE(INDEX($H$9:$H$2008,$W24),",",""))),"")) | AG24: =IF($W24="","",IFERROR(IF(ISNUMBER(INDEX($I$9:$I$2008,$W24)),INDEX($I$9:$I$2008,$W24),VALUE(SUBSTITUTE(INDEX($I$9:$I$2008,$W24),",",""))),"")) | AH24: =IF($W24="","",IFERROR(IF(ISNUMBER(INDEX($J$9:$J$2008,$W24)),INDEX($J$9:$J$2008,$W24),VALUE(SUBSTITUTE(INDEX($J$9:$J$2008,$W24),",",""))),"")) | AI24: =IF($W24="","",IFERROR(IF(ISNUMBER(INDEX($K$9:$K$2008,$W24)),INDEX($K$9:$K$2008,$W24),VALUE(SUBSTITUTE(INDEX($K$9:$K$2008,$W24),",",""))),"")) | AJ24: =IF($W24="","",IFERROR(IF(ISNUMBER(INDEX($L$9:$L$2008,$W24)),INDEX($L$9:$L$2008,$W24),VALUE(SUBSTITUTE(INDEX($L$9:$L$2008,$W24),",",""))),"")) | AK24: =IF($W24="","",IFERROR(IF(ISNUMBER(INDEX($M$9:$M$2008,$W24)),INDEX($M$9:$M$2008,$W24),VALUE(SUBSTITUTE(INDEX($M$9:$M$2008,$W24),",",""))),"")) | AL24: =IF($W24="","",IFERROR(IF(ISNUMBER(INDEX($P$9:$P$2008,$W24)),INDEX($P$9:$P$2008,$W24),VALUE(SUBSTITUTE(INDEX($P$9:$P$2008,$W24),"%",""))/100),""))
S25: =IF(AND(ISTEXT($A25),ISNUMBER(SEARCH(" - ",$A25)),ISERROR(SEARCH("Folio",$A25)),$D25=""),TRIM($A25),$S24) | T25: =IF(AND(ISNUMBER(SEARCH("Folio",$A25)),$D25<>""),1,"") | U25: =IF($T25=1,COUNTIF($T$9:$T25,1),"") | V25: =IF(AND(ISTEXT($A25),LEFT($A26,3)="Pan"),1,"") | W25: =IFERROR(MATCH(17,$U$9:$U$2008,0),"") | X25: =IF($W25="","",IF($R$5<>"",$R$5,$R$6)) | Y25: =IF($W25="","",INDEX($S$9:$S$2008,$W25)) | Z25: =IF($W25="","",IFERROR(TRIM(LEFT(SUBSTITUTE(INDEX($A$9:$A$2008,$W25),CHAR(10)," "),SEARCH("Folio",SUBSTITUTE(INDEX($A$9:$A$2008,$W25),CHAR(10)," "))-1)),TRIM(SUBSTITUTE(INDEX($A$9:$A$2008,$W25),CHAR(10)," ")))) | AA25: =IF($W25="","",IFERROR(TRIM(SUBSTITUTE(MID(SUBSTITUTE(INDEX($A$9:$A$2008,$W25),CHAR(10)," "),SEARCH("Folio",SUBSTITUTE(INDEX($A$9:$A$2008,$W25),CHAR(10)," "))+5,200),":","")),"")) | AB25: =IF($W25="","",IF(ISNUMBER(INDEX($D$9:$D$2008,$W25)),INDEX($D$9:$D$2008,$W25),IFERROR(DATE(2000+VALUE(RIGHT(INDEX($D$9:$D$2008,$W25),2)),VALUE(MID(INDEX($D$9:$D$2008,$W25),4,2)),VALUE(LEFT(INDEX($D$9:$D$2008,$W25),2))),""))) | AC25: =IF($W25="","",IFERROR(IF(ISNUMBER(INDEX($E$9:$E$2008,$W25)),INDEX($E$9:$E$2008,$W25),VALUE(SUBSTITUTE(INDEX($E$9:$E$2008,$W25),",",""))),"")) | AD25: =IF($W25="","",IFERROR(IF(ISNUMBER(INDEX($F$9:$F$2008,$W25)),INDEX($F$9:$F$2008,$W25),VALUE(SUBSTITUTE(INDEX($F$9:$F$2008,$W25),",",""))),"")) | AE25: =IF($W25="","",IFERROR(IF(ISNUMBER(INDEX($G$9:$G$2008,$W25)),INDEX($G$9:$G$2008,$W25),VALUE(SUBSTITUTE(INDEX($G$9:$G$2008,$W25),",",""))),"")) | AF25: =IF($W25="","",IFERROR(IF(ISNUMBER(INDEX($H$9:$H$2008,$W25)),INDEX($H$9:$H$2008,$W25),VALUE(SUBSTITUTE(INDEX($H$9:$H$2008,$W25),",",""))),"")) | AG25: =IF($W25="","",IFERROR(IF(ISNUMBER(INDEX($I$9:$I$2008,$W25)),INDEX($I$9:$I$2008,$W25),VALUE(SUBSTITUTE(INDEX($I$9:$I$2008,$W25),",",""))),"")) | AH25: =IF($W25="","",IFERROR(IF(ISNUMBER(INDEX($J$9:$J$2008,$W25)),INDEX($J$9:$J$2008,$W25),VALUE(SUBSTITUTE(INDEX($J$9:$J$2008,$W25),",",""))),"")) | AI25: =IF($W25="","",IFERROR(IF(ISNUMBER(INDEX($K$9:$K$2008,$W25)),INDEX($K$9:$K$2008,$W25),VALUE(SUBSTITUTE(INDEX($K$9:$K$2008,$W25),",",""))),"")) | AJ25: =IF($W25="","",IFERROR(IF(ISNUMBER(INDEX($L$9:$L$2008,$W25)),INDEX($L$9:$L$2008,$W25),VALUE(SUBSTITUTE(INDEX($L$9:$L$2008,$W25),",",""))),"")) | AK25: =IF($W25="","",IFERROR(IF(ISNUMBER(INDEX($M$9:$M$2008,$W25)),INDEX($M$9:$M$2008,$W25),VALUE(SUBSTITUTE(INDEX($M$9:$M$2008,$W25),",",""))),"")) | AL25: =IF($W25="","",IFERROR(IF(ISNUMBER(INDEX($P$9:$P$2008,$W25)),INDEX($P$9:$P$2008,$W25),VALUE(SUBSTITUTE(INDEX($P$9:$P$2008,$W25),"%",""))/100),""))
S26: =IF(AND(ISTEXT($A26),ISNUMBER(SEARCH(" - ",$A26)),ISERROR(SEARCH("Folio",$A26)),$D26=""),TRIM($A26),$S25) | T26: =IF(AND(ISNUMBER(SEARCH("Folio",$A26)),$D26<>""),1,"") | U26: =IF($T26=1,COUNTIF($T$9:$T26,1),"") | V26: =IF(AND(ISTEXT($A26),LEFT($A27,3)="Pan"),1,"") | W26: =IFERROR(MATCH(18,$U$9:$U$2008,0),"") | X26: =IF($W26="","",IF($R$5<>"",$R$5,$R$6)) | Y26: =IF($W26="","",INDEX($S$9:$S$2008,$W26)) | Z26: =IF($W26="","",IFERROR(TRIM(LEFT(SUBSTITUTE(INDEX($A$9:$A$2008,$W26),CHAR(10)," "),SEARCH("Folio",SUBSTITUTE(INDEX($A$9:$A$2008,$W26),CHAR(10)," "))-1)),TRIM(SUBSTITUTE(INDEX($A$9:$A$2008,$W26),CHAR(10)," ")))) | AA26: =IF($W26="","",IFERROR(TRIM(SUBSTITUTE(MID(SUBSTITUTE(INDEX($A$9:$A$2008,$W26),CHAR(10)," "),SEARCH("Folio",SUBSTITUTE(INDEX($A$9:$A$2008,$W26),CHAR(10)," "))+5,200),":","")),"")) | AB26: =IF($W26="","",IF(ISNUMBER(INDEX($D$9:$D$2008,$W26)),INDEX($D$9:$D$2008,$W26),IFERROR(DATE(2000+VALUE(RIGHT(INDEX($D$9:$D$2008,$W26),2)),VALUE(MID(INDEX($D$9:$D$2008,$W26),4,2)),VALUE(LEFT(INDEX($D$9:$D$2008,$W26),2))),""))) | AC26: =IF($W26="","",IFERROR(IF(ISNUMBER(INDEX($E$9:$E$2008,$W26)),INDEX($E$9:$E$2008,$W26),VALUE(SUBSTITUTE(INDEX($E$9:$E$2008,$W26),",",""))),"")) | AD26: =IF($W26="","",IFERROR(IF(ISNUMBER(INDEX($F$9:$F$2008,$W26)),INDEX($F$9:$F$2008,$W26),VALUE(SUBSTITUTE(INDEX($F$9:$F$2008,$W26),",",""))),"")) | AE26: =IF($W26="","",IFERROR(IF(ISNUMBER(INDEX($G$9:$G$2008,$W26)),INDEX($G$9:$G$2008,$W26),VALUE(SUBSTITUTE(INDEX($G$9:$G$2008,$W26),",",""))),"")) | AF26: =IF($W26="","",IFERROR(IF(ISNUMBER(INDEX($H$9:$H$2008,$W26)),INDEX($H$9:$H$2008,$W26),VALUE(SUBSTITUTE(INDEX($H$9:$H$2008,$W26),",",""))),"")) | AG26: =IF($W26="","",IFERROR(IF(ISNUMBER(INDEX($I$9:$I$2008,$W26)),INDEX($I$9:$I$2008,$W26),VALUE(SUBSTITUTE(INDEX($I$9:$I$2008,$W26),",",""))),"")) | AH26: =IF($W26="","",IFERROR(IF(ISNUMBER(INDEX($J$9:$J$2008,$W26)),INDEX($J$9:$J$2008,$W26),VALUE(SUBSTITUTE(INDEX($J$9:$J$2008,$W26),",",""))),"")) | AI26: =IF($W26="","",IFERROR(IF(ISNUMBER(INDEX($K$9:$K$2008,$W26)),INDEX($K$9:$K$2008,$W26),VALUE(SUBSTITUTE(INDEX($K$9:$K$2008,$W26),",",""))),"")) | AJ26: =IF($W26="","",IFERROR(IF(ISNUMBER(INDEX($L$9:$L$2008,$W26)),INDEX($L$9:$L$2008,$W26),VALUE(SUBSTITUTE(INDEX($L$9:$L$2008,$W26),",",""))),"")) | AK26: =IF($W26="","",IFERROR(IF(ISNUMBER(INDEX($M$9:$M$2008,$W26)),INDEX($M$9:$M$2008,$W26),VALUE(SUBSTITUTE(INDEX($M$9:$M$2008,$W26),",",""))),"")) | AL26: =IF($W26="","",IFERROR(IF(ISNUMBER(INDEX($P$9:$P$2008,$W26)),INDEX($P$9:$P$2008,$W26),VALUE(SUBSTITUTE(INDEX($P$9:$P$2008,$W26),"%",""))/100),""))
S27: =IF(AND(ISTEXT($A27),ISNUMBER(SEARCH(" - ",$A27)),ISERROR(SEARCH("Folio",$A27)),$D27=""),TRIM($A27),$S26) | T27: =IF(AND(ISNUMBER(SEARCH("Folio",$A27)),$D27<>""),1,"") | U27: =IF($T27=1,COUNTIF($T$9:$T27,1),"") | V27: =IF(AND(ISTEXT($A27),LEFT($A28,3)="Pan"),1,"") | W27: =IFERROR(MATCH(19,$U$9:$U$2008,0),"") | X27: =IF($W27="","",IF($R$5<>"",$R$5,$R$6)) | Y27: =IF($W27="","",INDEX($S$9:$S$2008,$W27)) | Z27: =IF($W27="","",IFERROR(TRIM(LEFT(SUBSTITUTE(INDEX($A$9:$A$2008,$W27),CHAR(10)," "),SEARCH("Folio",SUBSTITUTE(INDEX($A$9:$A$2008,$W27),CHAR(10)," "))-1)),TRIM(SUBSTITUTE(INDEX($A$9:$A$2008,$W27),CHAR(10)," ")))) | AA27: =IF($W27="","",IFERROR(TRIM(SUBSTITUTE(MID(SUBSTITUTE(INDEX($A$9:$A$2008,$W27),CHAR(10)," "),SEARCH("Folio",SUBSTITUTE(INDEX($A$9:$A$2008,$W27),CHAR(10)," "))+5,200),":","")),"")) | AB27: =IF($W27="","",IF(ISNUMBER(INDEX($D$9:$D$2008,$W27)),INDEX($D$9:$D$2008,$W27),IFERROR(DATE(2000+VALUE(RIGHT(INDEX($D$9:$D$2008,$W27),2)),VALUE(MID(INDEX($D$9:$D$2008,$W27),4,2)),VALUE(LEFT(INDEX($D$9:$D$2008,$W27),2))),""))) | AC27: =IF($W27="","",IFERROR(IF(ISNUMBER(INDEX($E$9:$E$2008,$W27)),INDEX($E$9:$E$2008,$W27),VALUE(SUBSTITUTE(INDEX($E$9:$E$2008,$W27),",",""))),"")) | AD27: =IF($W27="","",IFERROR(IF(ISNUMBER(INDEX($F$9:$F$2008,$W27)),INDEX($F$9:$F$2008,$W27),VALUE(SUBSTITUTE(INDEX($F$9:$F$2008,$W27),",",""))),"")) | AE27: =IF($W27="","",IFERROR(IF(ISNUMBER(INDEX($G$9:$G$2008,$W27)),INDEX($G$9:$G$2008,$W27),VALUE(SUBSTITUTE(INDEX($G$9:$G$2008,$W27),",",""))),"")) | AF27: =IF($W27="","",IFERROR(IF(ISNUMBER(INDEX($H$9:$H$2008,$W27)),INDEX($H$9:$H$2008,$W27),VALUE(SUBSTITUTE(INDEX($H$9:$H$2008,$W27),",",""))),"")) | AG27: =IF($W27="","",IFERROR(IF(ISNUMBER(INDEX($I$9:$I$2008,$W27)),INDEX($I$9:$I$2008,$W27),VALUE(SUBSTITUTE(INDEX($I$9:$I$2008,$W27),",",""))),"")) | AH27: =IF($W27="","",IFERROR(IF(ISNUMBER(INDEX($J$9:$J$2008,$W27)),INDEX($J$9:$J$2008,$W27),VALUE(SUBSTITUTE(INDEX($J$9:$J$2008,$W27),",",""))),"")) | AI27: =IF($W27="","",IFERROR(IF(ISNUMBER(INDEX($K$9:$K$2008,$W27)),INDEX($K$9:$K$2008,$W27),VALUE(SUBSTITUTE(INDEX($K$9:$K$2008,$W27),",",""))),"")) | AJ27: =IF($W27="","",IFERROR(IF(ISNUMBER(INDEX($L$9:$L$2008,$W27)),INDEX($L$9:$L$2008,$W27),VALUE(SUBSTITUTE(INDEX($L$9:$L$2008,$W27),",",""))),"")) | AK27: =IF($W27="","",IFERROR(IF(ISNUMBER(INDEX($M$9:$M$2008,$W27)),INDEX($M$9:$M$2008,$W27),VALUE(SUBSTITUTE(INDEX($M$9:$M$2008,$W27),",",""))),"")) | AL27: =IF($W27="","",IFERROR(IF(ISNUMBER(INDEX($P$9:$P$2008,$W27)),INDEX($P$9:$P$2008,$W27),VALUE(SUBSTITUTE(INDEX($P$9:$P$2008,$W27),"%",""))/100),""))
S28: =IF(AND(ISTEXT($A28),ISNUMBER(SEARCH(" - ",$A28)),ISERROR(SEARCH("Folio",$A28)),$D28=""),TRIM($A28),$S27) | T28: =IF(AND(ISNUMBER(SEARCH("Folio",$A28)),$D28<>""),1,"") | U28: =IF($T28=1,COUNTIF($T$9:$T28,1),"") | V28: =IF(AND(ISTEXT($A28),LEFT($A29,3)="Pan"),1,"") | W28: =IFERROR(MATCH(20,$U$9:$U$2008,0),"") | X28: =IF($W28="","",IF($R$5<>"",$R$5,$R$6)) | Y28: =IF($W28="","",INDEX($S$9:$S$2008,$W28)) | Z28: =IF($W28="","",IFERROR(TRIM(LEFT(SUBSTITUTE(INDEX($A$9:$A$2008,$W28),CHAR(10)," "),SEARCH("Folio",SUBSTITUTE(INDEX($A$9:$A$2008,$W28),CHAR(10)," "))-1)),TRIM(SUBSTITUTE(INDEX($A$9:$A$2008,$W28),CHAR(10)," ")))) | AA28: =IF($W28="","",IFERROR(TRIM(SUBSTITUTE(MID(SUBSTITUTE(INDEX($A$9:$A$2008,$W28),CHAR(10)," "),SEARCH("Folio",SUBSTITUTE(INDEX($A$9:$A$2008,$W28),CHAR(10)," "))+5,200),":","")),"")) | AB28: =IF($W28="","",IF(ISNUMBER(INDEX($D$9:$D$2008,$W28)),INDEX($D$9:$D$2008,$W28),IFERROR(DATE(2000+VALUE(RIGHT(INDEX($D$9:$D$2008,$W28),2)),VALUE(MID(INDEX($D$9:$D$2008,$W28),4,2)),VALUE(LEFT(INDEX($D$9:$D$2008,$W28),2))),""))) | AC28: =IF($W28="","",IFERROR(IF(ISNUMBER(INDEX($E$9:$E$2008,$W28)),INDEX($E$9:$E$2008,$W28),VALUE(SUBSTITUTE(INDEX($E$9:$E$2008,$W28),",",""))),"")) | AD28: =IF($W28="","",IFERROR(IF(ISNUMBER(INDEX($F$9:$F$2008,$W28)),INDEX($F$9:$F$2008,$W28),VALUE(SUBSTITUTE(INDEX($F$9:$F$2008,$W28),",",""))),"")) | AE28: =IF($W28="","",IFERROR(IF(ISNUMBER(INDEX($G$9:$G$2008,$W28)),INDEX($G$9:$G$2008,$W28),VALUE(SUBSTITUTE(INDEX($G$9:$G$2008,$W28),",",""))),"")) | AF28: =IF($W28="","",IFERROR(IF(ISNUMBER(INDEX($H$9:$H$2008,$W28)),INDEX($H$9:$H$2008,$W28),VALUE(SUBSTITUTE(INDEX($H$9:$H$2008,$W28),",",""))),"")) | AG28: =IF($W28="","",IFERROR(IF(ISNUMBER(INDEX($I$9:$I$2008,$W28)),INDEX($I$9:$I$2008,$W28),VALUE(SUBSTITUTE(INDEX($I$9:$I$2008,$W28),",",""))),"")) | AH28: =IF($W28="","",IFERROR(IF(ISNUMBER(INDEX($J$9:$J$2008,$W28)),INDEX($J$9:$J$2008,$W28),VALUE(SUBSTITUTE(INDEX($J$9:$J$2008,$W28),",",""))),"")) | AI28: =IF($W28="","",IFERROR(IF(ISNUMBER(INDEX($K$9:$K$2008,$W28)),INDEX($K$9:$K$2008,$W28),VALUE(SUBSTITUTE(INDEX($K$9:$K$2008,$W28),",",""))),"")) | AJ28: =IF($W28="","",IFERROR(IF(ISNUMBER(INDEX($L$9:$L$2008,$W28)),INDEX($L$9:$L$2008,$W28),VALUE(SUBSTITUTE(INDEX($L$9:$L$2008,$W28),",",""))),"")) | AK28: =IF($W28="","",IFERROR(IF(ISNUMBER(INDEX($M$9:$M$2008,$W28)),INDEX($M$9:$M$2008,$W28),VALUE(SUBSTITUTE(INDEX($M$9:$M$2008,$W28),",",""))),"")) | AL28: =IF($W28="","",IFERROR(IF(ISNUMBER(INDEX($P$9:$P$2008,$W28)),INDEX($P$9:$P$2008,$W28),VALUE(SUBSTITUTE(INDEX($P$9:$P$2008,$W28),"%",""))/100),""))
S29: =IF(AND(ISTEXT($A29),ISNUMBER(SEARCH(" - ",$A29)),ISERROR(SEARCH("Folio",$A29)),$D29=""),TRIM($A29),$S28) | T29: =IF(AND(ISNUMBER(SEARCH("Folio",$A29)),$D29<>""),1,"") | U29: =IF($T29=1,COUNTIF($T$9:$T29,1),"") | V29: =IF(AND(ISTEXT($A29),LEFT($A30,3)="Pan"),1,"") | W29: =IFERROR(MATCH(21,$U$9:$U$2008,0),"") | X29: =IF($W29="","",IF($R$5<>"",$R$5,$R$6)) | Y29: =IF($W29="","",INDEX($S$9:$S$2008,$W29)) | Z29: =IF($W29="","",IFERROR(TRIM(LEFT(SUBSTITUTE(INDEX($A$9:$A$2008,$W29),CHAR(10)," "),SEARCH("Folio",SUBSTITUTE(INDEX($A$9:$A$2008,$W29),CHAR(10)," "))-1)),TRIM(SUBSTITUTE(INDEX($A$9:$A$2008,$W29),CHAR(10)," ")))) | AA29: =IF($W29="","",IFERROR(TRIM(SUBSTITUTE(MID(SUBSTITUTE(INDEX($A$9:$A$2008,$W29),CHAR(10)," "),SEARCH("Folio",SUBSTITUTE(INDEX($A$9:$A$2008,$W29),CHAR(10)," "))+5,200),":","")),"")) | AB29: =IF($W29="","",IF(ISNUMBER(INDEX($D$9:$D$2008,$W29)),INDEX($D$9:$D$2008,$W29),IFERROR(DATE(2000+VALUE(RIGHT(INDEX($D$9:$D$2008,$W29),2)),VALUE(MID(INDEX($D$9:$D$2008,$W29),4,2)),VALUE(LEFT(INDEX($D$9:$D$2008,$W29),2))),""))) | AC29: =IF($W29="","",IFERROR(IF(ISNUMBER(INDEX($E$9:$E$2008,$W29)),INDEX($E$9:$E$2008,$W29),VALUE(SUBSTITUTE(INDEX($E$9:$E$2008,$W29),",",""))),"")) | AD29: =IF($W29="","",IFERROR(IF(ISNUMBER(INDEX($F$9:$F$2008,$W29)),INDEX($F$9:$F$2008,$W29),VALUE(SUBSTITUTE(INDEX($F$9:$F$2008,$W29),",",""))),"")) | AE29: =IF($W29="","",IFERROR(IF(ISNUMBER(INDEX($G$9:$G$2008,$W29)),INDEX($G$9:$G$2008,$W29),VALUE(SUBSTITUTE(INDEX($G$9:$G$2008,$W29),",",""))),"")) | AF29: =IF($W29="","",IFERROR(IF(ISNUMBER(INDEX($H$9:$H$2008,$W29)),INDEX($H$9:$H$2008,$W29),VALUE(SUBSTITUTE(INDEX($H$9:$H$2008,$W29),",",""))),"")) | AG29: =IF($W29="","",IFERROR(IF(ISNUMBER(INDEX($I$9:$I$2008,$W29)),INDEX($I$9:$I$2008,$W29),VALUE(SUBSTITUTE(INDEX($I$9:$I$2008,$W29),",",""))),"")) | AH29: =IF($W29="","",IFERROR(IF(ISNUMBER(INDEX($J$9:$J$2008,$W29)),INDEX($J$9:$J$2008,$W29),VALUE(SUBSTITUTE(INDEX($J$9:$J$2008,$W29),",",""))),"")) | AI29: =IF($W29="","",IFERROR(IF(ISNUMBER(INDEX($K$9:$K$2008,$W29)),INDEX($K$9:$K$2008,$W29),VALUE(SUBSTITUTE(INDEX($K$9:$K$2008,$W29),",",""))),"")) | AJ29: =IF($W29="","",IFERROR(IF(ISNUMBER(INDEX($L$9:$L$2008,$W29)),INDEX($L$9:$L$2008,$W29),VALUE(SUBSTITUTE(INDEX($L$9:$L$2008,$W29),",",""))),"")) | AK29: =IF($W29="","",IFERROR(IF(ISNUMBER(INDEX($M$9:$M$2008,$W29)),INDEX($M$9:$M$2008,$W29),VALUE(SUBSTITUTE(INDEX($M$9:$M$2008,$W29),",",""))),"")) | AL29: =IF($W29="","",IFERROR(IF(ISNUMBER(INDEX($P$9:$P$2008,$W29)),INDEX($P$9:$P$2008,$W29),VALUE(SUBSTITUTE(INDEX($P$9:$P$2008,$W29),"%",""))/100),""))
