Workbook

Sheet Instructions
A1: MUTUAL FUND RESEARCH - PERFORMANCE REVIEW
A2: Enter every scheme once on Fund Research. The three verdict tabs and the Summary fill themselves in.
A4: HOW TO USE
A5: 1. Lists | B5: Nothing to do - it holds the Category and Action dropdowns.
A6: 2. Fund Research | B6: The only sheet you type into. One row per scheme per client. Fill the blue columns; black columns calculate.
A7: 3. Best Funds | B7: Read-only. Every scheme whose 3-year return clears the Best threshold, ranked best first.
A8: 4. Need to Improve | B8: Read-only. Schemes in the middle band, worst first - this is your call-list.
A9: 5. Not Performing | B9: Read-only. Schemes below the Improve threshold, worst first. Review these with the client.
A10: 6. Summary | B10: Read-only dashboard: how many schemes and how much money sit in each verdict.
A12: COLOUR LEGEND
A13: Blue text on white | B13: You type here. These are the only cells to fill in.
A14: Black text on grey | B14: Calculated. Do not overwrite - it will break the tabs.
A15: Yellow fill | B15: Key setting. Safe to change - the whole workbook follows it.
A17: RATING RULE | B17: A fund is judged on its 3-year return. Change the two yellow cells to re-cut the bands - every tab re-sorts itself.
A18: Verdict | B18: Rule on 3-Year Return | D18: Threshold
A19: Best Fund | B19: 3-year return is greater than or equal to | D19: 0.13
A20: Need to Improve | B20: 3-year return is greater than or equal to | D20: 0.1
A21: Not Performing | B21: 3-year return is below | D21: =$D$20
A23: Set by | B23: The 13% Best threshold is the client's own brief: a fund returning 13% or more over 3 years is treated as best. The 10% Improve floor separates a fund that is lagging from one that is genuinely under-performing. Neither is a SEBI or AMFI standard - both are house rules, so change them when the view changes.
A25: NOTE ON RETURNS
A26: Enter 1Y / 3Y / 5Y returns as the scheme's published CAGR. The cells are percent-formatted, so typing 13.5 gives 13.50%. Returns are not calculated from the invested and current value in this workbook - a portfolio holding has its own cash-flow dates, and its XIRR is not the scheme's published return. Paste the scheme figure from the factsheet, AMFI or your research terminal, and note the source date in cell D3 of Fund Research.

Sheet Fund Research
A1: FUND RESEARCH REGISTER
A2: One row per scheme per client. Fill the blue columns - A to C, E to H, K to O and T. Everything else calculates.
A3: Returns as on | C3: Source of returns | H3: Schemes entered | I3: =COUNTA($B$6:$B$505) | K3: Rating bands | L3: =Instructions!$D$19 | M3: Best | N3: =Instructions!$D$20 | O3: Improve floor
A4: ▼ BLUE = you type ▼ BLACK on grey = calculated, do not overwrite
A5: Client Name | B5: Scheme Name | C5: Category | D5: Asset Class | E5: Folio No. | F5: Inv. Since | G5: Total Invested | H5: Current Value (Live) | I5: Gain / Loss | J5: Abs. Rtn. | K5: 1Y Return | L5: 3Y Return (CAGR) | M5: 5Y Return | N5: Category Avg 3Y | O5: Benchmark 3Y | P5: vs Category (3Y) | Q5: Status | R5: Verdict | S5: Suggested Action | T5: Remark | U5: _best | V5: _improve | W5: _poor
A6: Sample Client (EXAMPLE) | B6: Bluechip Flexi Cap Fund - Growth | C6: Equity - Flexi Cap Fund | D6: =IF($C6="","",IFERROR(TRIM(LEFT($C6,FIND("-",$C6)-1)),"")) | E6: 1910625/49 | F6: 44348 | G6: 190000 | H6: 265430 | I6: =IF($B6="","",$H6-$G6) | J6: =IF(OR($B6="",$G6=0,$G6=""),"",$I6/$G6) | K6: 0.184 | L6: 0.1512 | M6: 0.1725 | N6: 0.141 | O6: 0.1365 | P6: =IF(OR($L6="",$N6=""),"",$L6-$N6) | Q6: =IF($B6="","",IF(N($H6)>0,"Live","Exited")) | R6: =IF($B6="","",IF($L6="","Data Pending",IF($L6>=Instructions!$D$19,"Best Fund",IF($L6>=Instructions!$D$20,"Need to Improve","Not Performing")))) | S6: =IF($R6="","",IF($R6="Data Pending","Enter the 3Y return",IF($R6="Best Fund","Hold / consider top-up",IF($R6="Need to Improve","Watch 2 quarters, then decide","Review with client - switch or exit")))) | T6: EXAMPLE ROW - delete it before you start. Returns are the scheme's published CAGR, not this holding's XIRR. | U6: =IF($R6<>"Best Fund","",COUNTIFS($R$6:$R$505,"Best Fund",$L$6:$L$505,">"&$L6)+COUNTIFS($R$6:$R6,"Best Fund",$L$6:$L6,$L6)) | V6: =IF($R6<>"Need to Improve","",COUNTIFS($R$6:$R$505,"Need to Improve",$L$6:$L$505,"<"&$L6)+COUNTIFS($R$6:$R6,"Need to Improve",$L$6:$L6,$L6)) | W6: =IF($R6<>"Not Performing","",COUNTIFS($R$6:$R$505,"Not Performing",$L$6:$L$505,"<"&$L6)+COUNTIFS($R$6:$R6,"Not Performing",$L$6:$L6,$L6))
D7: =IF($C7="","",IFERROR(TRIM(LEFT($C7,FIND("-",$C7)-1)),"")) | I7: =IF($B7="","",$H7-$G7) | J7: =IF(OR($B7="",$G7=0,$G7=""),"",$I7/$G7) | P7: =IF(OR($L7="",$N7=""),"",$L7-$N7) | Q7: =IF($B7="","",IF(N($H7)>0,"Live","Exited")) | R7: =IF($B7="","",IF($L7="","Data Pending",IF($L7>=Instructions!$D$19,"Best Fund",IF($L7>=Instructions!$D$20,"Need to Improve","Not Performing")))) | S7: =IF($R7="","",IF($R7="Data Pending","Enter the 3Y return",IF($R7="Best Fund","Hold / consider top-up",IF($R7="Need to Improve","Watch 2 quarters, then decide","Review with client - switch or exit")))) | U7: =IF($R7<>"Best Fund","",COUNTIFS($R$6:$R$505,"Best Fund",$L$6:$L$505,">"&$L7)+COUNTIFS($R$6:$R7,"Best Fund",$L$6:$L7,$L7)) | V7: =IF($R7<>"Need to Improve","",COUNTIFS($R$6:$R$505,"Need to Improve",$L$6:$L$505,"<"&$L7)+COUNTIFS($R$6:$R7,"Need to Improve",$L$6:$L7,$L7)) | W7: =IF($R7<>"Not Performing","",COUNTIFS($R$6:$R$505,"Not Performing",$L$6:$L$505,"<"&$L7)+COUNTIFS($R$6:$R7,"Not Performing",$L$6:$L7,$L7))
D8: =IF($C8="","",IFERROR(TRIM(LEFT($C8,FIND("-",$C8)-1)),"")) | I8: =IF($B8="","",$H8-$G8) | J8: =IF(OR($B8="",$G8=0,$G8=""),"",$I8/$G8) | P8: =IF(OR($L8="",$N8=""),"",$L8-$N8) | Q8: =IF($B8="","",IF(N($H8)>0,"Live","Exited")) | R8: =IF($B8="","",IF($L8="","Data Pending",IF($L8>=Instructions!$D$19,"Best Fund",IF($L8>=Instructions!$D$20,"Need to Improve","Not Performing")))) | S8: =IF($R8="","",IF($R8="Data Pending","Enter the 3Y return",IF($R8="Best Fund","Hold / consider top-up",IF($R8="Need to Improve","Watch 2 quarters, then decide","Review with client - switch or exit")))) | U8: =IF($R8<>"Best Fund","",COUNTIFS($R$6:$R$505,"Best Fund",$L$6:$L$505,">"&$L8)+COUNTIFS($R$6:$R8,"Best Fund",$L$6:$L8,$L8)) | V8: =IF($R8<>"Need to Improve","",COUNTIFS($R$6:$R$505,"Need to Improve",$L$6:$L$505,"<"&$L8)+COUNTIFS($R$6:$R8,"Need to Improve",$L$6:$L8,$L8)) | W8: =IF($R8<>"Not Performing","",COUNTIFS($R$6:$R$505,"Not Performing",$L$6:$L$505,"<"&$L8)+COUNTIFS($R$6:$R8,"Not Performing",$L$6:$L8,$L8))
D9: =IF($C9="","",IFERROR(TRIM(LEFT($C9,FIND("-",$C9)-1)),"")) | I9: =IF($B9="","",$H9-$G9) | J9: =IF(OR($B9="",$G9=0,$G9=""),"",$I9/$G9) | P9: =IF(OR($L9="",$N9=""),"",$L9-$N9) | Q9: =IF($B9="","",IF(N($H9)>0,"Live","Exited")) | R9: =IF($B9="","",IF($L9="","Data Pending",IF($L9>=Instructions!$D$19,"Best Fund",IF($L9>=Instructions!$D$20,"Need to Improve","Not Performing")))) | S9: =IF($R9="","",IF($R9="Data Pending","Enter the 3Y return",IF($R9="Best Fund","Hold / consider top-up",IF($R9="Need to Improve","Watch 2 quarters, then decide","Review with client - switch or exit")))) | U9: =IF($R9<>"Best Fund","",COUNTIFS($R$6:$R$505,"Best Fund",$L$6:$L$505,">"&$L9)+COUNTIFS($R$6:$R9,"Best Fund",$L$6:$L9,$L9)) | V9: =IF($R9<>"Need to Improve","",COUNTIFS($R$6:$R$505,"Need to Improve",$L$6:$L$505,"<"&$L9)+COUNTIFS($R$6:$R9,"Need to Improve",$L$6:$L9,$L9)) | W9: =IF($R9<>"Not Performing","",COUNTIFS($R$6:$R$505,"Not Performing",$L$6:$L$505,"<"&$L9)+COUNTIFS($R$6:$R9,"Not Performing",$L$6:$L9,$L9))
D10: =IF($C10="","",IFERROR(TRIM(LEFT($C10,FIND("-",$C10)-1)),"")) | I10: =IF($B10="","",$H10-$G10) | J10: =IF(OR($B10="",$G10=0,$G10=""),"",$I10/$G10) | P10: =IF(OR($L10="",$N10=""),"",$L10-$N10) | Q10: =IF($B10="","",IF(N($H10)>0,"Live","Exited")) | R10: =IF($B10="","",IF($L10="","Data Pending",IF($L10>=Instructions!$D$19,"Best Fund",IF($L10>=Instructions!$D$20,"Need to Improve","Not Performing")))) | S10: =IF($R10="","",IF($R10="Data Pending","Enter the 3Y return",IF($R10="Best Fund","Hold / consider top-up",IF($R10="Need to Improve","Watch 2 quarters, then decide","Review with client - switch or exit")))) | U10: =IF($R10<>"Best Fund","",COUNTIFS($R$6:$R$505,"Best Fund",$L$6:$L$505,">"&$L10)+COUNTIFS($R$6:$R10,"Best Fund",$L$6:$L10,$L10)) | V10: =IF($R10<>"Need to Improve","",COUNTIFS($R$6:$R$505,"Need to Improve",$L$6:$L$505,"<"&$L10)+COUNTIFS($R$6:$R10,"Need to Improve",$L$6:$L10,$L10)) | W10: =IF($R10<>"Not Performing","",COUNTIFS($R$6:$R$505,"Not Performing",$L$6:$L$505,"<"&$L10)+COUNTIFS($R$6:$R10,"Not Performing",$L$6:$L10,$L10))
D11: =IF($C11="","",IFERROR(TRIM(LEFT($C11,FIND("-",$C11)-1)),"")) | I11: =IF($B11="","",$H11-$G11) | J11: =IF(OR($B11="",$G11=0,$G11=""),"",$I11/$G11) | P11: =IF(OR($L11="",$N11=""),"",$L11-$N11) | Q11: =IF($B11="","",IF(N($H11)>0,"Live","Exited")) | R11: =IF($B11="","",IF($L11="","Data Pending",IF($L11>=Instructions!$D$19,"Best Fund",IF($L11>=Instructions!$D$20,"Need to Improve","Not Performing")))) | S11: =IF($R11="","",IF($R11="Data Pending","Enter the 3Y return",IF($R11="Best Fund","Hold / consider top-up",IF($R11="Need to Improve","Watch 2 quarters, then decide","Review with client - switch or exit")))) | U11: =IF($R11<>"Best Fund","",COUNTIFS($R$6:$R$505,"Best Fund",$L$6:$L$505,">"&$L11)+COUNTIFS($R$6:$R11,"Best Fund",$L$6:$L11,$L11)) | V11: =IF($R11<>"Need to Improve","",COUNTIFS($R$6:$R$505,"Need to Improve",$L$6:$L$505,"<"&$L11)+COUNTIFS($R$6:$R11,"Need to Improve",$L$6:$L11,$L11)) | W11: =IF($R11<>"Not Performing","",COUNTIFS($R$6:$R$505,"Not Performing",$L$6:$L$505,"<"&$L11)+COUNTIFS($R$6:$R11,"Not Performing",$L$6:$L11,$L11))
D12: =IF($C12="","",IFERROR(TRIM(LEFT($C12,FIND("-",$C12)-1)),"")) | I12: =IF($B12="","",$H12-$G12) | J12: =IF(OR($B12="",$G12=0,$G12=""),"",$I12/$G12) | P12: =IF(OR($L12="",$N12=""),"",$L12-$N12) | Q12: =IF($B12="","",IF(N($H12)>0,"Live","Exited")) | R12: =IF($B12="","",IF($L12="","Data Pending",IF($L12>=Instructions!$D$19,"Best Fund",IF($L12>=Instructions!$D$20,"Need to Improve","Not Performing")))) | S12: =IF($R12="","",IF($R12="Data Pending","Enter the 3Y return",IF($R12="Best Fund","Hold / consider top-up",IF($R12="Need to Improve","Watch 2 quarters, then decide","Review with client - switch or exit")))) | U12: =IF($R12<>"Best Fund","",COUNTIFS($R$6:$R$505,"Best Fund",$L$6:$L$505,">"&$L12)+COUNTIFS($R$6:$R12,"Best Fund",$L$6:$L12,$L12)) | V12: =IF($R12<>"Need to Improve","",COUNTIFS($R$6:$R$505,"Need to Improve",$L$6:$L$505,"<"&$L12)+COUNTIFS($R$6:$R12,"Need to Improve",$L$6:$L12,$L12)) | W12: =IF($R12<>"Not Performing","",COUNTIFS($R$6:$R$505,"Not Performing",$L$6:$L$505,"<"&$L12)+COUNTIFS($R$6:$R12,"Not Performing",$L$6:$L12,$L12))
D13: =IF($C13="","",IFERROR(TRIM(LEFT($C13,FIND("-",$C13)-1)),"")) | I13: =IF($B13="","",$H13-$G13) | J13: =IF(OR($B13="",$G13=0,$G13=""),"",$I13/$G13) | P13: =IF(OR($L13="",$N13=""),"",$L13-$N13) | Q13: =IF($B13="","",IF(N($H13)>0,"Live","Exited")) | R13: =IF($B13="","",IF($L13="","Data Pending",IF($L13>=Instructions!$D$19,"Best Fund",IF($L13>=Instructions!$D$20,"Need to Improve","Not Performing")))) | S13: =IF($R13="","",IF($R13="Data Pending","Enter the 3Y return",IF($R13="Best Fund","Hold / consider top-up",IF($R13="Need to Improve","Watch 2 quarters, then decide","Review with client - switch or exit")))) | U13: =IF($R13<>"Best Fund","",COUNTIFS($R$6:$R$505,"Best Fund",$L$6:$L$505,">"&$L13)+COUNTIFS($R$6:$R13,"Best Fund",$L$6:$L13,$L13)) | V13: =IF($R13<>"Need to Improve","",COUNTIFS($R$6:$R$505,"Need to Improve",$L$6:$L$505,"<"&$L13)+COUNTIFS($R$6:$R13,"Need to Improve",$L$6:$L13,$L13)) | W13: =IF($R13<>"Not Performing","",COUNTIFS($R$6:$R$505,"Not Performing",$L$6:$L$505,"<"&$L13)+COUNTIFS($R$6:$R13,"Not Performing",$L$6:$L13,$L13))
D14: =IF($C14="","",IFERROR(TRIM(LEFT($C14,FIND("-",$C14)-1)),"")) | I14: =IF($B14="","",$H14-$G14) | J14: =IF(OR($B14="",$G14=0,$G14=""),"",$I14/$G14) | P14: =IF(OR($L14="",$N14=""),"",$L14-$N14) | Q14: =IF($B14="","",IF(N($H14)>0,"Live","Exited")) | R14: =IF($B14="","",IF($L14="","Data Pending",IF($L14>=Instructions!$D$19,"Best Fund",IF($L14>=Instructions!$D$20,"Need to Improve","Not Performing")))) | S14: =IF($R14="","",IF($R14="Data Pending","Enter the 3Y return",IF($R14="Best Fund","Hold / consider top-up",IF($R14="Need to Improve","Watch 2 quarters, then decide","Review with client - switch or exit")))) | U14: =IF($R14<>"Best Fund","",COUNTIFS($R$6:$R$505,"Best Fund",$L$6:$L$505,">"&$L14)+COUNTIFS($R$6:$R14,"Best Fund",$L$6:$L14,$L14)) | V14: =IF($R14<>"Need to Improve","",COUNTIFS($R$6:$R$505,"Need to Improve",$L$6:$L$505,"<"&$L14)+COUNTIFS($R$6:$R14,"Need to Improve",$L$6:$L14,$L14)) | W14: =IF($R14<>"Not Performing","",COUNTIFS($R$6:$R$505,"Not Performing",$L$6:$L$505,"<"&$L14)+COUNTIFS($R$6:$R14,"Not Performing",$L$6:$L14,$L14))
D15: =IF($C15="","",IFERROR(TRIM(LEFT($C15,FIND("-",$C15)-1)),"")) | I15: =IF($B15="","",$H15-$G15) | J15: =IF(OR($B15="",$G15=0,$G15=""),"",$I15/$G15) | P15: =IF(OR($L15="",$N15=""),"",$L15-$N15) | Q15: =IF($B15="","",IF(N($H15)>0,"Live","Exited")) | R15: =IF($B15="","",IF($L15="","Data Pending",IF($L15>=Instructions!$D$19,"Best Fund",IF($L15>=Instructions!$D$20,"Need to Improve","Not Performing")))) | S15: =IF($R15="","",IF($R15="Data Pending","Enter the 3Y return",IF($R15="Best Fund","Hold / consider top-up",IF($R15="Need to Improve","Watch 2 quarters, then decide","Review with client - switch or exit")))) | U15: =IF($R15<>"Best Fund","",COUNTIFS($R$6:$R$505,"Best Fund",$L$6:$L$505,">"&$L15)+COUNTIFS($R$6:$R15,"Best Fund",$L$6:$L15,$L15)) | V15: =IF($R15<>"Need to Improve","",COUNTIFS($R$6:$R$505,"Need to Improve",$L$6:$L$505,"<"&$L15)+COUNTIFS($R$6:$R15,"Need to Improve",$L$6:$L15,$L15)) | W15: =IF($R15<>"Not Performing","",COUNTIFS($R$6:$R$505,"Not Performing",$L$6:$L$505,"<"&$L15)+COUNTIFS($R$6:$R15,"Not Performing",$L$6:$L15,$L15))
D16: =IF($C16="","",IFERROR(TRIM(LEFT($C16,FIND("-",$C16)-1)),"")) | I16: =IF($B16="","",$H16-$G16) | J16: =IF(OR($B16="",$G16=0,$G16=""),"",$I16/$G16) | P16: =IF(OR($L16="",$N16=""),"",$L16-$N16) | Q16: =IF($B16="","",IF(N($H16)>0,"Live","Exited")) | R16: =IF($B16="","",IF($L16="","Data Pending",IF($L16>=Instructions!$D$19,"Best Fund",IF($L16>=Instructions!$D$20,"Need to Improve","Not Performing")))) | S16: =IF($R16="","",IF($R16="Data Pending","Enter the 3Y return",IF($R16="Best Fund","Hold / consider top-up",IF($R16="Need to Improve","Watch 2 quarters, then decide","Review with client - switch or exit")))) | U16: =IF($R16<>"Best Fund","",COUNTIFS($R$6:$R$505,"Best Fund",$L$6:$L$505,">"&$L16)+COUNTIFS($R$6:$R16,"Best Fund",$L$6:$L16,$L16)) | V16: =IF($R16<>"Need to Improve","",COUNTIFS($R$6:$R$505,"Need to Improve",$L$6:$L$505,"<"&$L16)+COUNTIFS($R$6:$R16,"Need to Improve",$L$6:$L16,$L16)) | W16: =IF($R16<>"Not Performing","",COUNTIFS($R$6:$R$505,"Not Performing",$L$6:$L$505,"<"&$L16)+COUNTIFS($R$6:$R16,"Not Performing",$L$6:$L16,$L16))
D17: =IF($C17="","",IFERROR(TRIM(LEFT($C17,FIND("-",$C17)-1)),"")) | I17: =IF($B17="","",$H17-$G17) | J17: =IF(OR($B17="",$G17=0,$G17=""),"",$I17/$G17) | P17: =IF(OR($L17="",$N17=""),"",$L17-$N17) | Q17: =IF($B17="","",IF(N($H17)>0,"Live","Exited")) | R17: =IF($B17="","",IF($L17="","Data Pending",IF($L17>=Instructions!$D$19,"Best Fund",IF($L17>=Instructions!$D$20,"Need to Improve","Not Performing")))) | S17: =IF($R17="","",IF($R17="Data Pending","Enter the 3Y return",IF($R17="Best Fund","Hold / consider top-up",IF($R17="Need to Improve","Watch 2 quarters, then decide","Review with client - switch or exit")))) | U17: =IF($R17<>"Best Fund","",COUNTIFS($R$6:$R$505,"Best Fund",$L$6:$L$505,">"&$L17)+COUNTIFS($R$6:$R17,"Best Fund",$L$6:$L17,$L17)) | V17: =IF($R17<>"Need to Improve","",COUNTIFS($R$6:$R$505,"Need to Improve",$L$6:$L$505,"<"&$L17)+COUNTIFS($R$6:$R17,"Need to Improve",$L$6:$L17,$L17)) | W17: =IF($R17<>"Not Performing","",COUNTIFS($R$6:$R$505,"Not Performing",$L$6:$L$505,"<"&$L17)+COUNTIFS($R$6:$R17,"Not Performing",$L$6:$L17,$L17))
D18: =IF($C18="","",IFERROR(TRIM(LEFT($C18,FIND("-",$C18)-1)),"")) | I18: =IF($B18="","",$H18-$G18) | J18: =IF(OR($B18="",$G18=0,$G18=""),"",$I18/$G18) | P18: =IF(OR($L18="",$N18=""),"",$L18-$N18) | Q18: =IF($B18="","",IF(N($H18)>0,"Live","Exited")) | R18: =IF($B18="","",IF($L18="","Data Pending",IF($L18>=Instructions!$D$19,"Best Fund",IF($L18>=Instructions!$D$20,"Need to Improve","Not Performing")))) | S18: =IF($R18="","",IF($R18="Data Pending","Enter the 3Y return",IF($R18="Best Fund","Hold / consider top-up",IF($R18="Need to Improve","Watch 2 quarters, then decide","Review with client - switch or exit")))) | U18: =IF($R18<>"Best Fund","",COUNTIFS($R$6:$R$505,"Best Fund",$L$6:$L$505,">"&$L18)+COUNTIFS($R$6:$R18,"Best Fund",$L$6:$L18,$L18)) | V18: =IF($R18<>"Need to Improve","",COUNTIFS($R$6:$R$505,"Need to Improve",$L$6:$L$505,"<"&$L18)+COUNTIFS($R$6:$R18,"Need to Improve",$L$6:$L18,$L18)) | W18: =IF($R18<>"Not Performing","",COUNTIFS($R$6:$R$505,"Not Performing",$L$6:$L$505,"<"&$L18)+COUNTIFS($R$6:$R18,"Not Performing",$L$6:$L18,$L18))
... D505: =IF($C505="","",IFERROR(TRIM(LEFT($C505,FIND("-",$C505)-1)),"")) | I505: =IF($B505="","",$H505-$G505) | J505: =IF(OR($B505="",$G505=0,$G505=""),"",$I505/$G505) | P505: =IF(OR($L505="",$N505=""),"",$L505-$N505) | Q505: =IF($B505="","",IF(N($H505)>0,"Live","Exited")) | R505: =IF($B505="","",IF($L505="","Data Pending",IF($L505>=Instructions!$D$19,"Best Fund",IF($L505>=Instructions!$D$20,"Need to Improve","Not Performing")))) | S505: =IF($R505="","",IF($R505="Data Pending","Enter the 3Y return",IF($R505="Best Fund","Hold / consider top-up",IF($R505="Need to Improve","Watch 2 quarters, then decide","Review with client - switch or exit")))) | U505: =IF($R505<>"Best Fund","",COUNTIFS($R$6:$R$505,"Best Fund",$L$6:$L$505,">"&$L505)+COUNTIFS($R$6:$R505,"Best Fund",$L$6:$L505,$L505)) | V505: =IF($R505<>"Need to Improve","",COUNTIFS($R$6:$R$505,"Need to Improve",$L$6:$L$505,"<"&$L505)+COUNTIFS($R$6:$R505,"Need to Improve",$L$6:$L505,$L505)) | W505: =IF($R505<>"Not Performing","",COUNTIFS($R$6:$R$505,"Not Performing",$L$6:$L$505,"<"&$L505)+COUNTIFS($R$6:$R505,"Not Performing",$L$6:$L505,$L505))

Sheet Best Funds
A1: BEST FUNDS
A2: Every scheme clearing the Best threshold on 3-year return.
A3: Schemes | B3: =COUNTIF('Fund Research'!$R$6:$R$505,"Best Fund") | C3: Current value | D3: =SUMIF('Fund Research'!$R$6:$R$505,"Best Fund",'Fund Research'!$H$6:$H$505) | E3: Invested | F3: =SUMIF('Fund Research'!$R$6:$R$505,"Best Fund",'Fund Research'!$G$6:$G$505) | G3: Avg 3Y | H3: =IFERROR(AVERAGEIF('Fund Research'!$R$6:$R$505,"Best Fund",'Fund Research'!$L$6:$L$505),"")
A4: Ranked best first by 3-year return. Read-only - edit on Fund Research.
A5: # | B5: Client Name | C5: Scheme Name | D5: Category | E5: Total Invested | F5: Current Value (Live) | G5: Gain / Loss | H5: Abs. Rtn. | I5: 3Y Return (CAGR) | J5: Category Avg 3Y | K5: vs Category (3Y) | L5: Suggested Action | M5: Remark
A6: =IFERROR(IF(INDEX('Fund Research'!$B$6:$B$505,MATCH(1,'Fund Research'!$U$6:$U$505,0))="","",1),"") | B6: =IFERROR(INDEX('Fund Research'!$A$6:$A$505,MATCH(1,'Fund Research'!$U$6:$U$505,0)),"") | C6: =IFERROR(INDEX('Fund Research'!$B$6:$B$505,MATCH(1,'Fund Research'!$U$6:$U$505,0)),"") | D6: =IFERROR(INDEX('Fund Research'!$C$6:$C$505,MATCH(1,'Fund Research'!$U$6:$U$505,0)),"") | E6: =IFERROR(INDEX('Fund Research'!$G$6:$G$505,MATCH(1,'Fund Research'!$U$6:$U$505,0)),"") | F6: =IFERROR(INDEX('Fund Research'!$H$6:$H$505,MATCH(1,'Fund Research'!$U$6:$U$505,0)),"") | G6: =IFERROR(INDEX('Fund Research'!$I$6:$I$505,MATCH(1,'Fund Research'!$U$6:$U$505,0)),"") | H6: =IFERROR(INDEX('Fund Research'!$J$6:$J$505,MATCH(1,'Fund Research'!$U$6:$U$505,0)),"") | I6: =IFERROR(INDEX('Fund Research'!$L$6:$L$505,MATCH(1,'Fund Research'!$U$6:$U$505,0)),"") | J6: =IFERROR(INDEX('Fund Research'!$N$6:$N$505,MATCH(1,'Fund Research'!$U$6:$U$505,0)),"") | K6: =IFERROR(INDEX('Fund Research'!$P$6:$P$505,MATCH(1,'Fund Research'!$U$6:$U$505,0)),"") | L6: =IFERROR(INDEX('Fund Research'!$S$6:$S$505,MATCH(1,'Fund Research'!$U$6:$U$505,0)),"") | M6: =IFERROR(INDEX('Fund Research'!$T$6:$T$505,MATCH(1,'Fund Research'!$U$6:$U$505,0)),"")
A7: =IFERROR(IF(INDEX('Fund Research'!$B$6:$B$505,MATCH(2,'Fund Research'!$U$6:$U$505,0))="","",2),"") | B7: =IFERROR(INDEX('Fund Research'!$A$6:$A$505,MATCH(2,'Fund Research'!$U$6:$U$505,0)),"") | C7: =IFERROR(INDEX('Fund Research'!$B$6:$B$505,MATCH(2,'Fund Research'!$U$6:$U$505,0)),"") | D7: =IFERROR(INDEX('Fund Research'!$C$6:$C$505,MATCH(2,'Fund Research'!$U$6:$U$505,0)),"") | E7: =IFERROR(INDEX('Fund Research'!$G$6:$G$505,MATCH(2,'Fund Research'!$U$6:$U$505,0)),"") | F7: =IFERROR(INDEX('Fund Research'!$H$6:$H$505,MATCH(2,'Fund Research'!$U$6:$U$505,0)),"") | G7: =IFERROR(INDEX('Fund Research'!$I$6:$I$505,MATCH(2,'Fund Research'!$U$6:$U$505,0)),"") | H7: =IFERROR(INDEX('Fund Research'!$J$6:$J$505,MATCH(2,'Fund Research'!$U$6:$U$505,0)),"") | I7: =IFERROR(INDEX('Fund Research'!$L$6:$L$505,MATCH(2,'Fund Research'!$U$6:$U$505,0)),"") | J7: =IFERROR(INDEX('Fund Research'!$N$6:$N$505,MATCH(2,'Fund Research'!$U$6:$U$505,0)),"") | K7: =IFERROR(INDEX('Fund Research'!$P$6:$P$505,MATCH(2,'Fund Research'!$U$6:$U$505,0)),"") | L7: =IFERROR(INDEX('Fund Research'!$S$6:$S$505,MATCH(2,'Fund Research'!$U$6:$U$505,0)),"") | M7: =IFERROR(INDEX('Fund Research'!$T$6:$T$505,MATCH(2,'Fund Research'!$U$6:$U$505,0)),"")
A8: =IFERROR(IF(INDEX('Fund Research'!$B$6:$B$505,MATCH(3,'Fund Research'!$U$6:$U$505,0))="","",3),"") | B8: =IFERROR(INDEX('Fund Research'!$A$6:$A$505,MATCH(3,'Fund Research'!$U$6:$U$505,0)),"") | C8: =IFERROR(INDEX('Fund Research'!$B$6:$B$505,MATCH(3,'Fund Research'!$U$6:$U$505,0)),"") | D8: =IFERROR(INDEX('Fund Research'!$C$6:$C$505,MATCH(3,'Fund Research'!$U$6:$U$505,0)),"") | E8: =IFERROR(INDEX('Fund Research'!$G$6:$G$505,MATCH(3,'Fund Research'!$U$6:$U$505,0)),"") | F8: =IFERROR(INDEX('Fund Research'!$H$6:$H$505,MATCH(3,'Fund Research'!$U$6:$U$505,0)),"") | G8: =IFERROR(INDEX('Fund Research'!$I$6:$I$505,MATCH(3,'Fund Research'!$U$6:$U$505,0)),"") | H8: =IFERROR(INDEX('Fund Research'!$J$6:$J$505,MATCH(3,'Fund Research'!$U$6:$U$505,0)),"") | I8: =IFERROR(INDEX('Fund Research'!$L$6:$L$505,MATCH(3,'Fund Research'!$U$6:$U$505,0)),"") | J8: =IFERROR(INDEX('Fund Research'!$N$6:$N$505,MATCH(3,'Fund Research'!$U$6:$U$505,0)),"") | K8: =IFERROR(INDEX('Fund Research'!$P$6:$P$505,MATCH(3,'Fund Research'!$U$6:$U$505,0)),"") | L8: =IFERROR(INDEX('Fund Research'!$S$6:$S$505,MATCH(3,'Fund Research'!$U$6:$U$505,0)),"") | M8: =IFERROR(INDEX('Fund Research'!$T$6:$T$505,MATCH(3,'Fund Research'!$U$6:$U$505,0)),"")
A9: =IFERROR(IF(INDEX('Fund Research'!$B$6:$B$505,MATCH(4,'Fund Research'!$U$6:$U$505,0))="","",4),"") | B9: =IFERROR(INDEX('Fund Research'!$A$6:$A$505,MATCH(4,'Fund Research'!$U$6:$U$505,0)),"") | C9: =IFERROR(INDEX('Fund Research'!$B$6:$B$505,MATCH(4,'Fund Research'!$U$6:$U$505,0)),"") | D9: =IFERROR(INDEX('Fund Research'!$C$6:$C$505,MATCH(4,'Fund Research'!$U$6:$U$505,0)),"") | E9: =IFERROR(INDEX('Fund Research'!$G$6:$G$505,MATCH(4,'Fund Research'!$U$6:$U$505,0)),"") | F9: =IFERROR(INDEX('Fund Research'!$H$6:$H$505,MATCH(4,'Fund Research'!$U$6:$U$505,0)),"") | G9: =IFERROR(INDEX('Fund Research'!$I$6:$I$505,MATCH(4,'Fund Research'!$U$6:$U$505,0)),"") | H9: =IFERROR(INDEX('Fund Research'!$J$6:$J$505,MATCH(4,'Fund Research'!$U$6:$U$505,0)),"") | I9: =IFERROR(INDEX('Fund Research'!$L$6:$L$505,MATCH(4,'Fund Research'!$U$6:$U$505,0)),"") | J9: =IFERROR(INDEX('Fund Research'!$N$6:$N$505,MATCH(4,'Fund Research'!$U$6:$U$505,0)),"") | K9: =IFERROR(INDEX('Fund Research'!$P$6:$P$505,MATCH(4,'Fund Research'!$U$6:$U$505,0)),"") | L9: =IFERROR(INDEX('Fund Research'!$S$6:$S$505,MATCH(4,'Fund Research'!$U$6:$U$505,0)),"") | M9: =IFERROR(INDEX('Fund Research'!$T$6:$T$505,MATCH(4,'Fund Research'!$U$6:$U$505,0)),"")
A10: =IFERROR(IF(INDEX('Fund Research'!$B$6:$B$505,MATCH(5,'Fund Research'!$U$6:$U$505,0))="","",5),"") | B10: =IFERROR(INDEX('Fund Research'!$A$6:$A$505,MATCH(5,'Fund Research'!$U$6:$U$505,0)),"") | C10: =IFERROR(INDEX('Fund Research'!$B$6:$B$505,MATCH(5,'Fund Research'!$U$6:$U$505,0)),"") | D10: =IFERROR(INDEX('Fund Research'!$C$6:$C$505,MATCH(5,'Fund Research'!$U$6:$U$505,0)),"") | E10: =IFERROR(INDEX('Fund Research'!$G$6:$G$505,MATCH(5,'Fund Research'!$U$6:$U$505,0)),"") | F10: =IFERROR(INDEX('Fund Research'!$H$6:$H$505,MATCH(5,'Fund Research'!$U$6:$U$505,0)),"") | G10: =IFERROR(INDEX('Fund Research'!$I$6:$I$505,MATCH(5,'Fund Research'!$U$6:$U$505,0)),"") | H10: =IFERROR(INDEX('Fund Research'!$J$6:$J$505,MATCH(5,'Fund Research'!$U$6:$U$505,0)),"") | I10: =IFERROR(INDEX('Fund Research'!$L$6:$L$505,MATCH(5,'Fund Research'!$U$6:$U$505,0)),"") | J10: =IFERROR(INDEX('Fund Research'!$N$6:$N$505,MATCH(5,'Fund Research'!$U$6:$U$505,0)),"") | K10: =IFERROR(INDEX('Fund Research'!$P$6:$P$505,MATCH(5,'Fund Research'!$U$6:$U$505,0)),"") | L10: =IFERROR(INDEX('Fund Research'!$S$6:$S$505,MATCH(5,'Fund Research'!$U$6:$U$505,0)),"") | M10: =IFERROR(INDEX('Fund Research'!$T$6:$T$505,MATCH(5,'Fund Research'!$U$6:$U$505,0)),"")
A11: =IFERROR(IF(INDEX('Fund Research'!$B$6:$B$505,MATCH(6,'Fund Research'!$U$6:$U$505,0))="","",6),"") | B11: =IFERROR(INDEX('Fund Research'!$A$6:$A$505,MATCH(6,'Fund Research'!$U$6:$U$505,0)),"") | C11: =IFERROR(INDEX('Fund Research'!$B$6:$B$505,MATCH(6,'Fund Research'!$U$6:$U$505,0)),"") | D11: =IFERROR(INDEX('Fund Research'!$C$6:$C$505,MATCH(6,'Fund Research'!$U$6:$U$505,0)),"") | E11: =IFERROR(INDEX('Fund Research'!$G$6:$G$505,MATCH(6,'Fund Research'!$U$6:$U$505,0)),"") | F11: =IFERROR(INDEX('Fund Research'!$H$6:$H$505,MATCH(6,'Fund Research'!$U$6:$U$505,0)),"") | G11: =IFERROR(INDEX('Fund Research'!$I$6:$I$505,MATCH(6,'Fund Research'!$U$6:$U$505,0)),"") | H11: =IFERROR(INDEX('Fund Research'!$J$6:$J$505,MATCH(6,'Fund Research'!$U$6:$U$505,0)),"") | I11: =IFERROR(INDEX('Fund Research'!$L$6:$L$505,MATCH(6,'Fund Research'!$U$6:$U$505,0)),"") | J11: =IFERROR(INDEX('Fund Research'!$N$6:$N$505,MATCH(6,'Fund Research'!$U$6:$U$505,0)),"") | K11: =IFERROR(INDEX('Fund Research'!$P$6:$P$505,MATCH(6,'Fund Research'!$U$6:$U$505,0)),"") | L11: =IFERROR(INDEX('Fund Research'!$S$6:$S$505,MATCH(6,'Fund Research'!$U$6:$U$505,0)),"") | M11: =IFERROR(INDEX('Fund Research'!$T$6:$T$505,MATCH(6,'Fund Research'!$U$6:$U$505,0)),"")
A12: =IFERROR(IF(INDEX('Fund Research'!$B$6:$B$505,MATCH(7,'Fund Research'!$U$6:$U$505,0))="","",7),"") | B12: =IFERROR(INDEX('Fund Research'!$A$6:$A$505,MATCH(7,'Fund Research'!$U$6:$U$505,0)),"") | C12: =IFERROR(INDEX('Fund Research'!$B$6:$B$505,MATCH(7,'Fund Research'!$U$6:$U$505,0)),"") | D12: =IFERROR(INDEX('Fund Research'!$C$6:$C$505,MATCH(7,'Fund Research'!$U$6:$U$505,0)),"") | E12: =IFERROR(INDEX('Fund Research'!$G$6:$G$505,MATCH(7,'Fund Research'!$U$6:$U$505,0)),"") | F12: =IFERROR(INDEX('Fund Research'!$H$6:$H$505,MATCH(7,'Fund Research'!$U$6:$U$505,0)),"") | G12: =IFERROR(INDEX('Fund Research'!$I$6:$I$505,MATCH(7,'Fund Research'!$U$6:$U$505,0)),"") | H12: =IFERROR(INDEX('Fund Research'!$J$6:$J$505,MATCH(7,'Fund Research'!$U$6:$U$505,0)),"") | I12: =IFERROR(INDEX('Fund Research'!$L$6:$L$505,MATCH(7,'Fund Research'!$U$6:$U$505,0)),"") | J12: =IFERROR(INDEX('Fund Research'!$N$6:$N$505,MATCH(7,'Fund Research'!$U$6:$U$505,0)),"") | K12: =IFERROR(INDEX('Fund Research'!$P$6:$P$505,MATCH(7,'Fund Research'!$U$6:$U$505,0)),"") | L12: =IFERROR(INDEX('Fund Research'!$S$6:$S$505,MATCH(7,'Fund Research'!$U$6:$U$505,0)),"") | M12: =IFERROR(INDEX('Fund Research'!$T$6:$T$505,MATCH(7,'Fund Research'!$U$6:$U$505,0)),"")
A13: =IFERROR(IF(INDEX('Fund Research'!$B$6:$B$505,MATCH(8,'Fund Research'!$U$6:$U$505,0))="","",8),"") | B13: =IFERROR(INDEX('Fund Research'!$A$6:$A$505,MATCH(8,'Fund Research'!$U$6:$U$505,0)),"") | C13: =IFERROR(INDEX('Fund Research'!$B$6:$B$505,MATCH(8,'Fund Research'!$U$6:$U$505,0)),"") | D13: =IFERROR(INDEX('Fund Research'!$C$6:$C$505,MATCH(8,'Fund Research'!$U$6:$U$505,0)),"") | E13: =IFERROR(INDEX('Fund Research'!$G$6:$G$505,MATCH(8,'Fund Research'!$U$6:$U$505,0)),"") | F13: =IFERROR(INDEX('Fund Research'!$H$6:$H$505,MATCH(8,'Fund Research'!$U$6:$U$505,0)),"") | G13: =IFERROR(INDEX('Fund Research'!$I$6:$I$505,MATCH(8,'Fund Research'!$U$6:$U$505,0)),"") | H13: =IFERROR(INDEX('Fund Research'!$J$6:$J$505,MATCH(8,'Fund Research'!$U$6:$U$505,0)),"") | I13: =IFERROR(INDEX('Fund Research'!$L$6:$L$505,MATCH(8,'Fund Research'!$U$6:$U$505,0)),"") | J13: =IFERROR(INDEX('Fund Research'!$N$6:$N$505,MATCH(8,'Fund Research'!$U$6:$U$505,0)),"") | K13: =IFERROR(INDEX('Fund Research'!$P$6:$P$505,MATCH(8,'Fund Research'!$U$6:$U$505,0)),"") | L13: =IFERROR(INDEX('Fund Research'!$S$6:$S$505,MATCH(8,'Fund Research'!$U$6:$U$505,0)),"") | M13: =IFERROR(INDEX('Fund Research'!$T$6:$T$505,MATCH(8,'Fund Research'!$U$6:$U$505,0)),"")
A14: =IFERROR(IF(INDEX('Fund Research'!$B$6:$B$505,MATCH(9,'Fund Research'!$U$6:$U$505,0))="","",9),"") | B14: =IFERROR(INDEX('Fund Research'!$A$6:$A$505,MATCH(9,'Fund Research'!$U$6:$U$505,0)),"") | C14: =IFERROR(INDEX('Fund Research'!$B$6:$B$505,MATCH(9,'Fund Research'!$U$6:$U$505,0)),"") | D14: =IFERROR(INDEX('Fund Research'!$C$6:$C$505,MATCH(9,'Fund Research'!$U$6:$U$505,0)),"") | E14: =IFERROR(INDEX('Fund Research'!$G$6:$G$505,MATCH(9,'Fund Research'!$U$6:$U$505,0)),"") | F14: =IFERROR(INDEX('Fund Research'!$H$6:$H$505,MATCH(9,'Fund Research'!$U$6:$U$505,0)),"") | G14: =IFERROR(INDEX('Fund Research'!$I$6:$I$505,MATCH(9,'Fund Research'!$U$6:$U$505,0)),"") | H14: =IFERROR(INDEX('Fund Research'!$J$6:$J$505,MATCH(9,'Fund Research'!$U$6:$U$505,0)),"") | I14: =IFERROR(INDEX('Fund Research'!$L$6:$L$505,MATCH(9,'Fund Research'!$U$6:$U$505,0)),"") | J14: =IFERROR(INDEX('Fund Research'!$N$6:$N$505,MATCH(9,'Fund Research'!$U$6:$U$505,0)),"") | K14: =IFERROR(INDEX('Fund Research'!$P$6:$P$505,MATCH(9,'Fund Research'!$U$6:$U$505,0)),"") | L14: =IFERROR(INDEX('Fund Research'!$S$6:$S$505,MATCH(9,'Fund Research'!$U$6:$U$505,0)),"") | M14: =IFERROR(INDEX('Fund Research'!$T$6:$T$505,MATCH(9,'Fund Research'!$U$6:$U$505,0)),"")
A15: =IFERROR(IF(INDEX('Fund Research'!$B$6:$B$505,MATCH(10,'Fund Research'!$U$6:$U$505,0))="","",10),"") | B15: =IFERROR(INDEX('Fund Research'!$A$6:$A$505,MATCH(10,'Fund Research'!$U$6:$U$505,0)),"") | C15: =IFERROR(INDEX('Fund Research'!$B$6:$B$505,MATCH(10,'Fund Research'!$U$6:$U$505,0)),"") | D15: =IFERROR(INDEX('Fund Research'!$C$6:$C$505,MATCH(10,'Fund Research'!$U$6:$U$505,0)),"") | E15: =IFERROR(INDEX('Fund Research'!$G$6:$G$505,MATCH(10,'Fund Research'!$U$6:$U$505,0)),"") | F15: =IFERROR(INDEX('Fund Research'!$H$6:$H$505,MATCH(10,'Fund Research'!$U$6:$U$505,0)),"") | G15: =IFERROR(INDEX('Fund Research'!$I$6:$I$505,MATCH(10,'Fund Research'!$U$6:$U$505,0)),"") | H15: =IFERROR(INDEX('Fund Research'!$J$6:$J$505,MATCH(10,'Fund Research'!$U$6:$U$505,0)),"") | I15: =IFERROR(INDEX('Fund Research'!$L$6:$L$505,MATCH(10,'Fund Research'!$U$6:$U$505,0)),"") | J15: =IFERROR(INDEX('Fund Research'!$N$6:$N$505,MATCH(10,'Fund Research'!$U$6:$U$505,0)),"") | K15: =IFERROR(INDEX('Fund Research'!$P$6:$P$505,MATCH(10,'Fund Research'!$U$6:$U$505,0)),"") | L15: =IFERROR(INDEX('Fund Research'!$S$6:$S$505,MATCH(10,'Fund Research'!$U$6:$U$505,0)),"") | M15: =IFERROR(INDEX('Fund Research'!$T$6:$T$505,MATCH(10,'Fund Research'!$U$6:$U$505,0)),"")
A16: =IFERROR(IF(INDEX('Fund Research'!$B$6:$B$505,MATCH(11,'Fund Research'!$U$6:$U$505,0))="","",11),"") | B16: =IFERROR(INDEX('Fund Research'!$A$6:$A$505,MATCH(11,'Fund Research'!$U$6:$U$505,0)),"") | C16: =IFERROR(INDEX('Fund Research'!$B$6:$B$505,MATCH(11,'Fund Research'!$U$6:$U$505,0)),"") | D16: =IFERROR(INDEX('Fund Research'!$C$6:$C$505,MATCH(11,'Fund Research'!$U$6:$U$505,0)),"") | E16: =IFERROR(INDEX('Fund Research'!$G$6:$G$505,MATCH(11,'Fund Research'!$U$6:$U$505,0)),"") | F16: =IFERROR(INDEX('Fund Research'!$H$6:$H$505,MATCH(11,'Fund Research'!$U$6:$U$505,0)),"") | G16: =IFERROR(INDEX('Fund Research'!$I$6:$I$505,MATCH(11,'Fund Research'!$U$6:$U$505,0)),"") | H16: =IFERROR(INDEX('Fund Research'!$J$6:$J$505,MATCH(11,'Fund Research'!$U$6:$U$505,0)),"") | I16: =IFERROR(INDEX('Fund Research'!$L$6:$L$505,MATCH(11,'Fund Research'!$U$6:$U$505,0)),"") | J16: =IFERROR(INDEX('Fund Research'!$N$6:$N$505,MATCH(11,'Fund Research'!$U$6:$U$505,0)),"") | K16: =IFERROR(INDEX('Fund Research'!$P$6:$P$505,MATCH(11,'Fund Research'!$U$6:$U$505,0)),"") | L16: =IFERROR(INDEX('Fund Research'!$S$6:$S$505,MATCH(11,'Fund Research'!$U$6:$U$505,0)),"") | M16: =IFERROR(INDEX('Fund Research'!$T$6:$T$505,MATCH(11,'Fund Research'!$U$6:$U$505,0)),"")
A17: =IFERROR(IF(INDEX('Fund Research'!$B$6:$B$505,MATCH(12,'Fund Research'!$U$6:$U$505,0))="","",12),"") | B17: =IFERROR(INDEX('Fund Research'!$A$6:$A$505,MATCH(12,'Fund Research'!$U$6:$U$505,0)),"") | C17: =IFERROR(INDEX('Fund Research'!$B$6:$B$505,MATCH(12,'Fund Research'!$U$6:$U$505,0)),"") | D17: =IFERROR(INDEX('Fund Research'!$C$6:$C$505,MATCH(12,'Fund Research'!$U$6:$U$505,0)),"") | E17: =IFERROR(INDEX('Fund Research'!$G$6:$G$505,MATCH(12,'Fund Research'!$U$6:$U$505,0)),"") | F17: =IFERROR(INDEX('Fund Research'!$H$6:$H$505,MATCH(12,'Fund Research'!$U$6:$U$505,0)),"") | G17: =IFERROR(INDEX('Fund Research'!$I$6:$I$505,MATCH(12,'Fund Research'!$U$6:$U$505,0)),"") | H17: =IFERROR(INDEX('Fund Research'!$J$6:$J$505,MATCH(12,'Fund Research'!$U$6:$U$505,0)),"") | I17: =IFERROR(INDEX('Fund Research'!$L$6:$L$505,MATCH(12,'Fund Research'!$U$6:$U$505,0)),"") | J17: =IFERROR(INDEX('Fund Research'!$N$6:$N$505,MATCH(12,'Fund Research'!$U$6:$U$505,0)),"") | K17: =IFERROR(INDEX('Fund Research'!$P$6:$P$505,MATCH(12,'Fund Research'!$U$6:$U$505,0)),"") | L17: =IFERROR(INDEX('Fund Research'!$S$6:$S$505,MATCH(12,'Fund Research'!$U$6:$U$505,0)),"") | M17: =IFERROR(INDEX('Fund Research'!$T$6:$T$505,MATCH(12,'Fund Research'!$U$6:$U$505,0)),"")
A18: =IFERROR(IF(INDEX('Fund Research'!$B$6:$B$505,MATCH(13,'Fund Research'!$U$6:$U$505,0))="","",13),"") | B18: =IFERROR(INDEX('Fund Research'!$A$6:$A$505,MATCH(13,'Fund Research'!$U$6:$U$505,0)),"") | C18: =IFERROR(INDEX('Fund Research'!$B$6:$B$505,MATCH(13,'Fund Research'!$U$6:$U$505,0)),"") | D18: =IFERROR(INDEX('Fund Research'!$C$6:$C$505,MATCH(13,'Fund Research'!$U$6:$U$505,0)),"") | E18: =IFERROR(INDEX('Fund Research'!$G$6:$G$505,MATCH(13,'Fund Research'!$U$6:$U$505,0)),"") | F18: =IFERROR(INDEX('Fund Research'!$H$6:$H$505,MATCH(13,'Fund Research'!$U$6:$U$505,0)),"") | G18: =IFERROR(INDEX('Fund Research'!$I$6:$I$505,MATCH(13,'Fund Research'!$U$6:$U$505,0)),"") | H18: =IFERROR(INDEX('Fund Research'!$J$6:$J$505,MATCH(13,'Fund Research'!$U$6:$U$505,0)),"") | I18: =IFERROR(INDEX('Fund Research'!$L$6:$L$505,MATCH(13,'Fund Research'!$U$6:$U$505,0)),"") | J18: =IFERROR(INDEX('Fund Research'!$N$6:$N$505,MATCH(13,'Fund Research'!$U$6:$U$505,0)),"") | K18: =IFERROR(INDEX('Fund Research'!$P$6:$P$505,MATCH(13,'Fund Research'!$U$6:$U$505,0)),"") | L18: =IFERROR(INDEX('Fund Research'!$S$6:$S$505,MATCH(13,'Fund Research'!$U$6:$U$505,0)),"") | M18: =IFERROR(INDEX('Fund Research'!$T$6:$T$505,MATCH(13,'Fund Research'!$U$6:$U$505,0)),"")
A19: =IFERROR(IF(INDEX('Fund Research'!$B$6:$B$505,MATCH(14,'Fund Research'!$U$6:$U$505,0))="","",14),"") | B19: =IFERROR(INDEX('Fund Research'!$A$6:$A$505,MATCH(14,'Fund Research'!$U$6:$U$505,0)),"") | C19: =IFERROR(INDEX('Fund Research'!$B$6:$B$505,MATCH(14,'Fund Research'!$U$6:$U$505,0)),"") | D19: =IFERROR(INDEX('Fund Research'!$C$6:$C$505,MATCH(14,'Fund Research'!$U$6:$U$505,0)),"") | E19: =IFERROR(INDEX('Fund Research'!$G$6:$G$505,MATCH(14,'Fund Research'!$U$6:$U$505,0)),"") | F19: =IFERROR(INDEX('Fund Research'!$H$6:$H$505,MATCH(14,'Fund Research'!$U$6:$U$505,0)),"") | G19: =IFERROR(INDEX('Fund Research'!$I$6:$I$505,MATCH(14,'Fund Research'!$U$6:$U$505,0)),"") | H19: =IFERROR(INDEX('Fund Research'!$J$6:$J$505,MATCH(14,'Fund Research'!$U$6:$U$505,0)),"") | I19: =IFERROR(INDEX('Fund Research'!$L$6:$L$505,MATCH(14,'Fund Research'!$U$6:$U$505,0)),"") | J19: =IFERROR(INDEX('Fund Research'!$N$6:$N$505,MATCH(14,'Fund Research'!$U$6:$U$505,0)),"") | K19: =IFERROR(INDEX('Fund Research'!$P$6:$P$505,MATCH(14,'Fund Research'!$U$6:$U$505,0)),"") | L19: =IFERROR(INDEX('Fund Research'!$S$6:$S$505,MATCH(14,'Fund Research'!$U$6:$U$505,0)),"") | M19: =IFERROR(INDEX('Fund Research'!$T$6:$T$505,MATCH(14,'Fund Research'!$U$6:$U$505,0)),"")
A20: =IFERROR(IF(INDEX('Fund Research'!$B$6:$B$505,MATCH(15,'Fund Research'!$U$6:$U$505,0))="","",15),"") | B20: =IFERROR(INDEX('Fund Research'!$A$6:$A$505,MATCH(15,'Fund Research'!$U$6:$U$505,0)),"") | C20: =IFERROR(INDEX('Fund Research'!$B$6:$B$505,MATCH(15,'Fund Research'!$U$6:$U$505,0)),"") | D20: =IFERROR(INDEX('Fund Research'!$C$6:$C$505,MATCH(15,'Fund Research'!$U$6:$U$505,0)),"") | E20: =IFERROR(INDEX('Fund Research'!$G$6:$G$505,MATCH(15,'Fund Research'!$U$6:$U$505,0)),"") | F20: =IFERROR(INDEX('Fund Research'!$H$6:$H$505,MATCH(15,'Fund Research'!$U$6:$U$505,0)),"") | G20: =IFERROR(INDEX('Fund Research'!$I$6:$I$505,MATCH(15,'Fund Research'!$U$6:$U$505,0)),"") | H20: =IFERROR(INDEX('Fund Research'!$J$6:$J$505,MATCH(15,'Fund Research'!$U$6:$U$505,0)),"") | I20: =IFERROR(INDEX('Fund Research'!$L$6:$L$505,MATCH(15,'Fund Research'!$U$6:$U$505,0)),"") | J20: =IFERROR(INDEX('Fund Research'!$N$6:$N$505,MATCH(15,'Fund Research'!$U$6:$U$505,0)),"") | K20: =IFERROR(INDEX('Fund Research'!$P$6:$P$505,MATCH(15,'Fund Research'!$U$6:$U$505,0)),"") | L20: =IFERROR(INDEX('Fund Research'!$S$6:$S$505,MATCH(15,'Fund Research'!$U$6:$U$505,0)),"") | M20: =IFERROR(INDEX('Fund Research'!$T$6:$T$505,MATCH(15,'Fund Research'!$U$6:$U$505,0)),"")
A21: =IFERROR(IF(INDEX('Fund Research'!$B$6:$B$505,MATCH(16,'Fund Research'!$U$6:$U$505,0))="","",16),"") | B21: =IFERROR(INDEX('Fund Research'!$A$6:$A$505,MATCH(16,'Fund Research'!$U$6:$U$505,0)),"") | C21: =IFERROR(INDEX('Fund Research'!$B$6:$B$505,MATCH(16,'Fund Research'!$U$6:$U$505,0)),"") | D21: =IFERROR(INDEX('Fund Research'!$C$6:$C$505,MATCH(16,'Fund Research'!$U$6:$U$505,0)),"") | E21: =IFERROR(INDEX('Fund Research'!$G$6:$G$505,MATCH(16,'Fund Research'!$U$6:$U$505,0)),"") | F21: =IFERROR(INDEX('Fund Research'!$H$6:$H$505,MATCH(16,'Fund Research'!$U$6:$U$505,0)),"") | G21: =IFERROR(INDEX('Fund Research'!$I$6:$I$505,MATCH(16,'Fund Research'!$U$6:$U$505,0)),"") | H21: =IFERROR(INDEX('Fund Research'!$J$6:$J$505,MATCH(16,'Fund Research'!$U$6:$U$505,0)),"") | I21: =IFERROR(INDEX('Fund Research'!$L$6:$L$505,MATCH(16,'Fund Research'!$U$6:$U$505,0)),"") | J21: =IFERROR(INDEX('Fund Research'!$N$6:$N$505,MATCH(16,'Fund Research'!$U$6:$U$505,0)),"") | K21: =IFERROR(INDEX('Fund Research'!$P$6:$P$505,MATCH(16,'Fund Research'!$U$6:$U$505,0)),"") | L21: =IFERROR(INDEX('Fund Research'!$S$6:$S$505,MATCH(16,'Fund Research'!$U$6:$U$505,0)),"") | M21: =IFERROR(INDEX('Fund Research'!$T$6:$T$505,MATCH(16,'Fund Research'!$U$6:$U$505,0)),"")
A22: =IFERROR(IF(INDEX('Fund Research'!$B$6:$B$505,MATCH(17,'Fund Research'!$U$6:$U$505,0))="","",17),"") | B22: =IFERROR(INDEX('Fund Research'!$A$6:$A$505,MATCH(17,'Fund Research'!$U$6:$U$505,0)),"") | C22: =IFERROR(INDEX('Fund Research'!$B$6:$B$505,MATCH(17,'Fund Research'!$U$6:$U$505,0)),"") | D22: =IFERROR(INDEX('Fund Research'!$C$6:$C$505,MATCH(17,'Fund Research'!$U$6:$U$505,0)),"") | E22: =IFERROR(INDEX('Fund Research'!$G$6:$G$505,MATCH(17,'Fund Research'!$U$6:$U$505,0)),"") | F22: =IFERROR(INDEX('Fund Research'!$H$6:$H$505,MATCH(17,'Fund Research'!$U$6:$U$505,0)),"") | G22: =IFERROR(INDEX('Fund Research'!$I$6:$I$505,MATCH(17,'Fund Research'!$U$6:$U$505,0)),"") | H22: =IFERROR(INDEX('Fund Research'!$J$6:$J$505,MATCH(17,'Fund Research'!$U$6:$U$505,0)),"") | I22: =IFERROR(INDEX('Fund Research'!$L$6:$L$505,MATCH(17,'Fund Research'!$U$6:$U$505,0)),"") | J22: =IFERROR(INDEX('Fund Research'!$N$6:$N$505,MATCH(17,'Fund Research'!$U$6:$U$505,0)),"") | K22: =IFERROR(INDEX('Fund Research'!$P$6:$P$505,MATCH(17,'Fund Research'!$U$6:$U$505,0)),"") | L22: =IFERROR(INDEX('Fund Research'!$S$6:$S$505,MATCH(17,'Fund Research'!$U$6:$U$505,0)),"") | M22: =IFERROR(INDEX('Fund Research'!$T$6:$T$505,MATCH(17,'Fund Research'!$U$6:$U$505,0)),"")
A23: =IFERROR(IF(INDEX('Fund Research'!$B$6:$B$505,MATCH(18,'Fund Research'!$U$6:$U$505,0))="","",18),"") | B23: =IFERROR(INDEX('Fund Research'!$A$6:$A$505,MATCH(18,'Fund Research'!$U$6:$U$505,0)),"") | C23: =IFERROR(INDEX('Fund Research'!$B$6:$B$505,MATCH(18,'Fund Research'!$U$6:$U$505,0)),"") | D23: =IFERROR(INDEX('Fund Research'!$C$6:$C$505,MATCH(18,'Fund Research'!$U$6:$U$505,0)),"") | E23: =IFERROR(INDEX('Fund Research'!$G$6:$G$505,MATCH(18,'Fund Research'!$U$6:$U$505,0)),"") | F23: =IFERROR(INDEX('Fund Research'!$H$6:$H$505,MATCH(18,'Fund Research'!$U$6:$U$505,0)),"") | G23: =IFERROR(INDEX('Fund Research'!$I$6:$I$505,MATCH(18,'Fund Research'!$U$6:$U$505,0)),"") | H23: =IFERROR(INDEX('Fund Research'!$J$6:$J$505,MATCH(18,'Fund Research'!$U$6:$U$505,0)),"") | I23: =IFERROR(INDEX('Fund Research'!$L$6:$L$505,MATCH(18,'Fund Research'!$U$6:$U$505,0)),"") | J23: =IFERROR(INDEX('Fund Research'!$N$6:$N$505,MATCH(18,'Fund Research'!$U$6:$U$505,0)),"") | K23: =IFERROR(INDEX('Fund Research'!$P$6:$P$505,MATCH(18,'Fund Research'!$U$6:$U$505,0)),"") | L23: =IFERROR(INDEX('Fund Research'!$S$6:$S$505,MATCH(18,'Fund Research'!$U$6:$U$505,0)),"") | M23: =IFERROR(INDEX('Fund Research'!$T$6:$T$505,MATCH(18,'Fund Research'!$U$6:$U$505,0)),"")
A24: =IFERROR(IF(INDEX('Fund Research'!$B$6:$B$505,MATCH(19,'Fund Research'!$U$6:$U$505,0))="","",19),"") | B24: =IFERROR(INDEX('Fund Research'!$A$6:$A$505,MATCH(19,'Fund Research'!$U$6:$U$505,0)),"") | C24: =IFERROR(INDEX('Fund Research'!$B$6:$B$505,MATCH(19,'Fund Research'!$U$6:$U$505,0)),"") | D24: =IFERROR(INDEX('Fund Research'!$C$6:$C$505,MATCH(19,'Fund Research'!$U$6:$U$505,0)),"") | E24: =IFERROR(INDEX('Fund Research'!$G$6:$G$505,MATCH(19,'Fund Research'!$U$6:$U$505,0)),"") | F24: =IFERROR(INDEX('Fund Research'!$H$6:$H$505,MATCH(19,'Fund Research'!$U$6:$U$505,0)),"") | G24: =IFERROR(INDEX('Fund Research'!$I$6:$I$505,MATCH(19,'Fund Research'!$U$6:$U$505,0)),"") | H24: =IFERROR(INDEX('Fund Research'!$J$6:$J$505,MATCH(19,'Fund Research'!$U$6:$U$505,0)),"") | I24: =IFERROR(INDEX('Fund Research'!$L$6:$L$505,MATCH(19,'Fund Research'!$U$6:$U$505,0)),"") | J24: =IFERROR(INDEX('Fund Research'!$N$6:$N$505,MATCH(19,'Fund Research'!$U$6:$U$505,0)),"") | K24: =IFERROR(INDEX('Fund Research'!$P$6:$P$505,MATCH(19,'Fund Research'!$U$6:$U$505,0)),"") | L24: =IFERROR(INDEX('Fund Research'!$S$6:$S$505,MATCH(19,'Fund Research'!$U$6:$U$505,0)),"") | M24: =IFERROR(INDEX('Fund Research'!$T$6:$T$505,MATCH(19,'Fund Research'!$U$6:$U$505,0)),"")
A25: =IFERROR(IF(INDEX('Fund Research'!$B$6:$B$505,MATCH(20,'Fund Research'!$U$6:$U$505,0))="","",20),"") | B25: =IFERROR(INDEX('Fund Research'!$A$6:$A$505,MATCH(20,'Fund Research'!$U$6:$U$505,0)),"") | C25: =IFERROR(INDEX('Fund Research'!$B$6:$B$505,MATCH(20,'Fund Research'!$U$6:$U$505,0)),"") | D25: =IFERROR(INDEX('Fund Research'!$C$6:$C$505,MATCH(20,'Fund Research'!$U$6:$U$505,0)),"") | E25: =IFERROR(INDEX('Fund Research'!$G$6:$G$505,MATCH(20,'Fund Research'!$U$6:$U$505,0)),"") | F25: =IFERROR(INDEX('Fund Research'!$H$6:$H$505,MATCH(20,'Fund Research'!$U$6:$U$505,0)),"") | G25: =IFERROR(INDEX('Fund Research'!$I$6:$I$505,MATCH(20,'Fund Research'!$U$6:$U$505,0)),"") | H25: =IFERROR(INDEX('Fund Research'!$J$6:$J$505,MATCH(20,'Fund Research'!$U$6:$U$505,0)),"") | I25: =IFERROR(INDEX('Fund Research'!$L$6:$L$505,MATCH(20,'Fund Research'!$U$6:$U$505,0)),"") | J25: =IFERROR(INDEX('Fund Research'!$N$6:$N$505,MATCH(20,'Fund Research'!$U$6:$U$505,0)),"") | K25: =IFERROR(INDEX('Fund Research'!$P$6:$P$505,MATCH(20,'Fund Research'!$U$6:$U$505,0)),"") | L25: =IFERROR(INDEX('Fund Research'!$S$6:$S$505,MATCH(20,'Fund Research'!$U$6:$U$505,0)),"") | M25: =IFERROR(INDEX('Fund Research'!$T$6:$T$505,MATCH(20,'Fund Research'!$U$6:$U$505,0)),"")
A26: =IFERROR(IF(INDEX('Fund Research'!$B$6:$B$505,MATCH(21,'Fund Research'!$U$6:$U$505,0))="","",21),"") | B26: =IFERROR(INDEX('Fund Research'!$A$6:$A$505,MATCH(21,'Fund Research'!$U$6:$U$505,0)),"") | C26: =IFERROR(INDEX('Fund Research'!$B$6:$B$505,MATCH(21,'Fund Research'!$U$6:$U$505,0)),"") | D26: =IFERROR(INDEX('Fund Research'!$C$6:$C$505,MATCH(21,'Fund Research'!$U$6:$U$505,0)),"") | E26: =IFERROR(INDEX('Fund Research'!$G$6:$G$505,MATCH(21,'Fund Research'!$U$6:$U$505,0)),"") | F26: =IFERROR(INDEX('Fund Research'!$H$6:$H$505,MATCH(21,'Fund Research'!$U$6:$U$505,0)),"") | G26: =IFERROR(INDEX('Fund Research'!$I$6:$I$505,MATCH(21,'Fund Research'!$U$6:$U$505,0)),"") | H26: =IFERROR(INDEX('Fund Research'!$J$6:$J$505,MATCH(21,'Fund Research'!$U$6:$U$505,0)),"") | I26: =IFERROR(INDEX('Fund Research'!$L$6:$L$505,MATCH(21,'Fund Research'!$U$6:$U$505,0)),"") | J26: =IFERROR(INDEX('Fund Research'!$N$6:$N$505,MATCH(21,'Fund Research'!$U$6:$U$505,0)),"") | K26: =IFERROR(INDEX('Fund Research'!$P$6:$P$505,MATCH(21,'Fund Research'!$U$6:$U$505,0)),"") | L26: =IFERROR(INDEX('Fund Research'!$S$6:$S$505,MATCH(21,'Fund Research'!$U$6:$U$505,0)),"") | M26: =IFERROR(INDEX('Fund Research'!$T$6:$T$505,MATCH(21,'Fund Research'!$U$6:$U$505,0)),"")
A27: =IFERROR(IF(INDEX('Fund Research'!$B$6:$B$505,MATCH(22,'Fund Research'!$U$6:$U$505,0))="","",22),"") | B27: =IFERROR(INDEX('Fund Research'!$A$6:$A$505,MATCH(22,'Fund Research'!$U$6:$U$505,0)),"") | C27: =IFERROR(INDEX('Fund Research'!$B$6:$B$505,MATCH(22,'Fund Research'!$U$6:$U$505,0)),"") | D27: =IFERROR(INDEX('Fund Research'!$C$6:$C$505,MATCH(22,'Fund Research'!$U$6:$U$505,0)),"") | E27: =IFERROR(INDEX('Fund Research'!$G$6:$G$505,MATCH(22,'Fund Research'!$U$6:$U$505,0)),"") | F27: =IFERROR(INDEX('Fund Research'!$H$6:$H$505,MATCH(22,'Fund Research'!$U$6:$U$505,0)),"") | G27: =IFERROR(INDEX('Fund Research'!$I$6:$I$505,MATCH(22,'Fund Research'!$U$6:$U$505,0)),"") | H27: =IFERROR(INDEX('Fund Research'!$J$6:$J$505,MATCH(22,'Fund Research'!$U$6:$U$505,0)),"") | I27: =IFERROR(INDEX('Fund Research'!$L$6:$L$505,MATCH(22,'Fund Research'!$U$6:$U$505,0)),"") | J27: =IFERROR(INDEX('Fund Research'!$N$6:$N$505,MATCH(22,'Fund Research'!$U$6:$U$505,0)),"") | K27: =IFERROR(INDEX('Fund Research'!$P$6:$P$505,MATCH(22,'Fund Research'!$U$6:$U$505,0)),"") | L27: =IFERROR(INDEX('Fund Research'!$S$6:$S$505,MATCH(22,'Fund Research'!$U$6:$U$505,0)),"") | M27: =IFERROR(INDEX('Fund Research'!$T$6:$T$505,MATCH(22,'Fund Research'!$U$6:$U$505,0)),"")
A28: =IFERROR(IF(INDEX('Fund Research'!$B$6:$B$505,MATCH(23,'Fund Research'!$U$6:$U$505,0))="","",23),"") | B28: =IFERROR(INDEX('Fund Research'!$A$6:$A$505,MATCH(23,'Fund Research'!$U$6:$U$505,0)),"") | C28: =IFERROR(INDEX('Fund Research'!$B$6:$B$505,MATCH(23,'Fund Research'!$U$6:$U$505,0)),"") | D28: =IFERROR(INDEX('Fund Research'!$C$6:$C$505,MATCH(23,'Fund Research'!$U$6:$U$505,0)),"") | E28: =IFERROR(INDEX('Fund Research'!$G$6:$G$505,MATCH(23,'Fund Research'!$U$6:$U$505,0)),"") | F28: =IFERROR(INDEX('Fund Research'!$H$6:$H$505,MATCH(23,'Fund Research'!$U$6:$U$505,0)),"") | G28: =IFERROR(INDEX('Fund Research'!$I$6:$I$505,MATCH(23,'Fund Research'!$U$6:$U$505,0)),"") | H28: =IFERROR(INDEX('Fund Research'!$J$6:$J$505,MATCH(23,'Fund Research'!$U$6:$U$505,0)),"") | I28: =IFERROR(INDEX('Fund Research'!$L$6:$L$505,MATCH(23,'Fund Research'!$U$6:$U$505,0)),"") | J28: =IFERROR(INDEX('Fund Research'!$N$6:$N$505,MATCH(23,'Fund Research'!$U$6:$U$505,0)),"") | K28: =IFERROR(INDEX('Fund Research'!$P$6:$P$505,MATCH(23,'Fund Research'!$U$6:$U$505,0)),"") | L28: =IFERROR(INDEX('Fund Research'!$S$6:$S$505,MATCH(23,'Fund Research'!$U$6:$U$505,0)),"") | M28: =IFERROR(INDEX('Fund Research'!$T$6:$T$505,MATCH(23,'Fund Research'!$U$6:$U$505,0)),"")
A29: =IFERROR(IF(INDEX('Fund Research'!$B$6:$B$505,MATCH(24,'Fund Research'!$U$6:$U$505,0))="","",24),"") | B29: =IFERROR(INDEX('Fund Research'!$A$6:$A$505,MATCH(24,'Fund Research'!$U$6:$U$505,0)),"") | C29: =IFERROR(INDEX('Fund Research'!$B$6:$B$505,MATCH(24,'Fund Research'!$U$6:$U$505,0)),"") | D29: =IFERROR(INDEX('Fund Research'!$C$6:$C$505,MATCH(24,'Fund Research'!$U$6:$U$505,0)),"") | E29: =IFERROR(INDEX('Fund Research'!$G$6:$G$505,MATCH(24,'Fund Research'!$U$6:$U$505,0)),"") | F29: =IFERROR(INDEX('Fund Research'!$H$6:$H$505,MATCH(24,'Fund Research'!$U$6:$U$505,0)),"") | G29: =IFERROR(INDEX('Fund Research'!$I$6:$I$505,MATCH(24,'Fund Research'!$U$6:$U$505,0)),"") | H29: =IFERROR(INDEX('Fund Research'!$J$6:$J$505,MATCH(24,'Fund Research'!$U$6:$U$505,0)),"") | I29: =IFERROR(INDEX('Fund Research'!$L$6:$L$505,MATCH(24,'Fund Research'!$U$6:$U$505,0)),"") | J29: =IFERROR(INDEX('Fund Research'!$N$6:$N$505,MATCH(24,'Fund Research'!$U$6:$U$505,0)),"") | K29: =IFERROR(INDEX('Fund Research'!$P$6:$P$505,MATCH(24,'Fund Research'!$U$6:$U$505,0)),"") | L29: =IFERROR(INDEX('Fund Research'!$S$6:$S$505,MATCH(24,'Fund Research'!$U$6:$U$505,0)),"") | M29: =IFERROR(INDEX('Fund Research'!$T$6:$T$505,MATCH(24,'Fund Research'!$U$6:$U$505,0)),"")
A30: =IFERROR(IF(INDEX('Fund Research'!$B$6:$B$505,MATCH(25,'Fund Research'!$U$6:$U$505,0))="","",25),"") | B30: =IFERROR(INDEX('Fund Research'!$A$6:$A$505,MATCH(25,'Fund Research'!$U$6:$U$505,0)),"") | C30: =IFERROR(INDEX('Fund Research'!$B$6:$B$505,MATCH(25,'Fund Research'!$U$6:$U$505,0)),"") | D30: =IFERROR(INDEX('Fund Research'!$C$6:$C$505,MATCH(25,'Fund Research'!$U$6:$U$505,0)),"") | E30: =IFERROR(INDEX('Fund Research'!$G$6:$G$505,MATCH(25,'Fund Research'!$U$6:$U$505,0)),"") | F30: =IFERROR(INDEX('Fund Research'!$H$6:$H$505,MATCH(25,'Fund Research'!$U$6:$U$505,0)),"") | G30: =IFERROR(INDEX('Fund Research'!$I$6:$I$505,MATCH(25,'Fund Research'!$U$6:$U$505,0)),"") | H30: =IFERROR(INDEX('Fund Research'!$J$6:$J$505,MATCH(25,'Fund Research'!$U$6:$U$505,0)),"") | I30: =IFERROR(INDEX('Fund Research'!$L$6:$L$505,MATCH(25,'Fund Research'!$U$6:$U$505,0)),"") | J30: =IFERROR(INDEX('Fund Research'!$N$6:$N$505,MATCH(25,'Fund Research'!$U$6:$U$505,0)),"") | K30: =IFERROR(INDEX('Fund Research'!$P$6:$P$505,MATCH(25,'Fund Research'!$U$6:$U$505,0)),"") | L30: =IFERROR(INDEX('Fund Research'!$S$6:$S$505,MATCH(25,'Fund Research'!$U$6:$U$505,0)),"") | M30: =IFERROR(INDEX('Fund Research'!$T$6:$T$505,MATCH(25,'Fund Research'!$U$6:$U$505,0)),"")
A31: =IFERROR(IF(INDEX('Fund Research'!$B$6:$B$505,MATCH(26,'Fund Research'!$U$6:$U$505,0))="","",26),"") | B31: =IFERROR(INDEX('Fund Research'!$A$6:$A$505,MATCH(26,'Fund Research'!$U$6:$U$505,0)),"") | C31: =IFERROR(INDEX('Fund Research'!$B$6:$B$505,MATCH(26,'Fund Research'!$U$6:$U$505,0)),"") | D31: =IFERROR(INDEX('Fund Research'!$C$6:$C$505,MATCH(26,'Fund Research'!$U$6:$U$505,0)),"") | E31: =IFERROR(INDEX('Fund Research'!$G$6:$G$505,MATCH(26,'Fund Research'!$U$6:$U$505,0)),"") | F31: =IFERROR(INDEX('Fund Research'!$H$6:$H$505,MATCH(26,'Fund Research'!$U$6:$U$505,0)),"") | G31: =IFERROR(INDEX('Fund Research'!$I$6:$I$505,MATCH(26,'Fund Research'!$U$6:$U$505,0)),"") | H31: =IFERROR(INDEX('Fund Research'!$J$6:$J$505,MATCH(26,'Fund Research'!$U$6:$U$505,0)),"") | I31: =IFERROR(INDEX('Fund Research'!$L$6:$L$505,MATCH(26,'Fund Research'!$U$6:$U$505,0)),"") | J31: =IFERROR(INDEX('Fund Research'!$N$6:$N$505,MATCH(26,'Fund Research'!$U$6:$U$505,0)),"") | K31: =IFERROR(INDEX('Fund Research'!$P$6:$P$505,MATCH(26,'Fund Research'!$U$6:$U$505,0)),"") | L31: =IFERROR(INDEX('Fund Research'!$S$6:$S$505,MATCH(26,'Fund Research'!$U$6:$U$505,0)),"") | M31: =IFERROR(INDEX('Fund Research'!$T$6:$T$505,MATCH(26,'Fund Research'!$U$6:$U$505,0)),"")
A32: =IFERROR(IF(INDEX('Fund Research'!$B$6:$B$505,MATCH(27,'Fund Research'!$U$6:$U$505,0))="","",27),"") | B32: =IFERROR(INDEX('Fund Research'!$A$6:$A$505,MATCH(27,'Fund Research'!$U$6:$U$505,0)),"") | C32: =IFERROR(INDEX('Fund Research'!$B$6:$B$505,MATCH(27,'Fund Research'!$U$6:$U$505,0)),"") | D32: =IFERROR(INDEX('Fund Research'!$C$6:$C$505,MATCH(27,'Fund Research'!$U$6:$U$505,0)),"") | E32: =IFERROR(INDEX('Fund Research'!$G$6:$G$505,MATCH(27,'Fund Research'!$U$6:$U$505,0)),"") | F32: =IFERROR(INDEX('Fund Research'!$H$6:$H$505,MATCH(27,'Fund Research'!$U$6:$U$505,0)),"") | G32: =IFERROR(INDEX('Fund Research'!$I$6:$I$505,MATCH(27,'Fund Research'!$U$6:$U$505,0)),"") | H32: =IFERROR(INDEX('Fund Research'!$J$6:$J$505,MATCH(27,'Fund Research'!$U$6:$U$505,0)),"") | I32: =IFERROR(INDEX('Fund Research'!$L$6:$L$505,MATCH(27,'Fund Research'!$U$6:$U$505,0)),"") | J32: =IFERROR(INDEX('Fund Research'!$N$6:$N$505,MATCH(27,'Fund Research'!$U$6:$U$505,0)),"") | K32: =IFERROR(INDEX('Fund Research'!$P$6:$P$505,MATCH(27,'Fund Research'!$U$6:$U$505,0)),"") | L32: =IFERROR(INDEX('Fund Research'!$S$6:$S$505,MATCH(27,'Fund Research'!$U$6:$U$505,0)),"") | M32: =IFERROR(INDEX('Fund Research'!$T$6:$T$505,MATCH(27,'Fund Research'!$U$6:$U$505,0)),"")
A33: =IFERROR(IF(INDEX('Fund Research'!$B$6:$B$505,MATCH(28,'Fund Research'!$U$6:$U$505,0))="","",28),"") | B33: =IFERROR(INDEX('Fund Research'!$A$6:$A$505,MATCH(28,'Fund Research'!$U$6:$U$505,0)),"") | C33: =IFERROR(INDEX('Fund Research'!$B$6:$B$505,MATCH(28,'Fund Research'!$U$6:$U$505,0)),"") | D33: =IFERROR(INDEX('Fund Research'!$C$6:$C$505,MATCH(28,'Fund Research'!$U$6:$U$505,0)),"") | E33: =IFERROR(INDEX('Fund Research'!$G$6:$G$505,MATCH(28,'Fund Research'!$U$6:$U$505,0)),"") | F33: =IFERROR(INDEX('Fund Research'!$H$6:$H$505,MATCH(28,'Fund Research'!$U$6:$U$505,0)),"") | G33: =IFERROR(INDEX('Fund Research'!$I$6:$I$505,MATCH(28,'Fund Research'!$U$6:$U$505,0)),"") | H33: =IFERROR(INDEX('Fund Research'!$J$6:$J$505,MATCH(28,'Fund Research'!$U$6:$U$505,0)),"") | I33: =IFERROR(INDEX('Fund Research'!$L$6:$L$505,MATCH(28,'Fund Research'!$U$6:$U$505,0)),"") | J33: =IFERROR(INDEX('Fund Research'!$N$6:$N$505,MATCH(28,'Fund Research'!$U$6:$U$505,0)),"") | K33: =IFERROR(INDEX('Fund Research'!$P$6:$P$505,MATCH(28,'Fund Research'!$U$6:$U$505,0)),"") | L33: =IFERROR(INDEX('Fund Research'!$S$6:$S$505,MATCH(28,'Fund Research'!$U$6:$U$505,0)),"") | M33: =IFERROR(INDEX('Fund Research'!$T$6:$T$505,MATCH(28,'Fund Research'!$U$6:$U$505,0)),"")
A34: =IFERROR(IF(INDEX('Fund Research'!$B$6:$B$505,MATCH(29,'Fund Research'!$U$6:$U$505,0))="","",29),"") | B34: =IFERROR(INDEX('Fund Research'!$A$6:$A$505,MATCH(29,'Fund Research'!$U$6:$U$505,0)),"") | C34: =IFERROR(INDEX('Fund Research'!$B$6:$B$505,MATCH(29,'Fund Research'!$U$6:$U$505,0)),"") | D34: =IFERROR(INDEX('Fund Research'!$C$6:$C$505,MATCH(29,'Fund Research'!$U$6:$U$505,0)),"") | E34: =IFERROR(INDEX('Fund Research'!$G$6:$G$505,MATCH(29,'Fund Research'!$U$6:$U$505,0)),"") | F34: =IFERROR(INDEX('Fund Research'!$H$6:$H$505,MATCH(29,'Fund Research'!$U$6:$U$505,0)),"") | G34: =IFERROR(INDEX('Fund Research'!$I$6:$I$505,MATCH(29,'Fund Research'!$U$6:$U$505,0)),"") | H34: =IFERROR(INDEX('Fund Research'!$J$6:$J$505,MATCH(29,'Fund Research'!$U$6:$U$505,0)),"") | I34: =IFERROR(INDEX('Fund Research'!$L$6:$L$505,MATCH(29,'Fund Research'!$U$6:$U$505,0)),"") | J34: =IFERROR(INDEX('Fund Research'!$N$6:$N$505,MATCH(29,'Fund Research'!$U$6:$U$505,0)),"") | K34: =IFERROR(INDEX('Fund Research'!$P$6:$P$505,MATCH(29,'Fund Research'!$U$6:$U$505,0)),"") | L34: =IFERROR(INDEX('Fund Research'!$S$6:$S$505,MATCH(29,'Fund Research'!$U$6:$U$505,0)),"") | M34: =IFERROR(INDEX('Fund Research'!$T$6:$T$505,MATCH(29,'Fund Research'!$U$6:$U$505,0)),"")
A35: =IFERROR(IF(INDEX('Fund Research'!$B$6:$B$505,MATCH(30,'Fund Research'!$U$6:$U$505,0))="","",30),"") | B35: =IFERROR(INDEX('Fund Research'!$A$6:$A$505,MATCH(30,'Fund Research'!$U$6:$U$505,0)),"") | C35: =IFERROR(INDEX('Fund Research'!$B$6:$B$505,MATCH(30,'Fund Research'!$U$6:$U$505,0)),"") | D35: =IFERROR(INDEX('Fund Research'!$C$6:$C$505,MATCH(30,'Fund Research'!$U$6:$U$505,0)),"") | E35: =IFERROR(INDEX('Fund Research'!$G$6:$G$505,MATCH(30,'Fund Research'!$U$6:$U$505,0)),"") | F35: =IFERROR(INDEX('Fund Research'!$H$6:$H$505,MATCH(30,'Fund Research'!$U$6:$U$505,0)),"") | G35: =IFERROR(INDEX('Fund Research'!$I$6:$I$505,MATCH(30,'Fund Research'!$U$6:$U$505,0)),"") | H35: =IFERROR(INDEX('Fund Research'!$J$6:$J$505,MATCH(30,'Fund Research'!$U$6:$U$505,0)),"") | I35: =IFERROR(INDEX('Fund Research'!$L$6:$L$505,MATCH(30,'Fund Research'!$U$6:$U$505,0)),"") | J35: =IFERROR(INDEX('Fund Research'!$N$6:$N$505,MATCH(30,'Fund Research'!$U$6:$U$505,0)),"") | K35: =IFERROR(INDEX('Fund Research'!$P$6:$P$505,MATCH(30,'Fund Research'!$U$6:$U$505,0)),"") | L35: =IFERROR(INDEX('Fund Research'!$S$6:$S$505,MATCH(30,'Fund Research'!$U$6:$U$505,0)),"") | M35: =IFERROR(INDEX('Fund Research'!$T$6:$T$505,MATCH(30,'Fund Research'!$U$6:$U$505,0)),"")
A36: =IFERROR(IF(INDEX('Fund Research'!$B$6:$B$505,MATCH(31,'Fund Research'!$U$6:$U$505,0))="","",31),"") | B36: =IFERROR(INDEX('Fund Research'!$A$6:$A$505,MATCH(31,'Fund Research'!$U$6:$U$505,0)),"") | C36: =IFERROR(INDEX('Fund Research'!$B$6:$B$505,MATCH(31,'Fund Research'!$U$6:$U$505,0)),"") | D36: =IFERROR(INDEX('Fund Research'!$C$6:$C$505,MATCH(31,'Fund Research'!$U$6:$U$505,0)),"") | E36: =IFERROR(INDEX('Fund Research'!$G$6:$G$505,MATCH(31,'Fund Research'!$U$6:$U$505,0)),"") | F36: =IFERROR(INDEX('Fund Research'!$H$6:$H$505,MATCH(31,'Fund Research'!$U$6:$U$505,0)),"") | G36: =IFERROR(INDEX('Fund Research'!$I$6:$I$505,MATCH(31,'Fund Research'!$U$6:$U$505,0)),"") | H36: =IFERROR(INDEX('Fund Research'!$J$6:$J$505,MATCH(31,'Fund Research'!$U$6:$U$505,0)),"") | I36: =IFERROR(INDEX('Fund Research'!$L$6:$L$505,MATCH(31,'Fund Research'!$U$6:$U$505,0)),"") | J36: =IFERROR(INDEX('Fund Research'!$N$6:$N$505,MATCH(31,'Fund Research'!$U$6:$U$505,0)),"") | K36: =IFERROR(INDEX('Fund Research'!$P$6:$P$505,MATCH(31,'Fund Research'!$U$6:$U$505,0)),"") | L36: =IFERROR(INDEX('Fund Research'!$S$6:$S$505,MATCH(31,'Fund Research'!$U$6:$U$505,0)),"") | M36: =IFERROR(INDEX('Fund Research'!$T$6:$T$505,MATCH(31,'Fund Research'!$U$6:$U$505,0)),"")
A37: =IFERROR(IF(INDEX('Fund Research'!$B$6:$B$505,MATCH(32,'Fund Research'!$U$6:$U$505,0))="","",32),"") | B37: =IFERROR(INDEX('Fund Research'!$A$6:$A$505,MATCH(32,'Fund Research'!$U$6:$U$505,0)),"") | C37: =IFERROR(INDEX('Fund Research'!$B$6:$B$505,MATCH(32,'Fund Research'!$U$6:$U$505,0)),"") | D37: =IFERROR(INDEX('Fund Research'!$C$6:$C$505,MATCH(32,'Fund Research'!$U$6:$U$505,0)),"") | E37: =IFERROR(INDEX('Fund Research'!$G$6:$G$505,MATCH(32,'Fund Research'!$U$6:$U$505,0)),"") | F37: =IFERROR(INDEX('Fund Research'!$H$6:$H$505,MATCH(32,'Fund Research'!$U$6:$U$505,0)),"") | G37: =IFERROR(INDEX('Fund Research'!$I$6:$I$505,MATCH(32,'Fund Research'!$U$6:$U$505,0)),"") | H37: =IFERROR(INDEX('Fund Research'!$J$6:$J$505,MATCH(32,'Fund Research'!$U$6:$U$505,0)),"") | I37: =IFERROR(INDEX('Fund Research'!$L$6:$L$505,MATCH(32,'Fund Research'!$U$6:$U$505,0)),"") | J37: =IFERROR(INDEX('Fund Research'!$N$6:$N$505,MATCH(32,'Fund Research'!$U$6:$U$505,0)),"") | K37: =IFERROR(INDEX('Fund Research'!$P$6:$P$505,MATCH(32,'Fund Research'!$U$6:$U$505,0)),"") | L37: =IFERROR(INDEX('Fund Research'!$S$6:$S$505,MATCH(32,'Fund Research'!$U$6:$U$505,0)),"") | M37: =IFERROR(INDEX('Fund Research'!$T$6:$T$505,MATCH(32,'Fund Research'!$U$6:$U$505,0)),"")
A38: =IFERROR(IF(INDEX('Fund Research'!$B$6:$B$505,MATCH(33,'Fund Research'!$U$6:$U$505,0))="","",33),"") | B38: =IFERROR(INDEX('Fund Research'!$A$6:$A$505,MATCH(33,'Fund Research'!$U$6:$U$505,0)),"") | C38: =IFERROR(INDEX('Fund Research'!$B$6:$B$505,MATCH(33,'Fund Research'!$U$6:$U$505,0)),"") | D38: =IFERROR(INDEX('Fund Research'!$C$6:$C$505,MATCH(33,'Fund Research'!$U$6:$U$505,0)),"") | E38: =IFERROR(INDEX('Fund Research'!$G$6:$G$505,MATCH(33,'Fund Research'!$U$6:$U$505,0)),"") | F38: =IFERROR(INDEX('Fund Research'!$H$6:$H$505,MATCH(33,'Fund Research'!$U$6:$U$505,0)),"") | G38: =IFERROR(INDEX('Fund Research'!$I$6:$I$505,MATCH(33,'Fund Research'!$U$6:$U$505,0)),"") | H38: =IFERROR(INDEX('Fund Research'!$J$6:$J$505,MATCH(33,'Fund Research'!$U$6:$U$505,0)),"") | I38: =IFERROR(INDEX('Fund Research'!$L$6:$L$505,MATCH(33,'Fund Research'!$U$6:$U$505,0)),"") | J38: =IFERROR(INDEX('Fund Research'!$N$6:$N$505,MATCH(33,'Fund Research'!$U$6:$U$505,0)),"") | K38: =IFERROR(INDEX('Fund Research'!$P$6:$P$505,MATCH(33,'Fund Research'!$U$6:$U$505,0)),"") | L38: =IFERROR(INDEX('Fund Research'!$S$6:$S$505,MATCH(33,'Fund Research'!$U$6:$U$505,0)),"") | M38: =IFERROR(INDEX('Fund Research'!$T$6:$T$505,MATCH(33,'Fund Research'!$U$6:$U$505,0)),"")
