Workbook

Sheet Key
A1: SCORING KEY
A2: Five options per indicator, always in the order +2, +1, 0, -1, -2. Do not reorder them - the Console scores a reading by its position here.
A4: Layer | B4: Indicator | C4: Option | D4: Score
A5: Macro & fundamental | B5: Real GDP growth (YoY) | C5: Above 7.5% - strong | D5: 2
C6: 6.5 to 7.5% - healthy | D6: 1
C7: 5.5 to 6.5% - moderating | D7: 0
C8: 4.5 to 5.5% - slowing | D8: -1
C9: Below 4.5% - weak | D9: -2
A10: Macro & fundamental | B10: CPI inflation vs RBI band | C10: Below 4% - supportive | D10: 2
C11: 4 to 5% - comfortable | D11: 1
C12: 5 to 6% - upper band | D12: 0
C13: 6 to 7% - above tolerance | D13: -1
C14: Above 7% - policy pressure | D14: -2
A15: Macro & fundamental | B15: RBI stance | C15: Cutting / accommodative | D15: 2
C16: On hold, dovish tone | D16: 1
C17: On hold, neutral | D17: 0
C18: On hold, hawkish tone | D18: -1
C19: Hiking / tightening | D19: -2
A20: Macro & fundamental | B20: Composite PMI | C20: Above 58 - very strong | D20: 2
C21: 55 to 58 - strong | D21: 1
C22: 52 to 55 - expanding | D22: 0
C23: 50 to 52 - barely expanding | D23: -1
C24: Below 50 - contracting | D24: -2
A25: Macro & fundamental | B25: Brent crude | C25: Below $65 - strong tailwind | D25: 2
C26: $65 to $75 - supportive | D26: 1
C27: $75 to $85 - neutral | D27: 0
C28: $85 to $95 - headwind | D28: -1
C29: Above $95 - serious drag | D29: -2
A30: Macro & fundamental | B30: USD/INR trend | C30: Appreciating | D30: 2
C31: Stable | D31: 1
C32: Mild depreciation | D32: 0
C33: Steady depreciation | D33: -1
C34: Sharp depreciation | D34: -2
A35: Macro & fundamental | B35: Nifty P/E vs long-run mean | C35: Below 18x - cheap | D35: 2
C36: 18 to 21x - fair | D36: 1
C37: 21 to 24x - full | D37: 0
C38: 24 to 27x - rich | D38: -1
C39: Above 27x - stretched | D39: -2
A40: Macro & fundamental | B40: Nifty earnings momentum | C40: Broad upgrades | D40: 2
C41: Mild upgrades | D41: 1
...

Sheet Console
A1: NIFTY BIAS CONSOLE
A2: Set every blue cell from today's live data. Scores, layer totals and the confluence test calculate themselves.
A3: This file holds no live market data. Every dropdown opens on a worked example - replace each one before acting on the output. The confluence test matters more than the headline score.
A5: COMPOSITE BIAS
A6: =IF($F$6="","-",ROUND($F$6,0)) | B6: =IF($F$6="","Nothing set yet",IF($F$6>=50,"STRONG BULLISH",IF($F$6>=20,"BULLISH",IF($F$6>-20,"NEUTRAL - no directional trade",IF($F$6>-50,"BEARISH","STRONG BEARISH"))))) | F6: =IF(SUM($G$10:$G$13)=0,"",SUM($F$10:$F$13)/SUM($G$10:$G$13))
B7: =IF($F$6="","set an indicator to begin","composite "&TEXT($F$6,"+0.0;-0.0;0.0")&" - weighted over the layers that have a view")
A9: Layer | B9: What it is | C9: Score | D9: Reading
A10: Macro & fundamental (20%) | B10: The regime. Moves over quarters - re-read on data releases, not daily. | C10: =IF(COUNT($C$33:$C$41)=0,"",AVERAGE($C$33:$C$41)*50) | D10: =IF($C10="","not set",IF($C10>=50,"strongly bullish",IF($C10>=15,"bullish",IF($C10>-15,"no clear view",IF($C10>-50,"bearish","strongly bearish"))))) | F10: =IF($C10="",0,$C10*0.2) | G10: =IF($C10="",0,0.2)
A11: Global cues & GIFT Nifty (15%) | B11: The overnight gap. Read at 08:30, stale by 10:00. | C11: =IF(COUNT($C$44:$C$49)=0,"",AVERAGE($C$44:$C$49)*50) | D11: =IF($C11="","not set",IF($C11>=50,"strongly bullish",IF($C11>=15,"bullish",IF($C11>-15,"no clear view",IF($C11>-50,"bearish","strongly bearish"))))) | F11: =IF($C11="",0,$C11*0.15) | G11: =IF($C11="",0,0.15)
A12: Derivatives & positioning (30%) | B12: Where the money actually sits. Turns weekly, around expiry. | C12: =IF(COUNT($C$52:$C$59)=0,"",AVERAGE($C$52:$C$59)*50) | D12: =IF($C12="","not set",IF($C12>=50,"strongly bullish",IF($C12>=15,"bullish",IF($C12>-15,"no clear view",IF($C12>-50,"bearish","strongly bearish"))))) | F12: =IF($C12="",0,$C12*0.3) | G12: =IF($C12="",0,0.3)
A13: Price action & technical (35%) | B13: The trigger. Turns intraday - this is what gets you in and out. | C13: =IF(COUNT($C$62:$C$70)=0,"",AVERAGE($C$62:$C$70)*50) | D13: =IF($C13="","not set",IF($C13>=50,"strongly bullish",IF($C13>=15,"bullish",IF($C13>-15,"no clear view",IF($C13>-50,"bearish","strongly bearish"))))) | F13: =IF($C13="",0,$C13*0.35) | G13: =IF($C13="",0,0.35)
A15: CONFLUENCE TEST
A17: Verdict | B17: =IF(COUNTIFS($C$10:$C$13,">=15")+COUNTIFS($C$10:$C$13,"<=-15")<2,"THIN - too few layers have a view",IF(OR(COUNTIFS($C$10:$C$13,"<=-15")=0,COUNTIFS($C$10:$C$13,">=15")=0),"ALIGNED - every layer with a view agrees",IF(AND(MIN(COUNTIFS($C$10:$C$13,">=15"),COUNTIFS($C$10:$C$13,"<=-15"))=1,COUNTIFS($C$10:$C$13,">=15")+COUNTIFS($C$10:$C$13,"<=-15")>=3),"MOSTLY AGREED - one layer dissents","CONFLICTED - the layers disagree")))
A18: What to do | B18: =IF(COUNTIFS($C$10:$C$13,">=15")+COUNTIFS($C$10:$C$13,"<=-15")<2,"Fill in more indicators before reading the score.",IF(OR(COUNTIFS($C$10:$C$13,"<=-15")=0,COUNTIFS($C$10:$C$13,">=15")=0),"This is the setup the framework exists to find. The composite can be acted on.",IF(AND(MIN(COUNTIFS($C$10:$C$13,">=15"),COUNTIFS($C$10:$C$13,"<=-15"))=1,COUNTIFS($C$10:$C$13,">=15")+COUNTIFS($C$10:$C$13,"<=-15")>=3),"Workable at reduced size. The dissenting layer is what to watch for the trade going wrong.","The composite is averaging two opposing views, not signalling. Stand aside.")))
A19: Layers voting | B19: =COUNTIFS($C$10:$C$13,">=15")&" up / "&COUNTIFS($C$10:$C$13,"<=-15")&" down (a layer votes only past +/-15; the rest are too flat to count)"
A32: MACRO & FUNDAMENTAL - 20% of the composite
A33: Real GDP growth (YoY) | B33: 5.5 to 6.5% - moderating | C33: =IF($B33="","",3-MATCH($B33,Key!$C$5:$C$9,0)) | D33: MoSPI quarterly print. Above 7% is among the fastest of any large economy and supports earnings expansion.
A34: CPI inflation vs RBI band | B34: 5 to 6% - upper band | C34: =IF($B34="","",3-MATCH($B34,Key!$C$10:$C$14,0)) | D34: RBI targets 4% with a +/-2% tolerance band. Above 6% forces a hawkish stance and compresses valuations.
A35: RBI stance | B35: On hold, neutral | C35: =IF($B35="","",3-MATCH($B35,Key!$C$15:$C$19,0)) | D35: Direction beats level. A cutting cycle lifts rate-sensitive sectors well before the cuts reach earnings.
A36: Composite PMI | B36: 52 to 55 - expanding | C36: =IF($B36="","",3-MATCH($B36,Key!$C$20:$C$24,0)) | D36: Above 50 is expansion. India has run among the highest composite readings globally; treat 55+ as genuine strength.
A37: Brent crude | B37: $85 to $95 - headwind | C37: =IF($B37="","",3-MATCH($B37,Key!$C$25:$C$29,0)) | D37: India imports roughly 85% of its crude. Falling crude eases the current account, inflation and input costs at once.
A38: USD/INR trend | B38: Steady depreciation | C38: =IF($B38="","",3-MATCH($B38,Key!$C$30:$C$34,0)) | D38: A depreciating rupee erodes FII returns in dollar terms and can turn a flat index into a loss for a foreign holder.
A39: Nifty P/E vs long-run mean | B39: Above 27x - stretched | C39: =IF($B39="","",3-MATCH($B39,Key!$C$35:$C$39,0)) | D39: The long-run mean sits near 20-22x. Rich valuations do not time a top, but they cap how far good news can carry.
A40: Nifty earnings momentum | B40: Mild downgrades | C40: =IF($B40="","",3-MATCH($B40,Key!$C$40:$C$44,0)) | D40: Consensus EPS revisions. Upgrades turn a liquidity rally into a durable one; without them a re-rating is borrowed.
A41: Remittance inflows | B41: Flat | C41: =IF($B41="","",3-MATCH($B41,Key!$C$45:$C$49,0)) | D41: India is the world's largest recipient. They cushion the current account and support rural consumption - a documented predictor of Indian market returns.
A43: GLOBAL CUES & GIFT NIFTY - 15% of the composite
A44: GIFT Nifty vs prior close | B44: +50 to +150 pts | C44: =IF($B44="","",3-MATCH($B44,Key!$C$50:$C$54,0)) | D44: The market's estimate of the opening gap, priced through the US session while NSE is shut. Compare against the prior Nifty FUTURES close, not spot. See Guide.
A45: US close (S&P 500 / Nasdaq) | B45: Up 0.3 to 1% | C45: =IF($B45="","",3-MATCH($B45,Key!$C$55:$C$59,0)) | D45: Sets the risk tone. Nasdaq matters more than the Dow for Indian IT and for broad risk appetite.
A46: Asian markets this morning | B46: Mixed | C46: =IF($B46="","",3-MATCH($B46,Key!$C$60:$C$64,0)) | D46: Nikkei, Hang Seng and Kospi trade alongside our session and often confirm or contradict GIFT Nifty in real time.
A47: Dollar index (DXY) | B47: Flat | C47: =IF($B47="","",3-MATCH($B47,Key!$C$65:$C$69,0)) | D47: A rising dollar pulls capital out of emerging markets - one of the more reliable medium-term headwinds for FII flows.
A48: US 10-year Treasury yield | B48: Rising | C48: =IF($B48="","",3-MATCH($B48,Key!$C$70:$C$74,0)) | D48: Higher risk-free yields raise the hurdle for emerging-market equity and compress the multiple India trades at.
A49: US VIX | B49: 14 to 17 | C49: =IF($B49="","",3-MATCH($B49,Key!$C$75:$C$79,0)) | D49: Global risk appetite. Above 25 tends to drag every emerging market down regardless of local fundamentals.
A51: DERIVATIVES & POSITIONING - 30% of the composite
A52: India VIX level | B52: 12 to 15 - calm, trend-friendly | C52: =IF($B52="","",3-MATCH($B52,Key!$C$80:$C$84,0)) | D52: Annualised expected move from the Nifty option order book. Not directional - but the regime it describes decides position size. See Guide.
A53: India VIX direction | B53: Falling | C53: =IF($B53="","",3-MATCH($B53,Key!$C$85:$C$89,0)) | D53: Rate of change beats level. VIX rising while the index also rises means protection is being bought into strength.
A54: Index futures OI build-up | B54: Long build-up - price up, OI up | C54: =IF($B54="","",3-MATCH($B54,Key!$C$90:$C$94,0)) | D54: Price direction paired with open interest - whether a move carries new money or is the other side unwinding. See Guide.
A55: Put-call ratio (OI) | B55: 1.0 to 1.2 - mildly bullish | C55: =IF($B55="","",3-MATCH($B55,Key!$C$95:$C$99,0)) | D55: Put writers expecting the index to hold is bullish. Past 1.5 it inverts - positioning is crowded and the trade is full.
A56: Option chain walls | B56: Put writers rolling strikes up | C56: =IF($B56="","",3-MATCH($B56,Key!$C$100:$C$104,0)) | D56: Highest Call OI is resistance, highest Put OI support. Watch the shift, not the level - writers rolling a strike up is the live signal.
A57: FII index futures positioning | B57: Net long 55 to 70% | C57: =IF($B57="","",3-MATCH($B57,Key!$C$105:$C$109,0)) | D57: The long-short ratio. Extended readings at either end often precede a squeeze rather than a continuation.
A58: FII / DII cash flows | B58: FII selling, DII absorbing | C58: =IF($B58="","",3-MATCH($B58,Key!$C$110:$C$114,0)) | D58: Direction and whether they agree. DII buying against FII selling slows a fall rather than reversing it.
...

Sheet Guide
A1: INDICATOR GUIDE
A2: How to read the inputs the Console scores.
A4: GIFT NIFTY
A5: GIFT Nifty is the Nifty 50 futures contract traded on NSE International Exchange in GIFT City, Gandhinagar. It took over the offshore Nifty contract from SGX Nifty in Singapore in July 2023 and settles in US dollars. It runs roughly 21 hours a day across two sessions - about 06:30 to 15:40 IST, then 16:35 to 02:45 IST - so it stays open through the US cash session while the Indian market is shut.
A9: That overlap is what makes it the most useful pre-open input. Anything that happens overnight is absorbed by GIFT Nifty before NSE opens. Take its level against the previous Nifty FUTURES close, not the spot close, since spot still carries the cost of carry. The difference is the market's estimate of the opening gap.
A13: Two cautions. GIFT Nifty indicates the open, not the day: a strong gap up sold into within the first fifteen minutes is a classic distribution signal and often marks the day's high. And its volumes are far thinner than NSE cash, so a large late move on light volume can misprice the gap.
A17: Reading the gap
A18: Gap vs prior close | B18: Reading | C18: What to watch at 09:15
A19: > +150 pts | B19: Strong gap up | C19: Gap-and-go, or an exhaustion gap. Wait for the first 15-minute candle to close before committing.
A20: +50 to +150 | B20: Gap up | C20: Healthy. Needs the opening range high to break for continuation.
A21: -50 to +50 | B21: Flat | C21: No overnight information. Trade the intraday structure, not the gap.
A22: -150 to -50 | B22: Gap down | C22: Check whether it fills. An unfilled gap down by noon signals genuine supply.
A23: < -150 pts | B23: Strong gap down | C23: Panic opens often mark intraday lows. Let the first 30 minutes print before shorting.
A25: INDIA VIX
A26: India VIX is computed by NSE from the order book of near- and next-month Nifty 50 options, on the methodology CBOE developed for the US VIX. It reads as an annualised percentage: a VIX of 14 means the option market is pricing a 14% move over the next year, which is roughly 14 / SQRT(12) = 4.0% over the next month, one standard deviation. Divide by SQRT(252) for a daily figure - about 0.88% at VIX 14.
A30: It is not directional. It measures expected magnitude, not sign. But because fear is priced faster than greed it carries an inverse correlation with Nifty of roughly -0.7 to -0.8. The asymmetry matters more than the correlation: VIX spikes mark bottoms far more reliably than low VIX marks tops. A market can sit at VIX 11 for months while grinding higher. It cannot sit at VIX 35 for long.
A34: Regimes
A35: India VIX | B35: Regime | C35: What it means for positioning
A36: Below 12 | B36: Complacency | C36: Options are cheap. Good for buyers, dangerous for naked sellers - a shock is underpriced.
A37: 12 - 15 | B37: Calm | C37: The trend-following regime. Breakouts tend to follow through.
A38: 15 - 20 | B38: Normal | C38: Nothing unusual. Trade the structure as it is.
A39: 20 - 25 | B39: Elevated | C39: Widen stops or cut size - the same stop gets hit by noise. Premium selling pays better.
A40: Above 25 | B40: Fear | C40: Historically closer to bottoms than tops. Contrarian longs work; leverage does not.
A42: Read the rate of change alongside the level. VIX jumping from 13 to 17 in a session is a bigger signal than VIX sitting at 19. And watch the divergence that precedes trouble: Nifty making a new high while VIX also rises means the option market is paying up for protection into strength, which rarely resolves upward.
A46: OPEN INTEREST, PCR AND MAX PAIN
A47: Open interest counts contracts outstanding. Paired with price direction it tells you whether a move is backed by new money or is merely being unwound.
A50: OI build-up
A51: Price | B51: Open interest | C51: Reading
A52: Up | B52: Up | C52: Long build-up - new buying, the strongest bullish state
A53: Down | B53: Up | C53: Short build-up - new selling, the strongest bearish state
A54: Up | B54: Down | C54: Short covering - a rally on exits, not conviction; it fades
A55: Down | B55: Down | C55: Long unwinding - holders leaving, weak hands first
A57: Put-call ratio is total Put OI divided by Call OI. Because option writers are the better-informed side, heavy put writing means writers expect the index to hold - bullish, the opposite of how it first reads. Below 0.8 bearish, 0.8 to 1.2 neutral, above 1.2 bullish. Past 1.5 or below 0.6 it inverts into a contrarian extreme: everyone is already positioned.
A61: Max pain is the strike at which the largest rupee value of options expires worthless. Price drifts toward it into expiry because writers defend it. Useful on expiry day and the day before; noise at the start of a series.
A64: The walls: highest Call OI acts as resistance, highest Put OI as support. The shift matters more than the level - put writers rolling a strike up is a live bullish signal; a wall sitting still is not.
A67: THE MODEL LAYER
A68: BiLSTM runs a long short-term memory network over the sequence in both directions, so each point is encoded with the context that follows it as well as what preceded it. It is the standard strong baseline for financial time series. The bidirectional pass is legitimate when training on history and becomes lookahead bias the moment it is applied to the live edge without care.
A72: Liquid neural networks are continuous-time recurrent networks whose time constants depend on the input, so the dynamics keep adapting after training rather than being frozen. They need far fewer neurons than an LSTM and hold up better on irregular, non-stationary series - which is the honest description of an index. That adaptivity is why they are interesting for regime shifts.
A76: Hybrid ensembles pair a deep sequence model with gradient-boosted trees on engineered features and a sentiment channel over financial news. For India the multilingual part is not decoration: material news breaks in Hindi, Gujarati and Marathi business media before it reaches English wires.
A80: What the published accuracy figures mean: almost all are directional accuracy on a held-out slice of history, not live profit. Four things separate the two - non-stationarity, since a model fitted before 2020 did not survive 2020; transaction costs and slippage, which consume most small edges; survivorship and lookahead bias in the dataset; and adaptivity, because a published edge is one being arbitraged away. The defensible use is probability and regime classification, never a point forecast of a closing level.
...
